Workbook
Name data: data!$L$3:$DJ$5003
Name header: data!$L$2:$DJ$2
Name index: data!$DL$3:$DL$5003
Name region: _xlfn.ANCHORARRAY(Lists!$F$5)
Name region_all: Lists!$B$5:$B$20
Name region_all_code: Lists!$C$5:$C$20
Name region_count: Lists!$F$3
Name year: _xlfn.ANCHORARRAY(Lists!$G$5)
Name year_all: Lists!$D$5:$D$105
Name year_count: Lists!$G$3

Sheet README
A1: Follow these steps:
B2: 1 | C2: Add sheets as-needed to calculate input data
B3: 2 | C3: Collect all values to be included in CIMS input files on the data sheet within the green "data" named range. Include values as appropriate in the text columns (B:M) to be able to link external files using the index column.
B4: 3 | C4: In the CIMS input .xlsx files (e.g., CIMS_exogenous prices), use following formula template to link to data in this file: =INDEX(data,MATCH(index_from_model_file,index,0),MATCH(year_from_model_file,year,0)) Note that "data", "index", and "year" are named ranges in this file. You can use these names in the .xlsx input file. Linking to this file while it is open will be easiest. It does not need to be open to update values in future.
A7: Model files linked to this data file:
C8: for clarity, include file path after "cims-models" folder (e.g., csv/model/CIMS_exogenous prices)
B9: 1 | C9: csv/model/electricity
B10: 2 | C10: csv/model/exogenous demand
B11: 3 | C11: csv/policies/net zero/NZ_electricity generation
B12: 4
B13: 5
B14: 6
B15: 7
B16: 8
B17: 9
B18: 10
A21: Change log
B22: Date | C22: Note

Sheet Lists
B1: Global lists | F1: Data lists
A3: Count | F3: =COUNTA(_xlfn.ANCHORARRAY(F5)) -> 1 | G3: =COUNTA(_xlfn.ANCHORARRAY(G5)) -> 1
B4: Region | C4: Code | D4: Date | F4: Region | G4: Date
B5: Canada | C5: CAN | D5: 2000 | F5: SORTBY(UNIQUE(VSTACK(#REF!$B$2:$B$6149,#REF!$B$2:$B$9013)),MATCH(UNIQUE(VSTACK(#REF!$B$2:$B$6149,#REF!$B$2:$B$9013)),region_all,0)) | G5: SORT(FILTER(UNIQUE(VSTACK(YEAR(#REF!$A$2:$A$6359),YEAR(#REF!$A$2:$A$9013))),UNIQUE(VSTACK(YEAR(#REF!$A$2:$A$6359),YEAR(#REF!$A$2:$A$9013)))>=2000))
B6: British Columbia | C6: BC | D6: 2001
B7: Alberta | C7: AB | D7: 2002
B8: Saskatchewan | C8: SK | D8: 2003
B9: Manitoba | C9: MB | D9: 2004
B10: Ontario | C10: ON | D10: 2005
B11: Quebec | C11: QC | D11: 2006
B12: New Brunswick | C12: NB | D12: 2007
B13: Nova Scotia | C13: NS | D13: 2008
B14: Prince Edward Island | C14: PE | D14: 2009
B15: Newfoundland and Labrador | C15: NL | D15: 2010
B16: Yukon | C16: YT | D16: 2011
B17: Northwest Territories | C17: NT | D17: 2012
... B20: Territories | C20: TR | D20: 2015
D21: 2016
D22: 2017
D23: 2018
D24: 2019
D25: 2020
D26: 2021
D27: 2022
D28: 2023
D29: 2024
D30: 2025
D31: 2026
D32: 2027
... D105: 2100

Sheet data
B1: Not used in index | D1: Not used in index | E1: Not used in index | K1: Not used in index
A2: Branch | B2: Type | C2: Region | D2: Sector | E2: Service | F2: Technology | G2: Parameter | H2: Context | I2: Sub_Context | J2: Target | K2: Source | L2: Comments | M2: Unit | N2: 2000 | O2: 2001 | P2: 2002 | Q2: 2003 | R2: 2004 | S2: 2005 | T2: 2006 | U2: 2007 | V2: 2008 | W2: 2009 | X2: 2010 | Y2: 2011 | Z2: 2012 | AA2: 2013 | AB2: 2014 | AC2: 2015 | AD2: 2016 | AE2: 2017 | AF2: 2018 | AG2: 2019 | AH2: 2020 | AI2: 2021 | AJ2: 2022 | AK2: 2023 | AL2: 2024 | AM2: 2025 | AN2: 2026 | AO2: 2027 | AP2: 2028 | AQ2: 2029 | AR2: 2030 | AS2: 2031 | AT2: 2032 | AU2: 2033 | AV2: 2034 | AW2: 2035 | AX2: 2036 | AY2: 2037 | AZ2: 2038 | BA2: 2039 | BB2: 2040 | BC2: 2041 | BD2: 2042 | BE2: 2043 | BF2: 2044 | BG2: 2045 | BH2: 2046 | BI2: 2047 | BJ2: 2048 | BK2: 2049 | BL2: 2050 | BM2: 2051 | BN2: 2052 | BO2: 2053 | BP2: 2054 | BQ2: 2055 | BR2: 2056 | BS2: 2057 | BT2: 2058 | BU2: 2059 | BV2: 2060 | BW2: 2061 | BX2: 2062 | BY2: 2063 | BZ2: 2064 | CA2: 2065 | CB2: 2066 | CC2: 2067 | CD2: 2068 | CE2: 2069 | CF2: 2070 | CG2: 2071 | CH2: 2072 | CI2: 2073 | CJ2: 2074 | CK2: 2075 | CL2: 2076 | CM2: 2077 | CN2: 2078 | CO2: 2079 | CP2: 2080 | CQ2: 2081 | CR2: 2082 | CS2: 2083 | CT2: 2084 | CU2: 2085 | CV2: 2086 | CW2: 2087 | CX2: 2088 | CY2: 2089 | CZ2: 2090 | DA2: 2091 | DB2: 2092 | DC2: 2093 | DD2: 2094 | DE2: 2095 | DF2: 2096 | DG2: 2097 | DH2: 2098 | DI2: 2099 | DJ2: 2100 | DL2: INDEX
C3: BC | G3: Service requested | J3: .Electricity.Utility Generation | K3: Statistics Canada | L3: Remove transmission losses from source calc; added back using multipliers below | M3: =calcs!$B$5 -> MWh | N3: =IFERROR(calcs!F28/SUMIFS(N$37:N$95,$C$37:$C$95,$C3),calcs!F28) -> 49518225 | O3: =IFERROR(calcs!G28/SUMIFS(O$37:O$95,$C$37:$C$95,$C3),calcs!G28) -> 39174669 | P3: =IFERROR(calcs!H28/SUMIFS(P$37:P$95,$C$37:$C$95,$C3),calcs!H28) -> 47135891 | Q3: =IFERROR(calcs!I28/SUMIFS(Q$37:Q$95,$C$37:$C$95,$C3),calcs!I28) -> 44924424 | R3: =IFERROR(calcs!J28/SUMIFS(R$37:R$95,$C$37:$C$95,$C3),calcs!J28) -> 42555966 | S3: =IFERROR(calcs!K28/SUMIFS(S$37:S$95,$C$37:$C$95,$C3),calcs!K28) -> 49381910 | T3: =IFERROR(calcs!L28/SUMIFS(T$37:T$95,$C$37:$C$95,$C3),calcs!L28) -> 43863717 | U3: =IFERROR(calcs!M28/SUMIFS(U$37:U$95,$C$37:$C$95,$C3),calcs!M28) -> 52795104 | ... DJ3: =IFERROR(calcs!DB28/SUMIFS(DJ$37:DJ$95,$C$37:$C$95,$C3),calcs!DB28) -> 94693886 | DL3: =_xlfn.CONCAT(A3,C3,F3:J3) -> BCService requested.Electricity.Utility Generation
C4: AB | G4: Service requested | J4: .Electricity.Utility Generation | K4: Statistics Canada | L4: Remove transmission losses from source calc; added back using multipliers below | M4: =calcs!$B$5 -> MWh | N4: =IFERROR(calcs!F29/SUMIFS(N$37:N$95,$C$37:$C$95,$C4),calcs!F29) -> 49261204 | O4: =IFERROR(calcs!G29/SUMIFS(O$37:O$95,$C$37:$C$95,$C4),calcs!G29) -> 51589796 | P4: =IFERROR(calcs!H29/SUMIFS(P$37:P$95,$C$37:$C$95,$C4),calcs!H29) -> 51810253 | Q4: =IFERROR(calcs!I29/SUMIFS(Q$37:Q$95,$C$37:$C$95,$C4),calcs!I29) -> 48965584 | R4: =IFERROR(calcs!J29/SUMIFS(R$37:R$95,$C$37:$C$95,$C4),calcs!J29) -> 51334202 | S4: =IFERROR(calcs!K29/SUMIFS(S$37:S$95,$C$37:$C$95,$C4),calcs!K29) -> 53188643 | T4: =IFERROR(calcs!L29/SUMIFS(T$37:T$95,$C$37:$C$95,$C4),calcs!L29) -> 49859223 | U4: =IFERROR(calcs!M29/SUMIFS(U$37:U$95,$C$37:$C$95,$C4),calcs!M29) -> 51315530 | ... DJ4: =IFERROR(calcs!DB29/SUMIFS(DJ$37:DJ$95,$C$37:$C$95,$C4),calcs!DB29) -> 83720487 | DL4: =_xlfn.CONCAT(A4,C4,F4:J4) -> ABService requested.Electricity.Utility Generation
C5: SK | G5: Service requested | J5: .Electricity.Utility Generation | K5: Statistics Canada | L5: Remove transmission losses from source calc; added back using multipliers below | M5: =calcs!$B$5 -> MWh | N5: =IFERROR(calcs!F30/SUMIFS(N$37:N$95,$C$37:$C$95,$C5),calcs!F30) -> 15466236 | O5: =IFERROR(calcs!G30/SUMIFS(O$37:O$95,$C$37:$C$95,$C5),calcs!G30) -> 14964091 | P5: =IFERROR(calcs!H30/SUMIFS(P$37:P$95,$C$37:$C$95,$C5),calcs!H30) -> 15587196 | Q5: =IFERROR(calcs!I30/SUMIFS(Q$37:Q$95,$C$37:$C$95,$C5),calcs!I30) -> 17343996 | R5: =IFERROR(calcs!J30/SUMIFS(R$37:R$95,$C$37:$C$95,$C5),calcs!J30) -> 17022256 | S5: =IFERROR(calcs!K30/SUMIFS(S$37:S$95,$C$37:$C$95,$C5),calcs!K30) -> 17573596 | T5: =IFERROR(calcs!L30/SUMIFS(T$37:T$95,$C$37:$C$95,$C5),calcs!L30) -> 17483548 | U5: =IFERROR(calcs!M30/SUMIFS(U$37:U$95,$C$37:$C$95,$C5),calcs!M30) -> 18021277 | ... DJ5: =IFERROR(calcs!DB30/SUMIFS(DJ$37:DJ$95,$C$37:$C$95,$C5),calcs!DB30) -> 35970101 | DL5: =_xlfn.CONCAT(A5,C5,F5:J5) -> SKService requested.Electricity.Utility Generation
C6: MB | G6: Service requested | J6: .Electricity.Utility Generation | K6: Statistics Canada | L6: Remove transmission losses from source calc; added back using multipliers below | M6: =calcs!$B$5 -> MWh | N6: =IFERROR(calcs!F31/SUMIFS(N$37:N$95,$C$37:$C$95,$C6),calcs!F31) -> 28488518 | O6: =IFERROR(calcs!G31/SUMIFS(O$37:O$95,$C$37:$C$95,$C6),calcs!G31) -> 29321948 | P6: =IFERROR(calcs!H31/SUMIFS(P$37:P$95,$C$37:$C$95,$C6),calcs!H31) -> 25786417 | Q6: =IFERROR(calcs!I31/SUMIFS(Q$37:Q$95,$C$37:$C$95,$C6),calcs!I31) -> 18518484 | R6: =IFERROR(calcs!J31/SUMIFS(R$37:R$95,$C$37:$C$95,$C6),calcs!J31) -> 24265035 | S6: =IFERROR(calcs!K31/SUMIFS(S$37:S$95,$C$37:$C$95,$C6),calcs!K31) -> 32455372 | T6: =IFERROR(calcs!L31/SUMIFS(T$37:T$95,$C$37:$C$95,$C6),calcs!L31) -> 30197739 | U6: =IFERROR(calcs!M31/SUMIFS(U$37:U$95,$C$37:$C$95,$C6),calcs!M31) -> 30151226 | ... DJ6: =IFERROR(calcs!DB31/SUMIFS(DJ$37:DJ$95,$C$37:$C$95,$C6),calcs!DB31) -> 56237559 | DL6: =_xlfn.CONCAT(A6,C6,F6:J6) -> MBService requested.Electricity.Utility Generation
C7: ON | G7: Service requested | J7: .Electricity.Utility Generation | K7: Statistics Canada | L7: Remove transmission losses from source calc; added back using multipliers below | M7: =calcs!$B$5 -> MWh | N7: =IFERROR(calcs!F32/SUMIFS(N$37:N$95,$C$37:$C$95,$C7),calcs!F32) -> 1.3885658e+08 | O7: =IFERROR(calcs!G32/SUMIFS(O$37:O$95,$C$37:$C$95,$C7),calcs!G32) -> 1.3851772e+08 | P7: =IFERROR(calcs!H32/SUMIFS(P$37:P$95,$C$37:$C$95,$C7),calcs!H32) -> 1.3951038e+08 | Q7: =IFERROR(calcs!I32/SUMIFS(Q$37:Q$95,$C$37:$C$95,$C7),calcs!I32) -> 1.3560108e+08 | R7: =IFERROR(calcs!J32/SUMIFS(R$37:R$95,$C$37:$C$95,$C7),calcs!J32) -> 1.4060164e+08 | S7: =IFERROR(calcs!K32/SUMIFS(S$37:S$95,$C$37:$C$95,$C7),calcs!K32) -> 1.4378748e+08 | T7: =IFERROR(calcs!L32/SUMIFS(T$37:T$95,$C$37:$C$95,$C7),calcs!L32) -> 1.4517551e+08 | U7: =IFERROR(calcs!M32/SUMIFS(U$37:U$95,$C$37:$C$95,$C7),calcs!M32) -> 1.4453862e+08 | ... DJ7: =IFERROR(calcs!DB32/SUMIFS(DJ$37:DJ$95,$C$37:$C$95,$C7),calcs!DB32) -> 2.3182849e+08 | DL7: =_xlfn.CONCAT(A7,C7,F7:J7) -> ONService requested.Electricity.Utility Generation
C8: QC | G8: Service requested | J8: .Electricity.Utility Generation | K8: Statistics Canada | L8: Remove transmission losses from source calc; added back using multipliers below | M8: =calcs!$B$5 -> MWh | N8: =IFERROR(calcs!F33/SUMIFS(N$37:N$95,$C$37:$C$95,$C8),calcs!F33) -> 1.4742535e+08 | O8: =IFERROR(calcs!G33/SUMIFS(O$37:O$95,$C$37:$C$95,$C8),calcs!G33) -> 1.3948905e+08 | P8: =IFERROR(calcs!H33/SUMIFS(P$37:P$95,$C$37:$C$95,$C8),calcs!H33) -> 1.4459838e+08 | Q8: =IFERROR(calcs!I33/SUMIFS(Q$37:Q$95,$C$37:$C$95,$C8),calcs!I33) -> 1.4510863e+08 | R8: =IFERROR(calcs!J33/SUMIFS(R$37:R$95,$C$37:$C$95,$C8),calcs!J33) -> 1.4068576e+08 | S8: =IFERROR(calcs!K33/SUMIFS(S$37:S$95,$C$37:$C$95,$C8),calcs!K33) -> 1.4858649e+08 | T8: =IFERROR(calcs!L33/SUMIFS(T$37:T$95,$C$37:$C$95,$C8),calcs!L33) -> 1.4716999e+08 | U8: =IFERROR(calcs!M33/SUMIFS(U$37:U$95,$C$37:$C$95,$C8),calcs!M33) -> 1.5938153e+08 | ... DJ8: =IFERROR(calcs!DB33/SUMIFS(DJ$37:DJ$95,$C$37:$C$95,$C8),calcs!DB33) -> 3.0741502e+08 | DL8: =_xlfn.CONCAT(A8,C8,F8:J8) -> QCService requested.Electricity.Utility Generation
C9: NB | G9: Service requested | J9: .Electricity.Utility Generation | K9: Statistics Canada | L9: Remove transmission losses from source calc; added back using multipliers below | M9: =calcs!$B$5 -> MWh | N9: =IFERROR(calcs!F34/SUMIFS(N$37:N$95,$C$37:$C$95,$C9),calcs!F34) -> 17540499 | O9: =IFERROR(calcs!G34/SUMIFS(O$37:O$95,$C$37:$C$95,$C9),calcs!G34) -> 18629149 | P9: =IFERROR(calcs!H34/SUMIFS(P$37:P$95,$C$37:$C$95,$C9),calcs!H34) -> 16566466 | Q9: =IFERROR(calcs!I34/SUMIFS(Q$37:Q$95,$C$37:$C$95,$C9),calcs!I34) -> 18063541 | R9: =IFERROR(calcs!J34/SUMIFS(R$37:R$95,$C$37:$C$95,$C9),calcs!J34) -> 18724425 | S9: =IFERROR(calcs!K34/SUMIFS(S$37:S$95,$C$37:$C$95,$C9),calcs!K34) -> 20294552 | T9: =IFERROR(calcs!L34/SUMIFS(T$37:T$95,$C$37:$C$95,$C9),calcs!L34) -> 17495374 | U9: =IFERROR(calcs!M34/SUMIFS(U$37:U$95,$C$37:$C$95,$C9),calcs!M34) -> 16283968 | ... DJ9: =IFERROR(calcs!DB34/SUMIFS(DJ$37:DJ$95,$C$37:$C$95,$C9),calcs!DB34) -> 20221480 | DL9: =_xlfn.CONCAT(A9,C9,F9:J9) -> NBService requested.Electricity.Utility Generation
C10: NS | G10: Service requested | J10: .Electricity.Utility Generation | K10: Statistics Canada | L10: Remove transmission losses from source calc; added back using multipliers below | M10: =calcs!$B$5 -> MWh | N10: =IFERROR(calcs!F35/SUMIFS(N$37:N$95,$C$37:$C$95,$C10),calcs!F35) -> 11380405 | O10: =IFERROR(calcs!G35/SUMIFS(O$37:O$95,$C$37:$C$95,$C10),calcs!G35) -> 9741655.8 | P10: =IFERROR(calcs!H35/SUMIFS(P$37:P$95,$C$37:$C$95,$C10),calcs!H35) -> 8313383.6 | Q10: =IFERROR(calcs!I35/SUMIFS(Q$37:Q$95,$C$37:$C$95,$C10),calcs!I35) -> 9742238.1 | R10: =IFERROR(calcs!J35/SUMIFS(R$37:R$95,$C$37:$C$95,$C10),calcs!J35) -> 9826507.5 | S10: =IFERROR(calcs!K35/SUMIFS(S$37:S$95,$C$37:$C$95,$C10),calcs!K35) -> 12208535 | T10: =IFERROR(calcs!L35/SUMIFS(T$37:T$95,$C$37:$C$95,$C10),calcs!L35) -> 11213485 | U10: =IFERROR(calcs!M35/SUMIFS(U$37:U$95,$C$37:$C$95,$C10),calcs!M35) -> 12337083 | ... DJ10: =IFERROR(calcs!DB35/SUMIFS(DJ$37:DJ$95,$C$37:$C$95,$C10),calcs!DB35) -> 14887097 | DL10: =_xlfn.CONCAT(A10,C10,F10:J10) -> NSService requested.Electricity.Utility Generation
C11: PE | G11: Service requested | J11: .Electricity.Utility Generation | K11: Statistics Canada | L11: Remove transmission losses from source calc; added back using multipliers below | M11: =calcs!$B$5 -> MWh | N11: =IFERROR(calcs!F36/SUMIFS(N$37:N$95,$C$37:$C$95,$C11),calcs!F36) -> 54078.453 | O11: =IFERROR(calcs!G36/SUMIFS(O$37:O$95,$C$37:$C$95,$C11),calcs!G36) -> 54883.373 | P11: =IFERROR(calcs!H36/SUMIFS(P$37:P$95,$C$37:$C$95,$C11),calcs!H36) -> 32257.182 | Q11: =IFERROR(calcs!I36/SUMIFS(Q$37:Q$95,$C$37:$C$95,$C11),calcs!I36) -> 62477.402 | R11: =IFERROR(calcs!J36/SUMIFS(R$37:R$95,$C$37:$C$95,$C11),calcs!J36) -> 35462.92 | S11: =IFERROR(calcs!K36/SUMIFS(S$37:S$95,$C$37:$C$95,$C11),calcs!K36) -> 46417 | T11: =IFERROR(calcs!L36/SUMIFS(T$37:T$95,$C$37:$C$95,$C11),calcs!L36) -> 43777 | U11: =IFERROR(calcs!M36/SUMIFS(U$37:U$95,$C$37:$C$95,$C11),calcs!M36) -> 44732 | ... DJ11: =IFERROR(calcs!DB36/SUMIFS(DJ$37:DJ$95,$C$37:$C$95,$C11),calcs!DB36) -> 897049.34 | DL11: =_xlfn.CONCAT(A11,C11,F11:J11) -> PEService requested.Electricity.Utility Generation
C12: NL | G12: Service requested | J12: .Electricity.Utility Generation | K12: Statistics Canada | L12: Remove transmission losses from source calc; added back using multipliers below | M12: =calcs!$B$5 -> MWh | N12: =IFERROR(calcs!F37/SUMIFS(N$37:N$95,$C$37:$C$95,$C12),calcs!F37) -> 42755239 | O12: =IFERROR(calcs!G37/SUMIFS(O$37:O$95,$C$37:$C$95,$C12),calcs!G37) -> 40407630 | P12: =IFERROR(calcs!H37/SUMIFS(P$37:P$95,$C$37:$C$95,$C12),calcs!H37) -> 43383044 | Q12: =IFERROR(calcs!I37/SUMIFS(Q$37:Q$95,$C$37:$C$95,$C12),calcs!I37) -> 41199271 | R12: =IFERROR(calcs!J37/SUMIFS(R$37:R$95,$C$37:$C$95,$C12),calcs!J37) -> 40590690 | S12: =IFERROR(calcs!K37/SUMIFS(S$37:S$95,$C$37:$C$95,$C12),calcs!K37) -> 40322068 | T12: =IFERROR(calcs!L37/SUMIFS(T$37:T$95,$C$37:$C$95,$C12),calcs!L37) -> 41803350 | U12: =IFERROR(calcs!M37/SUMIFS(U$37:U$95,$C$37:$C$95,$C12),calcs!M37) -> 40443694 | ... DJ12: =IFERROR(calcs!DB37/SUMIFS(DJ$37:DJ$95,$C$37:$C$95,$C12),calcs!DB37) -> 68549804 | DL12: =_xlfn.CONCAT(A12,C12,F12:J12) -> NLService requested.Electricity.Utility Generation
C13: YT | G13: Service requested | J13: .Electricity.Utility Generation | K13: Statistics Canada | L13: Remove transmission losses from source calc; added back using multipliers below | M13: =calcs!$B$5 -> MWh | N13: =IFERROR(calcs!F38/SUMIFS(N$37:N$95,$C$37:$C$95,$C13),calcs!F38) -> 296253.05 | O13: =IFERROR(calcs!G38/SUMIFS(O$37:O$95,$C$37:$C$95,$C13),calcs!G38) -> 300926.45 | P13: =IFERROR(calcs!H38/SUMIFS(P$37:P$95,$C$37:$C$95,$C13),calcs!H38) -> 312432.19 | Q13: =IFERROR(calcs!I38/SUMIFS(Q$37:Q$95,$C$37:$C$95,$C13),calcs!I38) -> 320512.16 | R13: =IFERROR(calcs!J38/SUMIFS(R$37:R$95,$C$37:$C$95,$C13),calcs!J38) -> 329141.15 | S13: =IFERROR(calcs!K38/SUMIFS(S$37:S$95,$C$37:$C$95,$C13),calcs!K38) -> 343749 | T13: =IFERROR(calcs!L38/SUMIFS(T$37:T$95,$C$37:$C$95,$C13),calcs!L38) -> 359031 | U13: =IFERROR(calcs!M38/SUMIFS(U$37:U$95,$C$37:$C$95,$C13),calcs!M38) -> 354694 | ... DJ13: =IFERROR(calcs!DB38/SUMIFS(DJ$37:DJ$95,$C$37:$C$95,$C13),calcs!DB38) -> 966553.57 | DL13: =_xlfn.CONCAT(A13,C13,F13:J13) -> YTService requested.Electricity.Utility Generation
C14: NT | G14: Service requested | J14: .Electricity.Utility Generation | K14: Statistics Canada | L14: Remove transmission losses from source calc; added back using multipliers below | M14: =calcs!$B$5 -> MWh | N14: =IFERROR(calcs!F39/SUMIFS(N$37:N$95,$C$37:$C$95,$C14),calcs!F39) -> 441653 | O14: =IFERROR(calcs!G39/SUMIFS(O$37:O$95,$C$37:$C$95,$C14),calcs!G39) -> 476052 | P14: =IFERROR(calcs!H39/SUMIFS(P$37:P$95,$C$37:$C$95,$C14),calcs!H39) -> 425552 | Q14: =IFERROR(calcs!I39/SUMIFS(Q$37:Q$95,$C$37:$C$95,$C14),calcs!I39) -> 464346 | R14: =IFERROR(calcs!J39/SUMIFS(R$37:R$95,$C$37:$C$95,$C14),calcs!J39) -> 364481 | S14: =IFERROR(calcs!K39/SUMIFS(S$37:S$95,$C$37:$C$95,$C14),calcs!K39) -> 336684 | T14: =IFERROR(calcs!L39/SUMIFS(T$37:T$95,$C$37:$C$95,$C14),calcs!L39) -> 326103 | U14: =IFERROR(calcs!M39/SUMIFS(U$37:U$95,$C$37:$C$95,$C14),calcs!M39) -> 333165 | ... DJ14: =IFERROR(calcs!DB39/SUMIFS(DJ$37:DJ$95,$C$37:$C$95,$C14),calcs!DB39) -> 545496.24 | DL14: =_xlfn.CONCAT(A14,C14,F14:J14) -> NTService requested.Electricity.Utility Generation
... C17: TR | G17: Service requested | J17: .Electricity.Utility Generation | K17: Statistics Canada | L17: Remove transmission losses from source calc; added back using multipliers below | M17: =calcs!$B$5 -> MWh | N17: =IFERROR(calcs!F42/SUMIFS(N$37:N$95,$C$37:$C$95,$C17),calcs!F42) -> 737906.05 | O17: =IFERROR(calcs!G42/SUMIFS(O$37:O$95,$C$37:$C$95,$C17),calcs!G42) -> 776978.44 | P17: =IFERROR(calcs!H42/SUMIFS(P$37:P$95,$C$37:$C$95,$C17),calcs!H42) -> 737984.18 | Q17: =IFERROR(calcs!I42/SUMIFS(Q$37:Q$95,$C$37:$C$95,$C17),calcs!I42) -> 784858.16 | R17: =IFERROR(calcs!J42/SUMIFS(R$37:R$95,$C$37:$C$95,$C17),calcs!J42) -> 833067.15 | S17: =IFERROR(calcs!K42/SUMIFS(S$37:S$95,$C$37:$C$95,$C17),calcs!K42) -> 822078 | T17: =IFERROR(calcs!L42/SUMIFS(T$37:T$95,$C$37:$C$95,$C17),calcs!L42) -> 829843 | U17: =IFERROR(calcs!M42/SUMIFS(U$37:U$95,$C$37:$C$95,$C17),calcs!M42) -> 836740 | ... DJ17: =IFERROR(calcs!DB42/SUMIFS(DJ$37:DJ$95,$C$37:$C$95,$C17),calcs!DB42) -> 1837898.9 | DL17: =_xlfn.CONCAT(A17,C17,F17:J17) -> TRService requested.Electricity.Utility Generation
DL18: =_xlfn.CONCAT(A18,C18,F18:J18)
A19: # Units | DL19: =_xlfn.CONCAT(A19,C19,F19:J19) -> # Units
A20: .Electricity | G20: Service provided | K20: JCIMS | M20: GJ | DL20: =_xlfn.CONCAT(A20,C20,F20:J20) -> .ElectricityService provided
A21: .Electricity.Utility Generation | G21: Service provided | K21: JCIMS | M21: MWh | DL21: =_xlfn.CONCAT(A21,C21,F21:J21) -> .Electricity.Utility GenerationService provided
A22: .Electricity.Utility Generation.Base Load | G22: Service provided | K22: JCIMS | M22: MWh | DL22: =_xlfn.CONCAT(A22,C22,F22:J22) -> .Electricity.Utility Generation.Base LoadService provided
A23: .Electricity.Utility Generation.Shoulder Load | G23: Service provided | K23: JCIMS | M23: MWh | DL23: =_xlfn.CONCAT(A23,C23,F23:J23) -> .Electricity.Utility Generation.Shoulder LoadService provided
A24: .Electricity.Utility Generation.Peak Load | G24: Service provided | K24: JCIMS | M24: MWh | DL24: =_xlfn.CONCAT(A24,C24,F24:J24) -> .Electricity.Utility Generation.Peak LoadService provided
A25: .Electricity.Storage | G25: Service provided | K25: JCIMS | M25: MWh | DL25: =_xlfn.CONCAT(A25,C25,F25:J25) -> .Electricity.StorageService provided
A26: .Electricity.Storage.Battery | G26: Service provided | K26: JCIMS | M26: MWh | DL26: =_xlfn.CONCAT(A26,C26,F26:J26) -> .Electricity.Storage.BatteryService provided
A27: .Electricity.Storage.Seasonal | G27: Service provided | K27: JCIMS | M27: MWh | DL27: =_xlfn.CONCAT(A27,C27,F27:J27) -> .Electricity.Storage.SeasonalService provided
A28: .Electricity.Transmission | G28: Service provided | K28: JCIMS | M28: unit | DL28: =_xlfn.CONCAT(A28,C28,F28:J28) -> .Electricity.TransmissionService provided
A29: .Electricity.CCS | G29: Service provided | K29: JCIMS | M29: tCO2 | DL29: =_xlfn.CONCAT(A29,C29,F29:J29) -> .Electricity.CCSService provided
A30: .Electricity.CCS.CCS_Coal | G30: Service provided | K30: JCIMS | M30: tCO2 | DL30: =_xlfn.CONCAT(A30,C30,F30:J30) -> .Electricity.CCS.CCS_CoalService provided
A31: .Electricity.CCS.CCS_Biomass | G31: Service provided | K31: JCIMS | M31: tCO2 | DL31: =_xlfn.CONCAT(A31,C31,F31:J31) -> .Electricity.CCS.CCS_BiomassService provided
A32: .Electricity.CCS.CCS_Natural Gas | G32: Service provided | K32: JCIMS | M32: tCO2 | DL32: =_xlfn.CONCAT(A32,C32,F32:J32) -> .Electricity.CCS.CCS_Natural GasService provided
DL33: =_xlfn.CONCAT(A33,C33,F33:J33)
A34: # Values | DL34: =_xlfn.CONCAT(A34,C34,F34:J34) -> # Values
A35: .Electricity | G35: Service requested | J35: .Electricity.Utility Generation | K35: JCIMS | M35: MWh | N35: =1/3.6 -> 0.27777778 | O35: =1/3.6 -> 0.27777778 | P35: =1/3.6 -> 0.27777778 | Q35: =1/3.6 -> 0.27777778 | R35: =1/3.6 -> 0.27777778 | S35: =1/3.6 -> 0.27777778 | T35: =1/3.6 -> 0.27777778 | U35: =1/3.6 -> 0.27777778 | ... DJ35: =1/3.6 -> 0.27777778 | DL35: =_xlfn.CONCAT(A35,C35,F35:J35) -> .ElectricityService requested.Electricity.Utility Generation
DL36: =_xlfn.CONCAT(A36,C36,F36:J36)
A37: .Electricity.Utility Generation | C37: BC | G37: Service requested | J37: .Electricity.Utility Generation.Base Load | K37: JCIMS | L37: Currently accounts for transmission losses | M37: MWh | N37: 0.87048461 | O37: 0.87048461 | P37: 0.87048461 | Q37: 0.87048461 | R37: 0.87048461 | S37: 0.87048461 | T37: 0.87048461 | U37: 0.87048461 | V37: 0.87048461 | W37: 0.87048461 | X37: 0.87048461 | Y37: 0.87048461 | Z37: 0.87048461 | AA37: 0.87048461 | AB37: 0.87048461 | AC37: 0.87048461 | AD37: 0.87048461 | AE37: 0.87048461 | AF37: 0.87048461 | AG37: 0.87048461 | AH37: 0.87048461 | AI37: 0.87048461 | AJ37: 0.87048461 | AK37: 0.87048461 | AL37: 0.87048461 | AM37: 0.87048461 | AN37: 0.87048461 | AO37: 0.87048461 | AP37: 0.87048461 | AQ37: 0.87048461 | AR37: 0.87048461 | AS37: 0.87048461 | AT37: 0.87048461 | AU37: 0.87048461 | AV37: 0.87048461 | AW37: 0.87048461 | AX37: 0.87048461 | AY37: 0.87048461 | AZ37: 0.87048461 | BA37: 0.87048461 | BB37: 0.87048461 | BC37: 0.87048461 | BD37: 0.87048461 | BE37: 0.87048461 | BF37: 0.87048461 | BG37: 0.87048461 | BH37: 0.87048461 | BI37: 0.87048461 | BJ37: 0.87048461 | BK37: 0.87048461 | BL37: 0.87048461 | BM37: 0.87048461 | BN37: 0.87048461 | BO37: 0.87048461 | BP37: 0.87048461 | BQ37: 0.87048461 | BR37: 0.87048461 | BS37: 0.87048461 | BT37: 0.87048461 | BU37: 0.87048461 | BV37: 0.87048461 | BW37: 0.87048461 | BX37: 0.87048461 | BY37: 0.87048461 | BZ37: 0.87048461 | CA37: 0.87048461 | CB37: 0.87048461 | CC37: 0.87048461 | CD37: 0.87048461 | CE37: 0.87048461 | CF37: 0.87048461 | CG37: 0.87048461 | CH37: 0.87048461 | CI37: 0.87048461 | CJ37: 0.87048461 | CK37: 0.87048461 | CL37: 0.87048461 | CM37: 0.87048461 | CN37: 0.87048461 | CO37: 0.87048461 | CP37: 0.87048461 | CQ37: 0.87048461 | CR37: 0.87048461 | CS37: 0.87048461 | CT37: 0.87048461 | CU37: 0.87048461 | CV37: 0.87048461 | CW37: 0.87048461 | CX37: 0.87048461 | CY37: 0.87048461 | CZ37: 0.87048461 | DA37: 0.87048461 | DB37: 0.87048461 | DC37: 0.87048461 | DD37: 0.87048461 | DE37: 0.87048461 | DF37: 0.87048461 | DG37: 0.87048461 | DH37: 0.87048461 | DI37: 0.87048461 | DJ37: 0.87048461 | DL37: =_xlfn.CONCAT(A37,C37,F37:J37) -> .Electricity.Utility GenerationBCService requested.Electricity.Utility Generation.Base Load
A38: .Electricity.Utility Generation | C38: BC | G38: Service requested | J38: .Electricity.Utility Generation.Shoulder Load | K38: JCIMS | L38: Currently accounts for transmission losses | M38: MWh | N38: 0.17094356 | O38: 0.17094356 | P38: 0.17094356 | Q38: 0.17094356 | R38: 0.17094356 | S38: 0.17094356 | T38: 0.17094356 | U38: 0.17094356 | V38: 0.17094356 | W38: 0.17094356 | X38: 0.17094356 | Y38: 0.17094356 | Z38: 0.17094356 | AA38: 0.17094356 | AB38: 0.17094356 | AC38: 0.17094356 | AD38: 0.17094356 | AE38: 0.17094356 | AF38: 0.17094356 | AG38: 0.17094356 | AH38: 0.17094356 | AI38: 0.17094356 | AJ38: 0.17094356 | AK38: 0.17094356 | AL38: 0.17094356 | AM38: 0.17094356 | AN38: 0.17094356 | AO38: 0.17094356 | AP38: 0.17094356 | AQ38: 0.17094356 | AR38: 0.17094356 | AS38: 0.17094356 | AT38: 0.17094356 | AU38: 0.17094356 | AV38: 0.17094356 | AW38: 0.17094356 | AX38: 0.17094356 | AY38: 0.17094356 | AZ38: 0.17094356 | BA38: 0.17094356 | BB38: 0.17094356 | BC38: 0.17094356 | BD38: 0.17094356 | BE38: 0.17094356 | BF38: 0.17094356 | BG38: 0.17094356 | BH38: 0.17094356 | BI38: 0.17094356 | BJ38: 0.17094356 | BK38: 0.17094356 | BL38: 0.17094356 | BM38: 0.17094356 | BN38: 0.17094356 | BO38: 0.17094356 | BP38: 0.17094356 | BQ38: 0.17094356 | BR38: 0.17094356 | BS38: 0.17094356 | BT38: 0.17094356 | BU38: 0.17094356 | BV38: 0.17094356 | BW38: 0.17094356 | BX38: 0.17094356 | BY38: 0.17094356 | BZ38: 0.17094356 | CA38: 0.17094356 | CB38: 0.17094356 | CC38: 0.17094356 | CD38: 0.17094356 | CE38: 0.17094356 | CF38: 0.17094356 | CG38: 0.17094356 | CH38: 0.17094356 | CI38: 0.17094356 | CJ38: 0.17094356 | CK38: 0.17094356 | CL38: 0.17094356 | CM38: 0.17094356 | CN38: 0.17094356 | CO38: 0.17094356 | CP38: 0.17094356 | CQ38: 0.17094356 | CR38: 0.17094356 | CS38: 0.17094356 | CT38: 0.17094356 | CU38: 0.17094356 | CV38: 0.17094356 | CW38: 0.17094356 | CX38: 0.17094356 | CY38: 0.17094356 | CZ38: 0.17094356 | DA38: 0.17094356 | DB38: 0.17094356 | DC38: 0.17094356 | DD38: 0.17094356 | DE38: 0.17094356 | DF38: 0.17094356 | DG38: 0.17094356 | DH38: 0.17094356 | DI38: 0.17094356 | DJ38: 0.17094356 | DL38: =_xlfn.CONCAT(A38,C38,F38:J38) -> .Electricity.Utility GenerationBCService requested.Electricity.Utility Generation.Shoulder Load
A39: .Electricity.Utility Generation | C39: BC | G39: Service requested | J39: .Electricity.Utility Generation.Peak Load | K39: JCIMS | L39: Currently accounts for transmission losses | M39: MWh | N39: 0.054702484 | O39: 0.054702484 | P39: 0.054702484 | Q39: 0.054702484 | R39: 0.054702484 | S39: 0.054702484 | T39: 0.054702484 | U39: 0.054702484 | V39: 0.054702484 | W39: 0.054702484 | X39: 0.054702484 | Y39: 0.054702484 | Z39: 0.054702484 | AA39: 0.054702484 | AB39: 0.054702484 | AC39: 0.054702484 | AD39: 0.054702484 | AE39: 0.054702484 | AF39: 0.054702484 | AG39: 0.054702484 | AH39: 0.054702484 | AI39: 0.054702484 | AJ39: 0.054702484 | AK39: 0.054702484 | AL39: 0.054702484 | AM39: 0.054702484 | AN39: 0.054702484 | AO39: 0.054702484 | AP39: 0.054702484 | AQ39: 0.054702484 | AR39: 0.054702484 | AS39: 0.054702484 | AT39: 0.054702484 | AU39: 0.054702484 | AV39: 0.054702484 | AW39: 0.054702484 | AX39: 0.054702484 | AY39: 0.054702484 | AZ39: 0.054702484 | BA39: 0.054702484 | BB39: 0.054702484 | BC39: 0.054702484 | BD39: 0.054702484 | BE39: 0.054702484 | BF39: 0.054702484 | BG39: 0.054702484 | BH39: 0.054702484 | BI39: 0.054702484 | BJ39: 0.054702484 | BK39: 0.054702484 | BL39: 0.054702484 | BM39: 0.054702484 | BN39: 0.054702484 | BO39: 0.054702484 | BP39: 0.054702484 | BQ39: 0.054702484 | BR39: 0.054702484 | BS39: 0.054702484 | BT39: 0.054702484 | BU39: 0.054702484 | BV39: 0.054702484 | BW39: 0.054702484 | BX39: 0.054702484 | BY39: 0.054702484 | BZ39: 0.054702484 | CA39: 0.054702484 | CB39: 0.054702484 | CC39: 0.054702484 | CD39: 0.054702484 | CE39: 0.054702484 | CF39: 0.054702484 | CG39: 0.054702484 | CH39: 0.054702484 | CI39: 0.054702484 | CJ39: 0.054702484 | CK39: 0.054702484 | CL39: 0.054702484 | CM39: 0.054702484 | CN39: 0.054702484 | CO39: 0.054702484 | CP39: 0.054702484 | CQ39: 0.054702484 | CR39: 0.054702484 | CS39: 0.054702484 | CT39: 0.054702484 | CU39: 0.054702484 | CV39: 0.054702484 | CW39: 0.054702484 | CX39: 0.054702484 | CY39: 0.054702484 | CZ39: 0.054702484 | DA39: 0.054702484 | DB39: 0.054702484 | DC39: 0.054702484 | DD39: 0.054702484 | DE39: 0.054702484 | DF39: 0.054702484 | DG39: 0.054702484 | DH39: 0.054702484 | DI39: 0.054702484 | DJ39: 0.054702484 | DL39: =_xlfn.CONCAT(A39,C39,F39:J39) -> .Electricity.Utility GenerationBCService requested.Electricity.Utility Generation.Peak Load
DL40: =_xlfn.CONCAT(A40,C40,F40:J40)
A41: .Electricity.Utility Generation | C41: AB | G41: Service requested | J41: .Electricity.Utility Generation.Base Load | K41: JCIMS | L41: Currently accounts for transmission losses | M41: MWh | N41: 0.86160474 | O41: 0.86160474 | P41: 0.86160474 | Q41: 0.86160474 | R41: 0.86160474 | S41: 0.86160474 | T41: 0.86160474 | U41: 0.86160474 | V41: 0.86160474 | W41: 0.86160474 | X41: 0.86160474 | Y41: 0.86160474 | Z41: 0.86160474 | AA41: 0.86160474 | AB41: 0.86160474 | AC41: 0.86160474 | AD41: 0.86160474 | AE41: 0.86160474 | AF41: 0.86160474 | AG41: 0.86160474 | AH41: 0.86160474 | AI41: 0.86160474 | AJ41: 0.86160474 | AK41: 0.86160474 | AL41: 0.86160474 | AM41: 0.86160474 | AN41: 0.86160474 | AO41: 0.86160474 | AP41: 0.86160474 | AQ41: 0.86160474 | AR41: 0.86160474 | AS41: 0.86160474 | AT41: 0.86160474 | AU41: 0.86160474 | AV41: 0.86160474 | AW41: 0.86160474 | AX41: 0.86160474 | AY41: 0.86160474 | AZ41: 0.86160474 | BA41: 0.86160474 | BB41: 0.86160474 | BC41: 0.86160474 | BD41: 0.86160474 | BE41: 0.86160474 | BF41: 0.86160474 | BG41: 0.86160474 | BH41: 0.86160474 | BI41: 0.86160474 | BJ41: 0.86160474 | BK41: 0.86160474 | BL41: 0.86160474 | BM41: 0.86160474 | BN41: 0.86160474 | BO41: 0.86160474 | BP41: 0.86160474 | BQ41: 0.86160474 | BR41: 0.86160474 | BS41: 0.86160474 | BT41: 0.86160474 | BU41: 0.86160474 | BV41: 0.86160474 | BW41: 0.86160474 | BX41: 0.86160474 | BY41: 0.86160474 | BZ41: 0.86160474 | CA41: 0.86160474 | CB41: 0.86160474 | CC41: 0.86160474 | CD41: 0.86160474 | CE41: 0.86160474 | CF41: 0.86160474 | CG41: 0.86160474 | CH41: 0.86160474 | CI41: 0.86160474 | CJ41: 0.86160474 | CK41: 0.86160474 | CL41: 0.86160474 | CM41: 0.86160474 | CN41: 0.86160474 | CO41: 0.86160474 | CP41: 0.86160474 | CQ41: 0.86160474 | CR41: 0.86160474 | CS41: 0.86160474 | CT41: 0.86160474 | CU41: 0.86160474 | CV41: 0.86160474 | CW41: 0.86160474 | CX41: 0.86160474 | CY41: 0.86160474 | CZ41: 0.86160474 | DA41: 0.86160474 | DB41: 0.86160474 | DC41: 0.86160474 | DD41: 0.86160474 | DE41: 0.86160474 | DF41: 0.86160474 | DG41: 0.86160474 | DH41: 0.86160474 | DI41: 0.86160474 | DJ41: 0.86160474 | DL41: =_xlfn.CONCAT(A41,C41,F41:J41) -> .Electricity.Utility GenerationABService requested.Electricity.Utility Generation.Base Load
A42: .Electricity.Utility Generation | C42: AB | G42: Service requested | J42: .Electricity.Utility Generation.Shoulder Load | K42: JCIMS | L42: Currently accounts for transmission losses | M42: MWh | N42: 0.16155089 | O42: 0.16155089 | P42: 0.16155089 | Q42: 0.16155089 | R42: 0.16155089 | S42: 0.16155089 | T42: 0.16155089 | U42: 0.16155089 | V42: 0.16155089 | W42: 0.16155089 | X42: 0.16155089 | Y42: 0.16155089 | Z42: 0.16155089 | AA42: 0.16155089 | AB42: 0.16155089 | AC42: 0.16155089 | AD42: 0.16155089 | AE42: 0.16155089 | AF42: 0.16155089 | AG42: 0.16155089 | AH42: 0.16155089 | AI42: 0.16155089 | AJ42: 0.16155089 | AK42: 0.16155089 | AL42: 0.16155089 | AM42: 0.16155089 | AN42: 0.16155089 | AO42: 0.16155089 | AP42: 0.16155089 | AQ42: 0.16155089 | AR42: 0.16155089 | AS42: 0.16155089 | AT42: 0.16155089 | AU42: 0.16155089 | AV42: 0.16155089 | AW42: 0.16155089 | AX42: 0.16155089 | AY42: 0.16155089 | AZ42: 0.16155089 | BA42: 0.16155089 | BB42: 0.16155089 | BC42: 0.16155089 | BD42: 0.16155089 | BE42: 0.16155089 | BF42: 0.16155089 | BG42: 0.16155089 | BH42: 0.16155089 | BI42: 0.16155089 | BJ42: 0.16155089 | BK42: 0.16155089 | BL42: 0.16155089 | BM42: 0.16155089 | BN42: 0.16155089 | BO42: 0.16155089 | BP42: 0.16155089 | BQ42: 0.16155089 | BR42: 0.16155089 | BS42: 0.16155089 | BT42: 0.16155089 | BU42: 0.16155089 | BV42: 0.16155089 | BW42: 0.16155089 | BX42: 0.16155089 | BY42: 0.16155089 | BZ42: 0.16155089 | CA42: 0.16155089 | CB42: 0.16155089 | CC42: 0.16155089 | CD42: 0.16155089 | CE42: 0.16155089 | CF42: 0.16155089 | CG42: 0.16155089 | CH42: 0.16155089 | CI42: 0.16155089 | CJ42: 0.16155089 | CK42: 0.16155089 | CL42: 0.16155089 | CM42: 0.16155089 | CN42: 0.16155089 | CO42: 0.16155089 | CP42: 0.16155089 | CQ42: 0.16155089 | CR42: 0.16155089 | CS42: 0.16155089 | CT42: 0.16155089 | CU42: 0.16155089 | CV42: 0.16155089 | CW42: 0.16155089 | CX42: 0.16155089 | CY42: 0.16155089 | CZ42: 0.16155089 | DA42: 0.16155089 | DB42: 0.16155089 | DC42: 0.16155089 | DD42: 0.16155089 | DE42: 0.16155089 | DF42: 0.16155089 | DG42: 0.16155089 | DH42: 0.16155089 | DI42: 0.16155089 | DJ42: 0.16155089 | DL42: =_xlfn.CONCAT(A42,C42,F42:J42) -> .Electricity.Utility GenerationABService requested.Electricity.Utility Generation.Shoulder Load
...

Sheet calcs
A1: Source | B1: Unit | C1: Parameter | AD1: Assumptions shown in red text / yellow highlight
AD2: Use: | AE2: Reference
AD3: Assumed CAGR (Reference) | AG3: Assumed CAGR (Net Zero)
F4: 2000 | G4: 2001 | H4: 2002 | I4: 2003 | J4: 2004 | K4: 2005 | L4: 2006 | M4: 2007 | N4: 2008 | O4: 2009 | P4: 2010 | Q4: 2011 | R4: 2012 | S4: 2013 | T4: 2014 | U4: 2015 | V4: 2016 | W4: 2017 | X4: 2018 | Y4: 2019 | Z4: 2020 | AA4: 2021 | AB4: 2022 | AC4: from | AD4: 2022 | AE4: 2050 | AG4: 2022 | AH4: 2050
A5: CEEDC | B5: MWh | C5: Generation | E5: Canada | F5: =SUM(F6:F18) -> 5.3683827e+08 | G5: =SUM(G6:G18) -> 5.166062e+08 | H5: =SUM(H6:H18) -> 5.28239e+08 | I5: =SUM(I6:I18) -> 5.1362287e+08 | J5: =SUM(J6:J18) -> 5.2047769e+08 | K5: =SUM(K6:K18) -> 5.5550989e+08 | L5: =SUM(L6:L18) -> 540849140 | M5: =SUM(M6:M18) -> 563825291 | ... AB5: =SUM(AB6:AB18) -> 580221844 | AC5: to | AD5: 2050 | AE5: 2100 | AG5: 2050 | AH5: 2100
A6: CEEDC | B6: MWh | C6: Generation | E6: British Columbia | F6: 54278445 | G6: 42940556 | H6: 51667095 | I6: 49243038 | J6: 46646899 | K6: 54129025 | L6: 48080365 | M6: 57870332 | N6: 52026613 | O6: 49406356 | P6: 48168392 | Q6: 53745300 | R6: 57987811 | S6: 53108051 | T6: 51589814 | U6: 54842969 | V6: 57297867 | W6: 60128454 | X6: 56209664 | Y6: 51972732 | Z6: 58425486 | AA6: 61957834 | AB6: 61218504 | AD6: 0.01 | AE6: 0.005 | AG6: 0.02 | AH6: 0.01
A7: CEEDC | B7: MWh | C7: Generation | E7: Alberta | F7: 53054608 | G7: 55562516 | H7: 55799950 | I7: 52736224 | J7: 55287239 | K7: 57284484 | L7: 53698678 | M7: 55267130 | N7: 54256699 | O7: 54510128 | P7: 54858263 | Q7: 66262557 | R7: 56816322 | S7: 57449143 | T7: 65011822 | U7: 60137919 | V7: 59779078 | W7: 61509830 | X7: 57660254 | Y7: 57621567 | Z7: 55455218 | AA7: 55411057 | AB7: 53179994 | AD7: 0.01 | AE7: 0.005 | AG7: 0.02 | AH7: 0.01
A8: CEEDC | B8: MWh | C8: Generation | E8: Saskatchewan | F8: 17126819 | G8: 16570760 | H8: 17260767 | I8: 19206192 | J8: 18849906 | K8: 19460443 | L8: 19360727 | M8: 19956191 | N8: 20849508 | O8: 20222753 | P8: 19513731 | Q8: 18891315 | R8: 18840180 | S8: 20372150 | T8: 20077854 | U8: 23138242 | V8: 24303876 | W8: 24950642 | X8: 23661454 | Y8: 23686155 | Z8: 23949108 | AA8: 24371988 | AB8: 23492660 | AD8: 0.01 | AE8: 0.005 | AG8: 0.02 | AH8: 0.01
A9: CEEDC | B9: MWh | C9: Generation | E9: Manitoba | F9: 32424901 | G9: 33373490 | H9: 29349439 | I9: 21077263 | J9: 27617841 | K9: 36939873 | L9: 34370292 | M9: 34317353 | N9: 35423638 | O9: 34108164 | P9: 33696415 | Q9: 35059306 | R9: 33156304 | S9: 36295832 | T9: 35501944 | U9: 35784620 | V9: 37621332 | W9: 36978819 | X9: 31635220 | Y9: 33850453 | Z9: 37158814 | AA9: 29008658 | AB9: 37751456 | AD9: 0.01 | AE9: 0.005 | AG9: 0.02 | AH9: 0.01
A10: CEEDC | B10: MWh | C10: Generation | E10: Ontario | F10: 1.4819272e+08 | G10: 1.4783108e+08 | H10: 1.4889048e+08 | I10: 1.4471833e+08 | J10: 1.5005511e+08 | K10: 153455154 | L10: 154936512 | M10: 154256798 | N10: 159294259 | O10: 141933227 | P10: 1.4444435e+08 | Q10: 1.4607656e+08 | R10: 1.4505346e+08 | S10: 1.5355287e+08 | T10: 1.5844375e+08 | U10: 154779429 | V10: 152888294 | W10: 148750326 | X10: 152120710 | Y10: 151054578 | Z10: 148800204 | AA10: 142546046 | AB10: 145923645 | AD10: 0.01 | AE10: 0.005 | AG10: 0.02 | AH10: 0.01
A11: CEEDC | B11: MWh | C11: Generation | E11: Quebec | F11: 1.5929265e+08 | G11: 1.507175e+08 | H11: 1.5623812e+08 | I11: 1.5678944e+08 | J11: 1.5201054e+08 | K11: 1.6054726e+08 | L11: 159016737 | M11: 172211270 | N11: 172302538 | O11: 176652497 | P11: 167899438 | Q11: 175871284 | R11: 1.7957071e+08 | S11: 1.8772889e+08 | T11: 1.8371934e+08 | U11: 182156355 | V11: 1.8776053e+08 | W11: 1.9253806e+08 | X11: 1.9148971e+08 | Y11: 1.9144694e+08 | Z11: 188408962 | AA11: 194575465 | AB11: 195905713 | AD11: 0.01 | AE11: 0.005 | AG11: 0.02 | AH11: 0.01
A12: CEEDC | B12: MWh | C12: Generation | E12: New Brunswick | F12: 17540499 | G12: 18629149 | H12: 16566466 | I12: 18063541 | J12: 18724425 | K12: 20294552 | L12: 17495374 | M12: 16283968 | N12: 13186324 | O12: 11903500 | P12: 9930605.3 | Q12: 10575546 | R12: 9167353 | S12: 13930804 | T12: 15739403 | U12: 13315082 | V12: 14668928 | W12: 12946831 | X12: 13061757 | Y12: 12953661 | Z12: 11692615 | AA12: 11763464 | AB12: 11926455 | AD12: 0.01 | AE12: 0.005 | AG12: 0.02 | AH12: 0.01
A13: CEEDC | B13: MWh | C13: Generation | E13: Nova Scotia | F13: 11380405 | G13: 9741655.8 | H13: 8313383.6 | I13: 9742238.1 | J13: 9826507.5 | K13: 12208535 | L13: 11213485 | M13: 12337083 | N13: 11972306 | O13: 11454230 | P13: 11717647 | Q13: 11376659 | R13: 10842636 | S13: 10514267 | T13: 10423896 | U13: 10049679 | V13: 9677579 | W13: 9800561 | X13: 10246686 | Y13: 9719560.6 | Z13: 9432134 | AA13: 9214783 | AB13: 8780282 | AD13: 0.01 | AE13: 0.005 | AG13: 0.02 | AH13: 0.01
A14: CEEDC | B14: MWh | C14: Generation | E14: Prince Edward Island | F14: 54078.453 | G14: 54883.373 | H14: 32257.182 | I14: 62477.402 | J14: 35462.92 | K14: 46417 | L14: 43777 | M14: 44732 | N14: 147944.5 | O14: 355044 | P14: 464144.5 | Q14: 492486 | R14: 482132 | S14: 507185 | T14: 619604 | U14: 615932 | V14: 599317 | W14: 609943 | X14: 643082 | Y14: 646986 | Z14: 657297 | AA14: 601691 | AB14: 529072 | AD14: 0.01 | AE14: 0.005 | AG14: 0.02 | AH14: 0.01
A15: CEEDC | B15: MWh | C15: Generation | E15: Newfoundland and Labrador | F15: 42755239 | G15: 40407630 | H15: 43383044 | I15: 41199271 | J15: 40590690 | K15: 40322068 | L15: 41803350 | M15: 40443694 | N15: 42126953 | O15: 37062952 | P15: 40484527 | Q15: 40328986 | R15: 42486532 | S15: 41809855 | T15: 39807071 | U15: 40505226 | V15: 41477571 | W15: 38532420 | X15: 43295767 | Y15: 42301183 | Z15: 39786521 | AA15: 40334432 | AB15: 40430086 | AD15: 0.01 | AE15: 0.005 | AG15: 0.02 | AH15: 0.01
A16: CEEDC | B16: MWh | C16: Generation | E16: Yukon | F16: 296253.05 | G16: 300926.45 | H16: 312432.19 | I16: 320512.16 | J16: 329141.15 | K16: 343749 | L16: 359031 | M16: 354694 | N16: 372615 | O16: 401888 | P16: 405482 | Q16: 425336 | R16: 455004 | S16: 448558 | T16: 433686 | U16: 447879 | V16: 446998 | W16: 484818 | X16: 477850 | Y16: 467487 | Z16: 532078 | AA16: 571511 | AB16: 570065 | AD16: 0.01 | AE16: 0.005 | AG16: 0.02 | AH16: 0.01
A17: CEEDC | B17: MWh | C17: Generation | E17: Northwest Territories | F17: 441653 | G17: 476052 | H17: 425552 | I17: 464346 | J17: 364481 | K17: 336684 | L17: 326103 | M17: 333165 | N17: 333455 | O17: 342542 | P17: 339225 | Q17: 343205 | R17: 335487 | S17: 347178 | T17: 343116 | U17: 324771 | V17: 339484 | W17: 335344 | X17: 342788 | Y17: 348674 | Z17: 346440 | AA17: 337334 | AB17: 321729 | AD17: 0.01 | AE17: 0.005 | AG17: 0.02 | AH17: 0.01
A18: CEEDC | B18: MWh | C18: Generation | E18: Nunavut | F18: 0 | G18: 0 | H18: 0 | I18: 0 | J18: 139445 | K18: 141645 | L18: 144709 | M18: 148881 | N18: 182199 | O18: 161925 | P18: 161925 | Q18: 98308 | R18: 98307 | S18: 98307 | T18: 157598 | U18: 157415 | V18: 188812 | W18: 189829 | X18: 193660 | Y18: 191134 | Z18: 195181 | AA18: 194790 | AB18: 192183 | AD18: 0.01 | AE18: 0.005 | AG18: 0.02 | AH18: 0.01
A19: CEEDC | B19: MWh | C19: Generation | E19: Atlantic | F19: =SUM(F12:F15) -> 71730221 | G19: =SUM(G12:G15) -> 68833318 | H19: =SUM(H12:H15) -> 68295151 | I19: =SUM(I12:I15) -> 69067527 | J19: =SUM(J12:J15) -> 69177085 | K19: =SUM(K12:K15) -> 72871572 | L19: =SUM(L12:L15) -> 70555986 | M19: =SUM(M12:M15) -> 69109477 | ... AB19: =SUM(AB12:AB15) -> 61665895
A20: CEEDC | B20: MWh | C20: Generation | E20: Territories | F20: =SUM(F16:F18) -> 737906.05 | G20: =SUM(G16:G18) -> 776978.44 | H20: =SUM(H16:H18) -> 737984.18 | I20: =SUM(I16:I18) -> 784858.16 | J20: =SUM(J16:J18) -> 833067.15 | K20: =SUM(K16:K18) -> 822078 | L20: =SUM(L16:L18) -> 829843 | M20: =SUM(M16:M18) -> 836740 | ... AB20: =SUM(AB16:AB18) -> 1083977
A22: Note: CEEDC data collected from Statistics Canada tables: 25-10-0015, 25-10-0019, 25-10-0020, 25-10-0084, and Electric Power Generation, Transmission and Distribution Table 6 (selected years)
F26: 2000 | G26: 2001 | H26: 2002 | I26: 2003 | J26: 2004 | K26: 2005 | L26: 2006 | M26: 2007 | N26: 2008 | O26: 2009 | P26: 2010 | Q26: 2011 | R26: 2012 | S26: 2013 | T26: 2014 | U26: 2015 | V26: 2016 | W26: 2017 | X26: 2018 | Y26: 2019 | Z26: 2020 | AA26: 2021 | AB26: 2022 | AC26: 2023 | AD26: 2024 | AE26: 2025 | AF26: 2026 | AG26: 2027 | AH26: 2028 | AI26: 2029 | AJ26: 2030 | AK26: 2031 | AL26: 2032 | AM26: 2033 | AN26: 2034 | AO26: 2035 | AP26: 2036 | AQ26: 2037 | AR26: 2038 | AS26: 2039 | AT26: 2040 | AU26: 2041 | AV26: 2042 | AW26: 2043 | AX26: 2044 | AY26: 2045 | AZ26: 2046 | BA26: 2047 | BB26: 2048 | BC26: 2049 | BD26: 2050 | BE26: 2051 | BF26: 2052 | BG26: 2053 | BH26: 2054 | BI26: 2055 | BJ26: 2056 | BK26: 2057 | BL26: 2058 | BM26: 2059 | BN26: 2060 | BO26: 2061 | BP26: 2062 | BQ26: 2063 | BR26: 2064 | BS26: 2065 | BT26: 2066 | BU26: 2067 | BV26: 2068 | BW26: 2069 | BX26: 2070 | BY26: 2071 | BZ26: 2072 | CA26: 2073 | CB26: 2074 | CC26: 2075 | CD26: 2076 | CE26: 2077 | CF26: 2078 | CG26: 2079 | CH26: 2080 | CI26: 2081 | CJ26: 2082 | CK26: 2083 | CL26: 2084 | CM26: 2085 | CN26: 2086 | CO26: 2087 | CP26: 2088 | CQ26: 2089 | CR26: 2090 | CS26: 2091 | CT26: 2092 | CU26: 2093 | CV26: 2094 | CW26: 2095 | CX26: 2096 | CY26: 2097 | CZ26: 2098 | DA26: 2099 | DB26: 2100
A27: https://www.miningandenergy.ca/read/top-active-coal-mines-in-canada | B27: MWh | C27: Generation | E27: Canada | F27: =SUM(F28:F40) -> 5.3683827e+08 | G27: =SUM(G28:G40) -> 5.166062e+08 | H27: =SUM(H28:H40) -> 5.28239e+08 | I27: =SUM(I28:I40) -> 5.1362287e+08 | J27: =SUM(J28:J40) -> 5.2047769e+08 | K27: =SUM(K28:K40) -> 5.5550989e+08 | L27: =SUM(L28:L40) -> 540849140 | M27: =SUM(M28:M40) -> 563825291 | ... DB27: =SUM(DB28:DB40) -> 9.8377465e+08
A28: https://www.miningandenergy.ca/read/top-active-coal-mines-in-canada | B28: MWh | C28: Generation | E28: British Columbia | F28: =F6 -> 54278445 | G28: =G6 -> 42940556 | H28: =H6 -> 51667095 | I28: =I6 -> 49243038 | J28: =J6 -> 46646899 | K28: =K6 -> 54129025 | L28: =L6 -> 48080365 | M28: =M6 -> 57870332 | ... AB28: =AB6 -> 61218504 | AC28: {=AB28*(1+INDEX($AD6:$AE6,_xlfn.XMATCH(AC$26,$AD$5:$AE$5,1)))} -> 61830689 | AD28: {=AC28*(1+INDEX($AD6:$AE6,_xlfn.XMATCH(AD$26,$AD$5:$AE$5,1)))} -> 62448996 | AE28: {=AD28*(1+INDEX($AD6:$AE6,_xlfn.XMATCH(AE$26,$AD$5:$AE$5,1)))} -> 63073486 | AF28: {=AE28*(1+INDEX($AD6:$AE6,_xlfn.XMATCH(AF$26,$AD$5:$AE$5,1)))} -> 63704221 | AG28: {=AF28*(1+INDEX($AD6:$AE6,_xlfn.XMATCH(AG$26,$AD$5:$AE$5,1)))} -> 64341263 | AH28: {=AG28*(1+INDEX($AD6:$AE6,_xlfn.XMATCH(AH$26,$AD$5:$AE$5,1)))} -> 64984676 | AI28: {=AH28*(1+INDEX($AD6:$AE6,_xlfn.XMATCH(AI$26,$AD$5:$AE$5,1)))} -> 65634522 | AJ28: {=AI28*(1+INDEX($AD6:$AE6,_xlfn.XMATCH(AJ$26,$AD$5:$AE$5,1)))} -> 66290868 | ... DB28: {=DA28*(1+INDEX($AD6:$AE6,_xlfn.XMATCH(DB$26,$AD$5:$AE$5,1)))} -> 1.0379687e+08
B29: MWh | C29: Generation | E29: Alberta | F29: =F7 -> 53054608 | G29: =G7 -> 55562516 | H29: =H7 -> 55799950 | I29: =I7 -> 52736224 | J29: =J7 -> 55287239 | K29: =K7 -> 57284484 | L29: =L7 -> 53698678 | M29: =M7 -> 55267130 | ... AB29: =AB7 -> 53179994 | AC29: {=AB29*(1+INDEX($AD7:$AE7,_xlfn.XMATCH(AC$26,$AD$5:$AE$5,1)))} -> 53711794 | AD29: {=AC29*(1+INDEX($AD7:$AE7,_xlfn.XMATCH(AD$26,$AD$5:$AE$5,1)))} -> 54248912 | AE29: {=AD29*(1+INDEX($AD7:$AE7,_xlfn.XMATCH(AE$26,$AD$5:$AE$5,1)))} -> 54791401 | AF29: {=AE29*(1+INDEX($AD7:$AE7,_xlfn.XMATCH(AF$26,$AD$5:$AE$5,1)))} -> 55339315 | AG29: {=AF29*(1+INDEX($AD7:$AE7,_xlfn.XMATCH(AG$26,$AD$5:$AE$5,1)))} -> 55892708 | AH29: {=AG29*(1+INDEX($AD7:$AE7,_xlfn.XMATCH(AH$26,$AD$5:$AE$5,1)))} -> 56451635 | AI29: {=AH29*(1+INDEX($AD7:$AE7,_xlfn.XMATCH(AI$26,$AD$5:$AE$5,1)))} -> 57016152 | AJ29: {=AI29*(1+INDEX($AD7:$AE7,_xlfn.XMATCH(AJ$26,$AD$5:$AE$5,1)))} -> 57586313 | ... DB29: {=DA29*(1+INDEX($AD7:$AE7,_xlfn.XMATCH(DB$26,$AD$5:$AE$5,1)))} -> 90167460
B30: MWh | C30: Generation | E30: Saskatchewan | F30: =F8 -> 17126819 | G30: =G8 -> 16570760 | H30: =H8 -> 17260767 | I30: =I8 -> 19206192 | J30: =J8 -> 18849906 | K30: =K8 -> 19460443 | L30: =L8 -> 19360727 | M30: =M8 -> 19956191 | ... AB30: =AB8 -> 23492660 | AC30: {=AB30*(1+INDEX($AD8:$AE8,_xlfn.XMATCH(AC$26,$AD$5:$AE$5,1)))} -> 23727587 | AD30: {=AC30*(1+INDEX($AD8:$AE8,_xlfn.XMATCH(AD$26,$AD$5:$AE$5,1)))} -> 23964862 | AE30: {=AD30*(1+INDEX($AD8:$AE8,_xlfn.XMATCH(AE$26,$AD$5:$AE$5,1)))} -> 24204511 | AF30: {=AE30*(1+INDEX($AD8:$AE8,_xlfn.XMATCH(AF$26,$AD$5:$AE$5,1)))} -> 24446556 | AG30: {=AF30*(1+INDEX($AD8:$AE8,_xlfn.XMATCH(AG$26,$AD$5:$AE$5,1)))} -> 24691022 | AH30: {=AG30*(1+INDEX($AD8:$AE8,_xlfn.XMATCH(AH$26,$AD$5:$AE$5,1)))} -> 24937932 | AI30: {=AH30*(1+INDEX($AD8:$AE8,_xlfn.XMATCH(AI$26,$AD$5:$AE$5,1)))} -> 25187311 | AJ30: {=AI30*(1+INDEX($AD8:$AE8,_xlfn.XMATCH(AJ$26,$AD$5:$AE$5,1)))} -> 25439184 | ... DB30: {=DA30*(1+INDEX($AD8:$AE8,_xlfn.XMATCH(DB$26,$AD$5:$AE$5,1)))} -> 39832150
B31: MWh | C31: Generation | E31: Manitoba | F31: =F9 -> 32424901 | G31: =G9 -> 33373490 | H31: =H9 -> 29349439 | I31: =I9 -> 21077263 | J31: =J9 -> 27617841 | K31: =K9 -> 36939873 | L31: =L9 -> 34370292 | M31: =M9 -> 34317353 | ... AB31: =AB9 -> 37751456 | AC31: {=AB31*(1+INDEX($AD9:$AE9,_xlfn.XMATCH(AC$26,$AD$5:$AE$5,1)))} -> 38128971 | AD31: {=AC31*(1+INDEX($AD9:$AE9,_xlfn.XMATCH(AD$26,$AD$5:$AE$5,1)))} -> 38510260 | AE31: {=AD31*(1+INDEX($AD9:$AE9,_xlfn.XMATCH(AE$26,$AD$5:$AE$5,1)))} -> 38895363 | AF31: {=AE31*(1+INDEX($AD9:$AE9,_xlfn.XMATCH(AF$26,$AD$5:$AE$5,1)))} -> 39284316 | AG31: {=AF31*(1+INDEX($AD9:$AE9,_xlfn.XMATCH(AG$26,$AD$5:$AE$5,1)))} -> 39677160 | AH31: {=AG31*(1+INDEX($AD9:$AE9,_xlfn.XMATCH(AH$26,$AD$5:$AE$5,1)))} -> 40073931 | AI31: {=AH31*(1+INDEX($AD9:$AE9,_xlfn.XMATCH(AI$26,$AD$5:$AE$5,1)))} -> 40474671 | AJ31: {=AI31*(1+INDEX($AD9:$AE9,_xlfn.XMATCH(AJ$26,$AD$5:$AE$5,1)))} -> 40879417 | ... DB31: {=DA31*(1+INDEX($AD9:$AE9,_xlfn.XMATCH(DB$26,$AD$5:$AE$5,1)))} -> 64008148
B32: MWh | C32: Generation | E32: Ontario | F32: =F10 -> 1.4819272e+08 | G32: =G10 -> 1.4783108e+08 | H32: =H10 -> 1.4889048e+08 | I32: =I10 -> 1.4471833e+08 | J32: =J10 -> 1.5005511e+08 | K32: =K10 -> 153455154 | L32: =L10 -> 154936512 | M32: =M10 -> 154256798 | ... AB32: =AB10 -> 145923645 | AC32: {=AB32*(1+INDEX($AD10:$AE10,_xlfn.XMATCH(AC$26,$AD$5:$AE$5,1)))} -> 1.4738288e+08 | AD32: {=AC32*(1+INDEX($AD10:$AE10,_xlfn.XMATCH(AD$26,$AD$5:$AE$5,1)))} -> 1.4885671e+08 | AE32: {=AD32*(1+INDEX($AD10:$AE10,_xlfn.XMATCH(AE$26,$AD$5:$AE$5,1)))} -> 1.5034528e+08 | AF32: {=AE32*(1+INDEX($AD10:$AE10,_xlfn.XMATCH(AF$26,$AD$5:$AE$5,1)))} -> 1.5184873e+08 | AG32: {=AF32*(1+INDEX($AD10:$AE10,_xlfn.XMATCH(AG$26,$AD$5:$AE$5,1)))} -> 1.5336722e+08 | AH32: {=AG32*(1+INDEX($AD10:$AE10,_xlfn.XMATCH(AH$26,$AD$5:$AE$5,1)))} -> 1.5490089e+08 | AI32: {=AH32*(1+INDEX($AD10:$AE10,_xlfn.XMATCH(AI$26,$AD$5:$AE$5,1)))} -> 1.564499e+08 | AJ32: {=AI32*(1+INDEX($AD10:$AE10,_xlfn.XMATCH(AJ$26,$AD$5:$AE$5,1)))} -> 1.580144e+08 | ... DB32: {=DA32*(1+INDEX($AD10:$AE10,_xlfn.XMATCH(DB$26,$AD$5:$AE$5,1)))} -> 2.4741568e+08
B33: MWh | C33: Generation | E33: Quebec | F33: =F11 -> 1.5929265e+08 | G33: =G11 -> 1.507175e+08 | H33: =H11 -> 1.5623812e+08 | I33: =I11 -> 1.5678944e+08 | J33: =J11 -> 1.5201054e+08 | K33: =K11 -> 1.6054726e+08 | L33: =L11 -> 159016737 | M33: =M11 -> 172211270 | ... AB33: =AB11 -> 195905713 | AC33: {=AB33*(1+INDEX($AD11:$AE11,_xlfn.XMATCH(AC$26,$AD$5:$AE$5,1)))} -> 1.9786477e+08 | AD33: {=AC33*(1+INDEX($AD11:$AE11,_xlfn.XMATCH(AD$26,$AD$5:$AE$5,1)))} -> 1.9984342e+08 | AE33: {=AD33*(1+INDEX($AD11:$AE11,_xlfn.XMATCH(AE$26,$AD$5:$AE$5,1)))} -> 2.0184185e+08 | AF33: {=AE33*(1+INDEX($AD11:$AE11,_xlfn.XMATCH(AF$26,$AD$5:$AE$5,1)))} -> 2.0386027e+08 | AG33: {=AF33*(1+INDEX($AD11:$AE11,_xlfn.XMATCH(AG$26,$AD$5:$AE$5,1)))} -> 2.0589887e+08 | AH33: {=AG33*(1+INDEX($AD11:$AE11,_xlfn.XMATCH(AH$26,$AD$5:$AE$5,1)))} -> 2.0795786e+08 | AI33: {=AH33*(1+INDEX($AD11:$AE11,_xlfn.XMATCH(AI$26,$AD$5:$AE$5,1)))} -> 2.1003744e+08 | AJ33: {=AI33*(1+INDEX($AD11:$AE11,_xlfn.XMATCH(AJ$26,$AD$5:$AE$5,1)))} -> 2.1213781e+08 | ... DB33: {=DA33*(1+INDEX($AD11:$AE11,_xlfn.XMATCH(DB$26,$AD$5:$AE$5,1)))} -> 3.3216101e+08
B34: MWh | C34: Generation | E34: New Brunswick | F34: =F12 -> 17540499 | G34: =G12 -> 18629149 | H34: =H12 -> 16566466 | I34: =I12 -> 18063541 | J34: =J12 -> 18724425 | K34: =K12 -> 20294552 | L34: =L12 -> 17495374 | M34: =M12 -> 16283968 | ... AB34: =AB12 -> 11926455 | AC34: {=AB34*(1+INDEX($AD12:$AE12,_xlfn.XMATCH(AC$26,$AD$5:$AE$5,1)))} -> 12045720 | AD34: {=AC34*(1+INDEX($AD12:$AE12,_xlfn.XMATCH(AD$26,$AD$5:$AE$5,1)))} -> 12166177 | AE34: {=AD34*(1+INDEX($AD12:$AE12,_xlfn.XMATCH(AE$26,$AD$5:$AE$5,1)))} -> 12287839 | AF34: {=AE34*(1+INDEX($AD12:$AE12,_xlfn.XMATCH(AF$26,$AD$5:$AE$5,1)))} -> 12410717 | AG34: {=AF34*(1+INDEX($AD12:$AE12,_xlfn.XMATCH(AG$26,$AD$5:$AE$5,1)))} -> 12534824 | AH34: {=AG34*(1+INDEX($AD12:$AE12,_xlfn.XMATCH(AH$26,$AD$5:$AE$5,1)))} -> 12660172 | AI34: {=AH34*(1+INDEX($AD12:$AE12,_xlfn.XMATCH(AI$26,$AD$5:$AE$5,1)))} -> 12786774 | AJ34: {=AI34*(1+INDEX($AD12:$AE12,_xlfn.XMATCH(AJ$26,$AD$5:$AE$5,1)))} -> 12914642 | ... DB34: {=DA34*(1+INDEX($AD12:$AE12,_xlfn.XMATCH(DB$26,$AD$5:$AE$5,1)))} -> 20221480
B35: MWh | C35: Generation | E35: Nova Scotia | F35: =F13 -> 11380405 | G35: =G13 -> 9741655.8 | H35: =H13 -> 8313383.6 | I35: =I13 -> 9742238.1 | J35: =J13 -> 9826507.5 | K35: =K13 -> 12208535 | L35: =L13 -> 11213485 | M35: =M13 -> 12337083 | ... AB35: =AB13 -> 8780282 | AC35: {=AB35*(1+INDEX($AD13:$AE13,_xlfn.XMATCH(AC$26,$AD$5:$AE$5,1)))} -> 8868084.8 | AD35: {=AC35*(1+INDEX($AD13:$AE13,_xlfn.XMATCH(AD$26,$AD$5:$AE$5,1)))} -> 8956765.7 | AE35: {=AD35*(1+INDEX($AD13:$AE13,_xlfn.XMATCH(AE$26,$AD$5:$AE$5,1)))} -> 9046333.3 | AF35: {=AE35*(1+INDEX($AD13:$AE13,_xlfn.XMATCH(AF$26,$AD$5:$AE$5,1)))} -> 9136796.7 | AG35: {=AF35*(1+INDEX($AD13:$AE13,_xlfn.XMATCH(AG$26,$AD$5:$AE$5,1)))} -> 9228164.6 | AH35: {=AG35*(1+INDEX($AD13:$AE13,_xlfn.XMATCH(AH$26,$AD$5:$AE$5,1)))} -> 9320446.3 | AI35: {=AH35*(1+INDEX($AD13:$AE13,_xlfn.XMATCH(AI$26,$AD$5:$AE$5,1)))} -> 9413650.7 | AJ35: {=AI35*(1+INDEX($AD13:$AE13,_xlfn.XMATCH(AJ$26,$AD$5:$AE$5,1)))} -> 9507787.2 | ... DB35: {=DA35*(1+INDEX($AD13:$AE13,_xlfn.XMATCH(DB$26,$AD$5:$AE$5,1)))} -> 14887097
B36: MWh | C36: Generation | E36: Prince Edward Island | F36: =F14 -> 54078.453 | G36: =G14 -> 54883.373 | H36: =H14 -> 32257.182 | I36: =I14 -> 62477.402 | J36: =J14 -> 35462.92 | K36: =K14 -> 46417 | L36: =L14 -> 43777 | M36: =M14 -> 44732 | ... AB36: =AB14 -> 529072 | AC36: {=AB36*(1+INDEX($AD14:$AE14,_xlfn.XMATCH(AC$26,$AD$5:$AE$5,1)))} -> 534362.72 | AD36: {=AC36*(1+INDEX($AD14:$AE14,_xlfn.XMATCH(AD$26,$AD$5:$AE$5,1)))} -> 539706.35 | AE36: {=AD36*(1+INDEX($AD14:$AE14,_xlfn.XMATCH(AE$26,$AD$5:$AE$5,1)))} -> 545103.41 | AF36: {=AE36*(1+INDEX($AD14:$AE14,_xlfn.XMATCH(AF$26,$AD$5:$AE$5,1)))} -> 550554.44 | AG36: {=AF36*(1+INDEX($AD14:$AE14,_xlfn.XMATCH(AG$26,$AD$5:$AE$5,1)))} -> 556059.99 | AH36: {=AG36*(1+INDEX($AD14:$AE14,_xlfn.XMATCH(AH$26,$AD$5:$AE$5,1)))} -> 561620.59 | AI36: {=AH36*(1+INDEX($AD14:$AE14,_xlfn.XMATCH(AI$26,$AD$5:$AE$5,1)))} -> 567236.8 | AJ36: {=AI36*(1+INDEX($AD14:$AE14,_xlfn.XMATCH(AJ$26,$AD$5:$AE$5,1)))} -> 572909.16 | ... DB36: {=DA36*(1+INDEX($AD14:$AE14,_xlfn.XMATCH(DB$26,$AD$5:$AE$5,1)))} -> 897049.34
B37: MWh | C37: Generation | E37: Newfoundland and Labrador | F37: =F15 -> 42755239 | G37: =G15 -> 40407630 | H37: =H15 -> 43383044 | I37: =I15 -> 41199271 | J37: =J15 -> 40590690 | K37: =K15 -> 40322068 | L37: =L15 -> 41803350 | M37: =M15 -> 40443694 | ... AB37: =AB15 -> 40430086 | AC37: {=AB37*(1+INDEX($AD15:$AE15,_xlfn.XMATCH(AC$26,$AD$5:$AE$5,1)))} -> 40834387 | AD37: {=AC37*(1+INDEX($AD15:$AE15,_xlfn.XMATCH(AD$26,$AD$5:$AE$5,1)))} -> 41242731 | AE37: {=AD37*(1+INDEX($AD15:$AE15,_xlfn.XMATCH(AE$26,$AD$5:$AE$5,1)))} -> 41655158 | AF37: {=AE37*(1+INDEX($AD15:$AE15,_xlfn.XMATCH(AF$26,$AD$5:$AE$5,1)))} -> 42071710 | AG37: {=AF37*(1+INDEX($AD15:$AE15,_xlfn.XMATCH(AG$26,$AD$5:$AE$5,1)))} -> 42492427 | AH37: {=AG37*(1+INDEX($AD15:$AE15,_xlfn.XMATCH(AH$26,$AD$5:$AE$5,1)))} -> 42917351 | AI37: {=AH37*(1+INDEX($AD15:$AE15,_xlfn.XMATCH(AI$26,$AD$5:$AE$5,1)))} -> 43346524 | AJ37: {=AI37*(1+INDEX($AD15:$AE15,_xlfn.XMATCH(AJ$26,$AD$5:$AE$5,1)))} -> 43779990 | ... DB37: {=DA37*(1+INDEX($AD15:$AE15,_xlfn.XMATCH(DB$26,$AD$5:$AE$5,1)))} -> 68549804
B38: MWh | C38: Generation | E38: Yukon | F38: =F16 -> 296253.05 | G38: =G16 -> 300926.45 | H38: =H16 -> 312432.19 | I38: =I16 -> 320512.16 | J38: =J16 -> 329141.15 | K38: =K16 -> 343749 | L38: =L16 -> 359031 | M38: =M16 -> 354694 | ... AB38: =AB16 -> 570065 | AC38: {=AB38*(1+INDEX($AD16:$AE16,_xlfn.XMATCH(AC$26,$AD$5:$AE$5,1)))} -> 575765.65 | AD38: {=AC38*(1+INDEX($AD16:$AE16,_xlfn.XMATCH(AD$26,$AD$5:$AE$5,1)))} -> 581523.31 | AE38: {=AD38*(1+INDEX($AD16:$AE16,_xlfn.XMATCH(AE$26,$AD$5:$AE$5,1)))} -> 587338.54 | AF38: {=AE38*(1+INDEX($AD16:$AE16,_xlfn.XMATCH(AF$26,$AD$5:$AE$5,1)))} -> 593211.92 | AG38: {=AF38*(1+INDEX($AD16:$AE16,_xlfn.XMATCH(AG$26,$AD$5:$AE$5,1)))} -> 599144.04 | AH38: {=AG38*(1+INDEX($AD16:$AE16,_xlfn.XMATCH(AH$26,$AD$5:$AE$5,1)))} -> 605135.48 | AI38: {=AH38*(1+INDEX($AD16:$AE16,_xlfn.XMATCH(AI$26,$AD$5:$AE$5,1)))} -> 611186.84 | AJ38: {=AI38*(1+INDEX($AD16:$AE16,_xlfn.XMATCH(AJ$26,$AD$5:$AE$5,1)))} -> 617298.71 | ... DB38: {=DA38*(1+INDEX($AD16:$AE16,_xlfn.XMATCH(DB$26,$AD$5:$AE$5,1)))} -> 966553.57
B39: MWh | C39: Generation | E39: Northwest Territories | F39: =F17 -> 441653 | G39: =G17 -> 476052 | H39: =H17 -> 425552 | I39: =I17 -> 464346 | J39: =J17 -> 364481 | K39: =K17 -> 336684 | L39: =L17 -> 326103 | M39: =M17 -> 333165 | ... AB39: =AB17 -> 321729 | AC39: {=AB39*(1+INDEX($AD17:$AE17,_xlfn.XMATCH(AC$26,$AD$5:$AE$5,1)))} -> 324946.29 | AD39: {=AC39*(1+INDEX($AD17:$AE17,_xlfn.XMATCH(AD$26,$AD$5:$AE$5,1)))} -> 328195.75 | AE39: {=AD39*(1+INDEX($AD17:$AE17,_xlfn.XMATCH(AE$26,$AD$5:$AE$5,1)))} -> 331477.71 | AF39: {=AE39*(1+INDEX($AD17:$AE17,_xlfn.XMATCH(AF$26,$AD$5:$AE$5,1)))} -> 334792.49 | AG39: {=AF39*(1+INDEX($AD17:$AE17,_xlfn.XMATCH(AG$26,$AD$5:$AE$5,1)))} -> 338140.41 | AH39: {=AG39*(1+INDEX($AD17:$AE17,_xlfn.XMATCH(AH$26,$AD$5:$AE$5,1)))} -> 341521.82 | AI39: {=AH39*(1+INDEX($AD17:$AE17,_xlfn.XMATCH(AI$26,$AD$5:$AE$5,1)))} -> 344937.03 | AJ39: {=AI39*(1+INDEX($AD17:$AE17,_xlfn.XMATCH(AJ$26,$AD$5:$AE$5,1)))} -> 348386.41 | ... DB39: {=DA39*(1+INDEX($AD17:$AE17,_xlfn.XMATCH(DB$26,$AD$5:$AE$5,1)))} -> 545496.24
B40: MWh | C40: Generation | E40: Nunavut | F40: =F18 -> 0 | G40: =G18 -> 0 | H40: =H18 -> 0 | I40: =I18 -> 0 | J40: =J18 -> 139445 | K40: =K18 -> 141645 | L40: =L18 -> 144709 | M40: =M18 -> 148881 | ... AB40: =AB18 -> 192183 | AC40: {=AB40*(1+INDEX($AD18:$AE18,_xlfn.XMATCH(AC$26,$AD$5:$AE$5,1)))} -> 194104.83 | AD40: {=AC40*(1+INDEX($AD18:$AE18,_xlfn.XMATCH(AD$26,$AD$5:$AE$5,1)))} -> 196045.88 | AE40: {=AD40*(1+INDEX($AD18:$AE18,_xlfn.XMATCH(AE$26,$AD$5:$AE$5,1)))} -> 198006.34 | AF40: {=AE40*(1+INDEX($AD18:$AE18,_xlfn.XMATCH(AF$26,$AD$5:$AE$5,1)))} -> 199986.4 | AG40: {=AF40*(1+INDEX($AD18:$AE18,_xlfn.XMATCH(AG$26,$AD$5:$AE$5,1)))} -> 201986.26 | AH40: {=AG40*(1+INDEX($AD18:$AE18,_xlfn.XMATCH(AH$26,$AD$5:$AE$5,1)))} -> 204006.13 | AI40: {=AH40*(1+INDEX($AD18:$AE18,_xlfn.XMATCH(AI$26,$AD$5:$AE$5,1)))} -> 206046.19 | AJ40: {=AI40*(1+INDEX($AD18:$AE18,_xlfn.XMATCH(AJ$26,$AD$5:$AE$5,1)))} -> 208106.65 | ... DB40: {=DA40*(1+INDEX($AD18:$AE18,_xlfn.XMATCH(DB$26,$AD$5:$AE$5,1)))} -> 325849.1
B41: MWh | C41: Generation | E41: Atlantic | F41: =SUM(F34:F37) -> 71730221 | G41: =SUM(G34:G37) -> 68833318 | H41: =SUM(H34:H37) -> 68295151 | I41: =SUM(I34:I37) -> 69067527 | J41: =SUM(J34:J37) -> 69177085 | K41: =SUM(K34:K37) -> 72871572 | L41: =SUM(L34:L37) -> 70555986 | M41: =SUM(M34:M37) -> 69109477 | ... DB41: =SUM(DB34:DB37) -> 1.0455543e+08
B42: MWh | C42: Generation | E42: Territories | F42: =SUM(F38:F40) -> 737906.05 | G42: =SUM(G38:G40) -> 776978.44 | H42: =SUM(H38:H40) -> 737984.18 | I42: =SUM(I38:I40) -> 784858.16 | J42: =SUM(J38:J40) -> 833067.15 | K42: =SUM(K38:K40) -> 822078 | L42: =SUM(L38:L40) -> 829843 | M42: =SUM(M38:M40) -> 836740 | ... DB42: =SUM(DB38:DB40) -> 1837898.9
F46: 2000 | G46: 2001 | H46: 2002 | I46: 2003 | J46: 2004 | K46: 2005 | L46: 2006 | M46: 2007 | N46: 2008 | O46: 2009 | P46: 2010 | Q46: 2011 | R46: 2012 | S46: 2013 | T46: 2014 | U46: 2015 | V46: 2016 | W46: 2017 | X46: 2018 | Y46: 2019 | Z46: 2020 | AA46: 2021 | AB46: 2022 | AC46: 2023 | AD46: 2024 | AE46: 2025 | AF46: 2026 | AG46: 2027 | AH46: 2028 | AI46: 2029 | AJ46: 2030 | AK46: 2031 | AL46: 2032 | AM46: 2033 | AN46: 2034 | AO46: 2035 | AP46: 2036 | AQ46: 2037 | AR46: 2038 | AS46: 2039 | AT46: 2040 | AU46: 2041 | AV46: 2042 | AW46: 2043 | AX46: 2044 | AY46: 2045 | AZ46: 2046 | BA46: 2047 | BB46: 2048 | BC46: 2049 | BD46: 2050 | BE46: 2051 | BF46: 2052 | BG46: 2053 | BH46: 2054 | BI46: 2055 | BJ46: 2056 | BK46: 2057 | BL46: 2058 | BM46: 2059 | BN46: 2060 | BO46: 2061 | BP46: 2062 | BQ46: 2063 | BR46: 2064 | BS46: 2065 | BT46: 2066 | BU46: 2067 | BV46: 2068 | BW46: 2069 | BX46: 2070 | BY46: 2071 | BZ46: 2072 | CA46: 2073 | CB46: 2074 | CC46: 2075 | CD46: 2076 | CE46: 2077 | CF46: 2078 | CG46: 2079 | CH46: 2080 | CI46: 2081 | CJ46: 2082 | CK46: 2083 | CL46: 2084 | CM46: 2085 | CN46: 2086 | CO46: 2087 | CP46: 2088 | CQ46: 2089 | CR46: 2090 | CS46: 2091 | CT46: 2092 | CU46: 2093 | CV46: 2094 | CW46: 2095 | CX46: 2096 | CY46: 2097 | CZ46: 2098 | DA46: 2099 | DB46: 2100
A47: https://www.miningandenergy.ca/read/top-active-coal-mines-in-canada | B47: MWh | C47: Generation | E47: Canada | F47: =SUM(F48:F60) -> 5.3683827e+08 | G47: =SUM(G48:G60) -> 5.166062e+08 | H47: =SUM(H48:H60) -> 5.28239e+08 | I47: =SUM(I48:I60) -> 5.1362287e+08 | J47: =SUM(J48:J60) -> 5.2047769e+08 | K47: =SUM(K48:K60) -> 5.5550989e+08 | L47: =SUM(L48:L60) -> 540849140 | M47: =SUM(M48:M60) -> 563825291 | ... DB47: =SUM(DB48:DB60) -> 1.6613746e+09
...
