Workbook
Name CH4_GJ: #REF!
Name CO2_GJ: #REF!
Name CoeffIndex: #REF!
Name CoeffYear: #REF!
Name Competition: #REF!:INDEX(#REF!,COUNTA(#REF!))
Name Deflator_JCIMS: #REF!
Name Fuel: #REF!:INDEX(#REF!,COUNTA(#REF!))
Name Fuel_JCIMS: #REF!:INDEX(#REF!,COUNTA(#REF!))
Name FuelCheck_JCIMS: #REF!
Name FuelMult_JCIMS: #REF!
Name FuelMult_JCIMS_Index: #REF!
Name FuelMultiplier_JCIMS: #REF!
Name FuelMultiplier_JCIMS_Index: #REF!
Name FuelPrices_CER: #REF!
Name FuelPrices_CER_Index: #REF!
Name FuelPrices_JCIMS: #REF!
Name FuelPrices_JCIMS_Index: #REF!
Name FuelPrices_pyCIMS: #REF!
Name FuelPrices_pyCIMS_Index: #REF!
Name gal_per_bbl: #REF!
Name GHG: #REF!:INDEX(#REF!,COUNTA(#REF!))
Name GHG_JCIMS: #REF!:INDEX(#REF!,COUNTA(#REF!))
Name GJ_per_MMBtu: #REF!
Name GJ_per_MWh: #REF!
Name l_per_gal: #REF!
Name N2O_GJ: #REF!
Name Node: #REF!:INDEX(#REF!,COUNTA(#REF!))
Name Region: #REF!:INDEX(#REF!,COUNTA(#REF!))
Name Scraped_codemap: #REF!
Name Scraped_data: #REF!
Name Scraped_first: #REF!
Name Scraped_index: #REF!
Name Scraped_last: #REF!
Name Scraped_NOx: #REF!
Name Scraped_PM10: #REF!
Name Scraped_SOx: #REF!
Name Sector: #REF!:INDEX(#REF!,COUNTA(#REF!))
Name Sector_JCIMS: #REF!:INDEX(#REF!,COUNTA(#REF!))
Name Tree_JCIMS: #REF!
Name Tree_pyCIMS: #REF!
Name Year: #REF!

Sheet Price Multiplier
B1: Category | C1: Region | D1: Sector | E1: Fuel | F1: Unit | I1: Source | J1: 2000 | K1: 2005 | L1: 2010 | M1: 2015 | N1: 2020 | O1: 2025 | P1: 2030 | Q1: 2035 | R1: 2040 | S1: 2045 | T1: 2050 | V1: Links in this workbook do NOT auto update!!!
F2: Year | G2: Currency | H2: Commodity
B3: pyCIMS
C4: Alberta | D4: Agriculture | E4: Biodiesel | F4: 2005 | G4: CAD | H4: GJ | I4: JCIMS | J4: =IF(JCIMS!J4>=0,JCIMS!J4/INDEX(CIMS!J$4:J$41,MATCH($C4&$E4,CIMS!$W$4:$W$41,0)),1) -> 1.1868954 | K4: =IF(JCIMS!K4>=0,JCIMS!K4/INDEX(CIMS!K$4:K$41,MATCH($C4&$E4,CIMS!$W$4:$W$41,0)),1) -> 1.4689607 | L4: =IF(JCIMS!L4>=0,JCIMS!L4/INDEX(CIMS!L$4:L$41,MATCH($C4&$E4,CIMS!$W$4:$W$41,0)),1) -> 1.880258 | M4: =IF(JCIMS!M4>=0,JCIMS!M4/INDEX(CIMS!M$4:M$41,MATCH($C4&$E4,CIMS!$W$4:$W$41,0)),1) -> 2.0992134 | N4: =IF(JCIMS!N4>=0,JCIMS!N4/INDEX(CIMS!N$4:N$41,MATCH($C4&$E4,CIMS!$W$4:$W$41,0)),1) -> 2.2031115 | O4: =IF(JCIMS!O4>=0,JCIMS!O4/INDEX(CIMS!O$4:O$41,MATCH($C4&$E4,CIMS!$W$4:$W$41,0)),1) -> 2.9053912 | P4: =IF(JCIMS!P4>=0,JCIMS!P4/INDEX(CIMS!P$4:P$41,MATCH($C4&$E4,CIMS!$W$4:$W$41,0)),1) -> 2.7829301 | Q4: =IF(JCIMS!Q4>=0,JCIMS!Q4/INDEX(CIMS!Q$4:Q$41,MATCH($C4&$E4,CIMS!$W$4:$W$41,0)),1) -> 2.6695271 | ... T4: =IF(JCIMS!T4>=0,JCIMS!T4/INDEX(CIMS!T$4:T$41,MATCH($C4&$E4,CIMS!$W$4:$W$41,0)),1) -> 2.5612593 | V4: =C4&D4&E4 -> AlbertaAgricultureBiodiesel
C5: Alberta | D5: Agriculture | E5: Electricity | F5: 2005 | G5: CAD | H5: GJ | I5: JCIMS | J5: =IF(JCIMS!J5>=0,JCIMS!J5/INDEX(CIMS!J$4:J$41,MATCH($C5&$E5,CIMS!$W$4:$W$41,0)),1) -> 1.4051183 | K5: =IF(JCIMS!K5>=0,JCIMS!K5/INDEX(CIMS!K$4:K$41,MATCH($C5&$E5,CIMS!$W$4:$W$41,0)),1) -> 1.5973077 | L5: =IF(JCIMS!L5>=0,JCIMS!L5/INDEX(CIMS!L$4:L$41,MATCH($C5&$E5,CIMS!$W$4:$W$41,0)),1) -> 1.0587142 | M5: =IF(JCIMS!M5>=0,JCIMS!M5/INDEX(CIMS!M$4:M$41,MATCH($C5&$E5,CIMS!$W$4:$W$41,0)),1) -> 1.6976859 | N5: =IF(JCIMS!N5>=0,JCIMS!N5/INDEX(CIMS!N$4:N$41,MATCH($C5&$E5,CIMS!$W$4:$W$41,0)),1) -> 1.5115374 | O5: =IF(JCIMS!O5>=0,JCIMS!O5/INDEX(CIMS!O$4:O$41,MATCH($C5&$E5,CIMS!$W$4:$W$41,0)),1) -> 1.5905143 | P5: =IF(JCIMS!P5>=0,JCIMS!P5/INDEX(CIMS!P$4:P$41,MATCH($C5&$E5,CIMS!$W$4:$W$41,0)),1) -> 1.7373186 | Q5: =IF(JCIMS!Q5>=0,JCIMS!Q5/INDEX(CIMS!Q$4:Q$41,MATCH($C5&$E5,CIMS!$W$4:$W$41,0)),1) -> 1.5983 | ... T5: =IF(JCIMS!T5>=0,JCIMS!T5/INDEX(CIMS!T$4:T$41,MATCH($C5&$E5,CIMS!$W$4:$W$41,0)),1) -> 1.2628374 | V5: =C5&D5&E5 -> AlbertaAgricultureElectricity
C6: Alberta | D6: Agriculture | E6: Ethanol | F6: 2005 | G6: CAD | H6: GJ | I6: JCIMS | J6: =IF(JCIMS!J6>=0,JCIMS!J6/INDEX(CIMS!J$4:J$41,MATCH($C6&$E6,CIMS!$W$4:$W$41,0)),1) -> 1 | K6: =IF(JCIMS!K6>=0,JCIMS!K6/INDEX(CIMS!K$4:K$41,MATCH($C6&$E6,CIMS!$W$4:$W$41,0)),1) -> 1 | L6: =IF(JCIMS!L6>=0,JCIMS!L6/INDEX(CIMS!L$4:L$41,MATCH($C6&$E6,CIMS!$W$4:$W$41,0)),1) -> 1 | M6: =IF(JCIMS!M6>=0,JCIMS!M6/INDEX(CIMS!M$4:M$41,MATCH($C6&$E6,CIMS!$W$4:$W$41,0)),1) -> 1 | N6: =IF(JCIMS!N6>=0,JCIMS!N6/INDEX(CIMS!N$4:N$41,MATCH($C6&$E6,CIMS!$W$4:$W$41,0)),1) -> 1 | O6: =IF(JCIMS!O6>=0,JCIMS!O6/INDEX(CIMS!O$4:O$41,MATCH($C6&$E6,CIMS!$W$4:$W$41,0)),1) -> 1 | P6: =IF(JCIMS!P6>=0,JCIMS!P6/INDEX(CIMS!P$4:P$41,MATCH($C6&$E6,CIMS!$W$4:$W$41,0)),1) -> 1 | Q6: =IF(JCIMS!Q6>=0,JCIMS!Q6/INDEX(CIMS!Q$4:Q$41,MATCH($C6&$E6,CIMS!$W$4:$W$41,0)),1) -> 1 | ... T6: =IF(JCIMS!T6>=0,JCIMS!T6/INDEX(CIMS!T$4:T$41,MATCH($C6&$E6,CIMS!$W$4:$W$41,0)),1) -> 1 | V6: =C6&D6&E6 -> AlbertaAgricultureEthanol | AA6: P&P solid biomass
C7: Alberta | D7: Agriculture | E7: Jet Fuel | F7: 2005 | G7: CAD | H7: GJ | I7: JCIMS | J7: =IF(JCIMS!J7>=0,JCIMS!J7/INDEX(CIMS!J$4:J$41,MATCH("Generic Fuels"&$E7,CIMS!$W$4:$W$41,0)),1) -> 1 | K7: =IF(JCIMS!K7>=0,JCIMS!K7/INDEX(CIMS!K$4:K$41,MATCH("Generic Fuels"&$E7,CIMS!$W$4:$W$41,0)),1) -> 1 | L7: =IF(JCIMS!L7>=0,JCIMS!L7/INDEX(CIMS!L$4:L$41,MATCH("Generic Fuels"&$E7,CIMS!$W$4:$W$41,0)),1) -> 1 | M7: =IF(JCIMS!M7>=0,JCIMS!M7/INDEX(CIMS!M$4:M$41,MATCH("Generic Fuels"&$E7,CIMS!$W$4:$W$41,0)),1) -> 1 | N7: =IF(JCIMS!N7>=0,JCIMS!N7/INDEX(CIMS!N$4:N$41,MATCH("Generic Fuels"&$E7,CIMS!$W$4:$W$41,0)),1) -> 1 | O7: =IF(JCIMS!O7>=0,JCIMS!O7/INDEX(CIMS!O$4:O$41,MATCH("Generic Fuels"&$E7,CIMS!$W$4:$W$41,0)),1) -> 1 | P7: =IF(JCIMS!P7>=0,JCIMS!P7/INDEX(CIMS!P$4:P$41,MATCH("Generic Fuels"&$E7,CIMS!$W$4:$W$41,0)),1) -> 1 | Q7: =IF(JCIMS!Q7>=0,JCIMS!Q7/INDEX(CIMS!Q$4:Q$41,MATCH("Generic Fuels"&$E7,CIMS!$W$4:$W$41,0)),1) -> 1 | ... T7: =IF(JCIMS!T7>=0,JCIMS!T7/INDEX(CIMS!T$4:T$41,MATCH("Generic Fuels"&$E7,CIMS!$W$4:$W$41,0)),1) -> 1 | V7: =C7&D7&E7 -> AlbertaAgricultureJet Fuel
C8: Alberta | D8: Agriculture | E8: Black Liquor | F8: 2005 | G8: CAD | H8: GJ | I8: JCIMS | J8: =IF(JCIMS!J8>=0,JCIMS!J8/INDEX(CIMS!J$4:J$41,MATCH("Generic Fuels"&$E8,CIMS!$W$4:$W$41,0)),1) -> 1 | K8: =IF(JCIMS!K8>=0,JCIMS!K8/INDEX(CIMS!K$4:K$41,MATCH("Generic Fuels"&$E8,CIMS!$W$4:$W$41,0)),1) -> 1 | L8: =IF(JCIMS!L8>=0,JCIMS!L8/INDEX(CIMS!L$4:L$41,MATCH("Generic Fuels"&$E8,CIMS!$W$4:$W$41,0)),1) -> 1 | M8: =IF(JCIMS!M8>=0,JCIMS!M8/INDEX(CIMS!M$4:M$41,MATCH("Generic Fuels"&$E8,CIMS!$W$4:$W$41,0)),1) -> 1 | N8: =IF(JCIMS!N8>=0,JCIMS!N8/INDEX(CIMS!N$4:N$41,MATCH("Generic Fuels"&$E8,CIMS!$W$4:$W$41,0)),1) -> 1 | O8: =IF(JCIMS!O8>=0,JCIMS!O8/INDEX(CIMS!O$4:O$41,MATCH("Generic Fuels"&$E8,CIMS!$W$4:$W$41,0)),1) -> 1 | P8: =IF(JCIMS!P8>=0,JCIMS!P8/INDEX(CIMS!P$4:P$41,MATCH("Generic Fuels"&$E8,CIMS!$W$4:$W$41,0)),1) -> 1 | Q8: =IF(JCIMS!Q8>=0,JCIMS!Q8/INDEX(CIMS!Q$4:Q$41,MATCH("Generic Fuels"&$E8,CIMS!$W$4:$W$41,0)),1) -> 1 | ... T8: =IF(JCIMS!T8>=0,JCIMS!T8/INDEX(CIMS!T$4:T$41,MATCH("Generic Fuels"&$E8,CIMS!$W$4:$W$41,0)),1) -> 1 | V8: =C8&D8&E8 -> AlbertaAgricultureBlack Liquor
C9: Alberta | D9: Agriculture | E9: Coal | F9: 2005 | G9: CAD | H9: GJ | I9: JCIMS | J9: =IF(JCIMS!J9>=0,JCIMS!J9/INDEX(CIMS!J$4:J$41,MATCH("Generic Fuels"&$E9,CIMS!$W$4:$W$41,0)),1) -> 1 | K9: =IF(JCIMS!K9>=0,JCIMS!K9/INDEX(CIMS!K$4:K$41,MATCH("Generic Fuels"&$E9,CIMS!$W$4:$W$41,0)),1) -> 1 | L9: =IF(JCIMS!L9>=0,JCIMS!L9/INDEX(CIMS!L$4:L$41,MATCH("Generic Fuels"&$E9,CIMS!$W$4:$W$41,0)),1) -> 1 | M9: =IF(JCIMS!M9>=0,JCIMS!M9/INDEX(CIMS!M$4:M$41,MATCH("Generic Fuels"&$E9,CIMS!$W$4:$W$41,0)),1) -> 1 | N9: =IF(JCIMS!N9>=0,JCIMS!N9/INDEX(CIMS!N$4:N$41,MATCH("Generic Fuels"&$E9,CIMS!$W$4:$W$41,0)),1) -> 1 | O9: =IF(JCIMS!O9>=0,JCIMS!O9/INDEX(CIMS!O$4:O$41,MATCH("Generic Fuels"&$E9,CIMS!$W$4:$W$41,0)),1) -> 1 | P9: =IF(JCIMS!P9>=0,JCIMS!P9/INDEX(CIMS!P$4:P$41,MATCH("Generic Fuels"&$E9,CIMS!$W$4:$W$41,0)),1) -> 1 | Q9: =IF(JCIMS!Q9>=0,JCIMS!Q9/INDEX(CIMS!Q$4:Q$41,MATCH("Generic Fuels"&$E9,CIMS!$W$4:$W$41,0)),1) -> 1 | ... T9: =IF(JCIMS!T9>=0,JCIMS!T9/INDEX(CIMS!T$4:T$41,MATCH("Generic Fuels"&$E9,CIMS!$W$4:$W$41,0)),1) -> 1 | V9: =C9&D9&E9 -> AlbertaAgricultureCoal
C10: Alberta | D10: Agriculture | E10: Coke | F10: 2005 | G10: CAD | H10: GJ | I10: JCIMS | J10: =IF(JCIMS!J10>=0,JCIMS!J10/INDEX(CIMS!J$4:J$41,MATCH("Generic Fuels"&$E10,CIMS!$W$4:$W$41,0)),1) -> 1 | K10: =IF(JCIMS!K10>=0,JCIMS!K10/INDEX(CIMS!K$4:K$41,MATCH("Generic Fuels"&$E10,CIMS!$W$4:$W$41,0)),1) -> 1 | L10: =IF(JCIMS!L10>=0,JCIMS!L10/INDEX(CIMS!L$4:L$41,MATCH("Generic Fuels"&$E10,CIMS!$W$4:$W$41,0)),1) -> 1 | M10: =IF(JCIMS!M10>=0,JCIMS!M10/INDEX(CIMS!M$4:M$41,MATCH("Generic Fuels"&$E10,CIMS!$W$4:$W$41,0)),1) -> 1 | N10: =IF(JCIMS!N10>=0,JCIMS!N10/INDEX(CIMS!N$4:N$41,MATCH("Generic Fuels"&$E10,CIMS!$W$4:$W$41,0)),1) -> 1 | O10: =IF(JCIMS!O10>=0,JCIMS!O10/INDEX(CIMS!O$4:O$41,MATCH("Generic Fuels"&$E10,CIMS!$W$4:$W$41,0)),1) -> 1 | P10: =IF(JCIMS!P10>=0,JCIMS!P10/INDEX(CIMS!P$4:P$41,MATCH("Generic Fuels"&$E10,CIMS!$W$4:$W$41,0)),1) -> 1 | Q10: =IF(JCIMS!Q10>=0,JCIMS!Q10/INDEX(CIMS!Q$4:Q$41,MATCH("Generic Fuels"&$E10,CIMS!$W$4:$W$41,0)),1) -> 1 | ... T10: =IF(JCIMS!T10>=0,JCIMS!T10/INDEX(CIMS!T$4:T$41,MATCH("Generic Fuels"&$E10,CIMS!$W$4:$W$41,0)),1) -> 1 | V10: =C10&D10&E10 -> AlbertaAgricultureCoke
C11: Alberta | D11: Agriculture | E11: Diesel | F11: 2005 | G11: CAD | H11: GJ | I11: JCIMS | J11: =IF(JCIMS!J11>=0,JCIMS!J11/INDEX(CIMS!J$4:J$41,MATCH("Generic Fuels"&$E11,CIMS!$W$4:$W$41,0)),1) -> 0.51353593 | K11: =IF(JCIMS!K11>=0,JCIMS!K11/INDEX(CIMS!K$4:K$41,MATCH("Generic Fuels"&$E11,CIMS!$W$4:$W$41,0)),1) -> 0.63580249 | L11: =IF(JCIMS!L11>=0,JCIMS!L11/INDEX(CIMS!L$4:L$41,MATCH("Generic Fuels"&$E11,CIMS!$W$4:$W$41,0)),1) -> 0.94383249 | M11: =IF(JCIMS!M11>=0,JCIMS!M11/INDEX(CIMS!M$4:M$41,MATCH("Generic Fuels"&$E11,CIMS!$W$4:$W$41,0)),1) -> 0.97297638 | N11: =IF(JCIMS!N11>=0,JCIMS!N11/INDEX(CIMS!N$4:N$41,MATCH("Generic Fuels"&$E11,CIMS!$W$4:$W$41,0)),1) -> 1.1398654 | O11: =IF(JCIMS!O11>=0,JCIMS!O11/INDEX(CIMS!O$4:O$41,MATCH("Generic Fuels"&$E11,CIMS!$W$4:$W$41,0)),1) -> 1.264586 | P11: =IF(JCIMS!P11>=0,JCIMS!P11/INDEX(CIMS!P$4:P$41,MATCH("Generic Fuels"&$E11,CIMS!$W$4:$W$41,0)),1) -> 1.3730757 | Q11: =IF(JCIMS!Q11>=0,JCIMS!Q11/INDEX(CIMS!Q$4:Q$41,MATCH("Generic Fuels"&$E11,CIMS!$W$4:$W$41,0)),1) -> 1.4634137 | ... T11: =IF(JCIMS!T11>=0,JCIMS!T11/INDEX(CIMS!T$4:T$41,MATCH("Generic Fuels"&$E11,CIMS!$W$4:$W$41,0)),1) -> 1.555465 | V11: =C11&D11&E11 -> AlbertaAgricultureDiesel
C12: Alberta | D12: Agriculture | E12: Gasoline | F12: 2005 | G12: CAD | H12: GJ | I12: JCIMS | J12: =IF(JCIMS!J12>=0,JCIMS!J12/INDEX(CIMS!J$4:J$41,MATCH("Generic Fuels"&$E12,CIMS!$W$4:$W$41,0)),1) -> 1 | K12: =IF(JCIMS!K12>=0,JCIMS!K12/INDEX(CIMS!K$4:K$41,MATCH("Generic Fuels"&$E12,CIMS!$W$4:$W$41,0)),1) -> 1 | L12: =IF(JCIMS!L12>=0,JCIMS!L12/INDEX(CIMS!L$4:L$41,MATCH("Generic Fuels"&$E12,CIMS!$W$4:$W$41,0)),1) -> 1 | M12: =IF(JCIMS!M12>=0,JCIMS!M12/INDEX(CIMS!M$4:M$41,MATCH("Generic Fuels"&$E12,CIMS!$W$4:$W$41,0)),1) -> 1 | N12: =IF(JCIMS!N12>=0,JCIMS!N12/INDEX(CIMS!N$4:N$41,MATCH("Generic Fuels"&$E12,CIMS!$W$4:$W$41,0)),1) -> 1 | O12: =IF(JCIMS!O12>=0,JCIMS!O12/INDEX(CIMS!O$4:O$41,MATCH("Generic Fuels"&$E12,CIMS!$W$4:$W$41,0)),1) -> 1 | P12: =IF(JCIMS!P12>=0,JCIMS!P12/INDEX(CIMS!P$4:P$41,MATCH("Generic Fuels"&$E12,CIMS!$W$4:$W$41,0)),1) -> 1 | Q12: =IF(JCIMS!Q12>=0,JCIMS!Q12/INDEX(CIMS!Q$4:Q$41,MATCH("Generic Fuels"&$E12,CIMS!$W$4:$W$41,0)),1) -> 1 | ... T12: =IF(JCIMS!T12>=0,JCIMS!T12/INDEX(CIMS!T$4:T$41,MATCH("Generic Fuels"&$E12,CIMS!$W$4:$W$41,0)),1) -> 1 | V12: =C12&D12&E12 -> AlbertaAgricultureGasoline
C13: Alberta | D13: Agriculture | E13: Fuel Oil | F13: 2005 | G13: CAD | H13: GJ | I13: JCIMS | J13: =IF(JCIMS!J13>=0,JCIMS!J13/INDEX(CIMS!J$4:J$41,MATCH("Generic Fuels"&$E13,CIMS!$W$4:$W$41,0)),1) -> 1 | K13: =IF(JCIMS!K13>=0,JCIMS!K13/INDEX(CIMS!K$4:K$41,MATCH("Generic Fuels"&$E13,CIMS!$W$4:$W$41,0)),1) -> 1 | L13: =IF(JCIMS!L13>=0,JCIMS!L13/INDEX(CIMS!L$4:L$41,MATCH("Generic Fuels"&$E13,CIMS!$W$4:$W$41,0)),1) -> 1 | M13: =IF(JCIMS!M13>=0,JCIMS!M13/INDEX(CIMS!M$4:M$41,MATCH("Generic Fuels"&$E13,CIMS!$W$4:$W$41,0)),1) -> 1 | N13: =IF(JCIMS!N13>=0,JCIMS!N13/INDEX(CIMS!N$4:N$41,MATCH("Generic Fuels"&$E13,CIMS!$W$4:$W$41,0)),1) -> 1 | O13: =IF(JCIMS!O13>=0,JCIMS!O13/INDEX(CIMS!O$4:O$41,MATCH("Generic Fuels"&$E13,CIMS!$W$4:$W$41,0)),1) -> 1 | P13: =IF(JCIMS!P13>=0,JCIMS!P13/INDEX(CIMS!P$4:P$41,MATCH("Generic Fuels"&$E13,CIMS!$W$4:$W$41,0)),1) -> 1 | Q13: =IF(JCIMS!Q13>=0,JCIMS!Q13/INDEX(CIMS!Q$4:Q$41,MATCH("Generic Fuels"&$E13,CIMS!$W$4:$W$41,0)),1) -> 1 | ... T13: =IF(JCIMS!T13>=0,JCIMS!T13/INDEX(CIMS!T$4:T$41,MATCH("Generic Fuels"&$E13,CIMS!$W$4:$W$41,0)),1) -> 1 | V13: =C13&D13&E13 -> AlbertaAgricultureFuel Oil
C14: Alberta | D14: Agriculture | E14: Hydrogen | F14: 2005 | G14: CAD | H14: GJ | I14: JCIMS | J14: =IF(JCIMS!J14>=0,JCIMS!J14/INDEX(CIMS!J$4:J$41,MATCH("Generic Fuels"&$E14,CIMS!$W$4:$W$41,0)),1) -> 1 | K14: =IF(JCIMS!K14>=0,JCIMS!K14/INDEX(CIMS!K$4:K$41,MATCH("Generic Fuels"&$E14,CIMS!$W$4:$W$41,0)),1) -> 1 | L14: =IF(JCIMS!L14>=0,JCIMS!L14/INDEX(CIMS!L$4:L$41,MATCH("Generic Fuels"&$E14,CIMS!$W$4:$W$41,0)),1) -> 1 | M14: =IF(JCIMS!M14>=0,JCIMS!M14/INDEX(CIMS!M$4:M$41,MATCH("Generic Fuels"&$E14,CIMS!$W$4:$W$41,0)),1) -> 1 | N14: =IF(JCIMS!N14>=0,JCIMS!N14/INDEX(CIMS!N$4:N$41,MATCH("Generic Fuels"&$E14,CIMS!$W$4:$W$41,0)),1) -> 1 | O14: =IF(JCIMS!O14>=0,JCIMS!O14/INDEX(CIMS!O$4:O$41,MATCH("Generic Fuels"&$E14,CIMS!$W$4:$W$41,0)),1) -> 1 | P14: =IF(JCIMS!P14>=0,JCIMS!P14/INDEX(CIMS!P$4:P$41,MATCH("Generic Fuels"&$E14,CIMS!$W$4:$W$41,0)),1) -> 1 | Q14: =IF(JCIMS!Q14>=0,JCIMS!Q14/INDEX(CIMS!Q$4:Q$41,MATCH("Generic Fuels"&$E14,CIMS!$W$4:$W$41,0)),1) -> 1 | ... T14: =IF(JCIMS!T14>=0,JCIMS!T14/INDEX(CIMS!T$4:T$41,MATCH("Generic Fuels"&$E14,CIMS!$W$4:$W$41,0)),1) -> 1 | V14: =C14&D14&E14 -> AlbertaAgricultureHydrogen
C15: Alberta | D15: Agriculture | E15: Biogas | F15: 2005 | G15: CAD | H15: GJ | I15: JCIMS | J15: =IF(JCIMS!J15>=0,JCIMS!J15/INDEX(CIMS!J$4:J$41,MATCH("Generic Fuels"&$E15,CIMS!$W$4:$W$41,0)),1) -> 1 | K15: =IF(JCIMS!K15>=0,JCIMS!K15/INDEX(CIMS!K$4:K$41,MATCH("Generic Fuels"&$E15,CIMS!$W$4:$W$41,0)),1) -> 1 | L15: =IF(JCIMS!L15>=0,JCIMS!L15/INDEX(CIMS!L$4:L$41,MATCH("Generic Fuels"&$E15,CIMS!$W$4:$W$41,0)),1) -> 1 | M15: =IF(JCIMS!M15>=0,JCIMS!M15/INDEX(CIMS!M$4:M$41,MATCH("Generic Fuels"&$E15,CIMS!$W$4:$W$41,0)),1) -> 1 | N15: =IF(JCIMS!N15>=0,JCIMS!N15/INDEX(CIMS!N$4:N$41,MATCH("Generic Fuels"&$E15,CIMS!$W$4:$W$41,0)),1) -> 1 | O15: =IF(JCIMS!O15>=0,JCIMS!O15/INDEX(CIMS!O$4:O$41,MATCH("Generic Fuels"&$E15,CIMS!$W$4:$W$41,0)),1) -> 1 | P15: =IF(JCIMS!P15>=0,JCIMS!P15/INDEX(CIMS!P$4:P$41,MATCH("Generic Fuels"&$E15,CIMS!$W$4:$W$41,0)),1) -> 1 | Q15: =IF(JCIMS!Q15>=0,JCIMS!Q15/INDEX(CIMS!Q$4:Q$41,MATCH("Generic Fuels"&$E15,CIMS!$W$4:$W$41,0)),1) -> 1 | ... T15: =IF(JCIMS!T15>=0,JCIMS!T15/INDEX(CIMS!T$4:T$41,MATCH("Generic Fuels"&$E15,CIMS!$W$4:$W$41,0)),1) -> 1 | V15: =C15&D15&E15 -> AlbertaAgricultureBiogas
C16: Alberta | D16: Agriculture | E16: LPG | F16: 2005 | G16: CAD | H16: GJ | I16: JCIMS | J16: =IF(JCIMS!J16>=0,JCIMS!J16/INDEX(CIMS!J$4:J$41,MATCH("Generic Fuels"&$E16,CIMS!$W$4:$W$41,0)),1) -> 1 | K16: =IF(JCIMS!K16>=0,JCIMS!K16/INDEX(CIMS!K$4:K$41,MATCH("Generic Fuels"&$E16,CIMS!$W$4:$W$41,0)),1) -> 1 | L16: =IF(JCIMS!L16>=0,JCIMS!L16/INDEX(CIMS!L$4:L$41,MATCH("Generic Fuels"&$E16,CIMS!$W$4:$W$41,0)),1) -> 1 | M16: =IF(JCIMS!M16>=0,JCIMS!M16/INDEX(CIMS!M$4:M$41,MATCH("Generic Fuels"&$E16,CIMS!$W$4:$W$41,0)),1) -> 1 | N16: =IF(JCIMS!N16>=0,JCIMS!N16/INDEX(CIMS!N$4:N$41,MATCH("Generic Fuels"&$E16,CIMS!$W$4:$W$41,0)),1) -> 1 | O16: =IF(JCIMS!O16>=0,JCIMS!O16/INDEX(CIMS!O$4:O$41,MATCH("Generic Fuels"&$E16,CIMS!$W$4:$W$41,0)),1) -> 1 | P16: =IF(JCIMS!P16>=0,JCIMS!P16/INDEX(CIMS!P$4:P$41,MATCH("Generic Fuels"&$E16,CIMS!$W$4:$W$41,0)),1) -> 1 | Q16: =IF(JCIMS!Q16>=0,JCIMS!Q16/INDEX(CIMS!Q$4:Q$41,MATCH("Generic Fuels"&$E16,CIMS!$W$4:$W$41,0)),1) -> 1 | ... T16: =IF(JCIMS!T16>=0,JCIMS!T16/INDEX(CIMS!T$4:T$41,MATCH("Generic Fuels"&$E16,CIMS!$W$4:$W$41,0)),1) -> 1 | V16: =C16&D16&E16 -> AlbertaAgricultureLPG
C17: Alberta | D17: Agriculture | E17: Natural Gas | F17: 2005 | G17: CAD | H17: GJ | I17: JCIMS | J17: =IF(JCIMS!J17>=0,JCIMS!J17/INDEX(CIMS!J$4:J$41,MATCH("Generic Fuels"&$E17,CIMS!$W$4:$W$41,0)),1) -> 1.5163094 | K17: =IF(JCIMS!K17>=0,JCIMS!K17/INDEX(CIMS!K$4:K$41,MATCH("Generic Fuels"&$E17,CIMS!$W$4:$W$41,0)),1) -> 1.1160073 | L17: =IF(JCIMS!L17>=0,JCIMS!L17/INDEX(CIMS!L$4:L$41,MATCH("Generic Fuels"&$E17,CIMS!$W$4:$W$41,0)),1) -> 0.81132676 | M17: =IF(JCIMS!M17>=0,JCIMS!M17/INDEX(CIMS!M$4:M$41,MATCH("Generic Fuels"&$E17,CIMS!$W$4:$W$41,0)),1) -> 0.44280498 | N17: =IF(JCIMS!N17>=0,JCIMS!N17/INDEX(CIMS!N$4:N$41,MATCH("Generic Fuels"&$E17,CIMS!$W$4:$W$41,0)),1) -> 1.9148443 | O17: =IF(JCIMS!O17>=0,JCIMS!O17/INDEX(CIMS!O$4:O$41,MATCH("Generic Fuels"&$E17,CIMS!$W$4:$W$41,0)),1) -> 1.9837531 | P17: =IF(JCIMS!P17>=0,JCIMS!P17/INDEX(CIMS!P$4:P$41,MATCH("Generic Fuels"&$E17,CIMS!$W$4:$W$41,0)),1) -> 2.1434783 | Q17: =IF(JCIMS!Q17>=0,JCIMS!Q17/INDEX(CIMS!Q$4:Q$41,MATCH("Generic Fuels"&$E17,CIMS!$W$4:$W$41,0)),1) -> 2.0033718 | ... T17: =IF(JCIMS!T17>=0,JCIMS!T17/INDEX(CIMS!T$4:T$41,MATCH("Generic Fuels"&$E17,CIMS!$W$4:$W$41,0)),1) -> 1.3318893 | V17: =C17&D17&E17 -> AlbertaAgricultureNatural Gas
C18: Alberta | D18: Agriculture | E18: Petroleum Coke | F18: 2005 | G18: CAD | H18: GJ | I18: JCIMS | J18: =IF(JCIMS!J18>=0,JCIMS!J18/INDEX(CIMS!J$4:J$41,MATCH("Generic Fuels"&$E18,CIMS!$W$4:$W$41,0)),1) -> 1 | K18: =IF(JCIMS!K18>=0,JCIMS!K18/INDEX(CIMS!K$4:K$41,MATCH("Generic Fuels"&$E18,CIMS!$W$4:$W$41,0)),1) -> 1 | L18: =IF(JCIMS!L18>=0,JCIMS!L18/INDEX(CIMS!L$4:L$41,MATCH("Generic Fuels"&$E18,CIMS!$W$4:$W$41,0)),1) -> 1 | M18: =IF(JCIMS!M18>=0,JCIMS!M18/INDEX(CIMS!M$4:M$41,MATCH("Generic Fuels"&$E18,CIMS!$W$4:$W$41,0)),1) -> 1 | N18: =IF(JCIMS!N18>=0,JCIMS!N18/INDEX(CIMS!N$4:N$41,MATCH("Generic Fuels"&$E18,CIMS!$W$4:$W$41,0)),1) -> 1 | O18: =IF(JCIMS!O18>=0,JCIMS!O18/INDEX(CIMS!O$4:O$41,MATCH("Generic Fuels"&$E18,CIMS!$W$4:$W$41,0)),1) -> 1 | P18: =IF(JCIMS!P18>=0,JCIMS!P18/INDEX(CIMS!P$4:P$41,MATCH("Generic Fuels"&$E18,CIMS!$W$4:$W$41,0)),1) -> 1 | Q18: =IF(JCIMS!Q18>=0,JCIMS!Q18/INDEX(CIMS!Q$4:Q$41,MATCH("Generic Fuels"&$E18,CIMS!$W$4:$W$41,0)),1) -> 1 | ... T18: =IF(JCIMS!T18>=0,JCIMS!T18/INDEX(CIMS!T$4:T$41,MATCH("Generic Fuels"&$E18,CIMS!$W$4:$W$41,0)),1) -> 1 | V18: =C18&D18&E18 -> AlbertaAgriculturePetroleum Coke
... C23: Alberta | D23: Agriculture | E23: Solid Biomass | F23: 2005 | G23: CAD | H23: GJ | I23: JCIMS | J23: =IF(JCIMS!J23>=0,JCIMS!J23/INDEX(CIMS!J$4:J$41,MATCH("Generic Fuels"&$E23,CIMS!$W$4:$W$41,0)),1) -> 1 | K23: =IF(JCIMS!K23>=0,JCIMS!K23/INDEX(CIMS!K$4:K$41,MATCH("Generic Fuels"&$E23,CIMS!$W$4:$W$41,0)),1) -> 1 | L23: =IF(JCIMS!L23>=0,JCIMS!L23/INDEX(CIMS!L$4:L$41,MATCH("Generic Fuels"&$E23,CIMS!$W$4:$W$41,0)),1) -> 1 | M23: =IF(JCIMS!M23>=0,JCIMS!M23/INDEX(CIMS!M$4:M$41,MATCH("Generic Fuels"&$E23,CIMS!$W$4:$W$41,0)),1) -> 1 | N23: =IF(JCIMS!N23>=0,JCIMS!N23/INDEX(CIMS!N$4:N$41,MATCH("Generic Fuels"&$E23,CIMS!$W$4:$W$41,0)),1) -> 1 | O23: =IF(JCIMS!O23>=0,JCIMS!O23/INDEX(CIMS!O$4:O$41,MATCH("Generic Fuels"&$E23,CIMS!$W$4:$W$41,0)),1) -> 1 | P23: =IF(JCIMS!P23>=0,JCIMS!P23/INDEX(CIMS!P$4:P$41,MATCH("Generic Fuels"&$E23,CIMS!$W$4:$W$41,0)),1) -> 1 | Q23: =IF(JCIMS!Q23>=0,JCIMS!Q23/INDEX(CIMS!Q$4:Q$41,MATCH("Generic Fuels"&$E23,CIMS!$W$4:$W$41,0)),1) -> 1 | ... T23: =IF(JCIMS!T23>=0,JCIMS!T23/INDEX(CIMS!T$4:T$41,MATCH("Generic Fuels"&$E23,CIMS!$W$4:$W$41,0)),1) -> 1 | V23: =C23&D23&E23 -> AlbertaAgricultureSolid Biomass
C24: Alberta | D24: Biodiesel | E24: Biodiesel | F24: 2005 | G24: CAD | H24: GJ | I24: JCIMS | J24: =IF(JCIMS!J24>=0,JCIMS!J24/INDEX(CIMS!J$4:J$41,MATCH($C24&$E24,CIMS!$W$4:$W$41,0)),1) -> 1.1868954 | K24: =IF(JCIMS!K24>=0,JCIMS!K24/INDEX(CIMS!K$4:K$41,MATCH($C24&$E24,CIMS!$W$4:$W$41,0)),1) -> 1.4689607 | L24: =IF(JCIMS!L24>=0,JCIMS!L24/INDEX(CIMS!L$4:L$41,MATCH($C24&$E24,CIMS!$W$4:$W$41,0)),1) -> 1.880258 | M24: =IF(JCIMS!M24>=0,JCIMS!M24/INDEX(CIMS!M$4:M$41,MATCH($C24&$E24,CIMS!$W$4:$W$41,0)),1) -> 2.0992134 | N24: =IF(JCIMS!N24>=0,JCIMS!N24/INDEX(CIMS!N$4:N$41,MATCH($C24&$E24,CIMS!$W$4:$W$41,0)),1) -> 2.2031115 | O24: =IF(JCIMS!O24>=0,JCIMS!O24/INDEX(CIMS!O$4:O$41,MATCH($C24&$E24,CIMS!$W$4:$W$41,0)),1) -> 2.9053912 | P24: =IF(JCIMS!P24>=0,JCIMS!P24/INDEX(CIMS!P$4:P$41,MATCH($C24&$E24,CIMS!$W$4:$W$41,0)),1) -> 2.7829301 | Q24: =IF(JCIMS!Q24>=0,JCIMS!Q24/INDEX(CIMS!Q$4:Q$41,MATCH($C24&$E24,CIMS!$W$4:$W$41,0)),1) -> 2.6695271 | ... T24: =IF(JCIMS!T24>=0,JCIMS!T24/INDEX(CIMS!T$4:T$41,MATCH($C24&$E24,CIMS!$W$4:$W$41,0)),1) -> 2.5612593 | V24: =C24&D24&E24 -> AlbertaBiodieselBiodiesel
C25: Alberta | D25: Biodiesel | E25: Electricity | F25: 2005 | G25: CAD | H25: GJ | I25: JCIMS | J25: =IF(JCIMS!J25>=0,JCIMS!J25/INDEX(CIMS!J$4:J$41,MATCH($C25&$E25,CIMS!$W$4:$W$41,0)),1) -> 0.22794841 | K25: =IF(JCIMS!K25>=0,JCIMS!K25/INDEX(CIMS!K$4:K$41,MATCH($C25&$E25,CIMS!$W$4:$W$41,0)),1) -> 0.69791862 | L25: =IF(JCIMS!L25>=0,JCIMS!L25/INDEX(CIMS!L$4:L$41,MATCH($C25&$E25,CIMS!$W$4:$W$41,0)),1) -> 1.0587142 | M25: =IF(JCIMS!M25>=0,JCIMS!M25/INDEX(CIMS!M$4:M$41,MATCH($C25&$E25,CIMS!$W$4:$W$41,0)),1) -> 1.6976859 | N25: =IF(JCIMS!N25>=0,JCIMS!N25/INDEX(CIMS!N$4:N$41,MATCH($C25&$E25,CIMS!$W$4:$W$41,0)),1) -> 1.5115374 | O25: =IF(JCIMS!O25>=0,JCIMS!O25/INDEX(CIMS!O$4:O$41,MATCH($C25&$E25,CIMS!$W$4:$W$41,0)),1) -> 1.5905143 | P25: =IF(JCIMS!P25>=0,JCIMS!P25/INDEX(CIMS!P$4:P$41,MATCH($C25&$E25,CIMS!$W$4:$W$41,0)),1) -> 1.7373186 | Q25: =IF(JCIMS!Q25>=0,JCIMS!Q25/INDEX(CIMS!Q$4:Q$41,MATCH($C25&$E25,CIMS!$W$4:$W$41,0)),1) -> 1.5983 | ... T25: =IF(JCIMS!T25>=0,JCIMS!T25/INDEX(CIMS!T$4:T$41,MATCH($C25&$E25,CIMS!$W$4:$W$41,0)),1) -> 1.2628374 | V25: =C25&D25&E25 -> AlbertaBiodieselElectricity
C26: Alberta | D26: Biodiesel | E26: Ethanol | F26: 2005 | G26: CAD | H26: GJ | I26: JCIMS | J26: =IF(JCIMS!J26>=0,JCIMS!J26/INDEX(CIMS!J$4:J$41,MATCH($C26&$E26,CIMS!$W$4:$W$41,0)),1) -> 1 | K26: =IF(JCIMS!K26>=0,JCIMS!K26/INDEX(CIMS!K$4:K$41,MATCH($C26&$E26,CIMS!$W$4:$W$41,0)),1) -> 1 | L26: =IF(JCIMS!L26>=0,JCIMS!L26/INDEX(CIMS!L$4:L$41,MATCH($C26&$E26,CIMS!$W$4:$W$41,0)),1) -> 1 | M26: =IF(JCIMS!M26>=0,JCIMS!M26/INDEX(CIMS!M$4:M$41,MATCH($C26&$E26,CIMS!$W$4:$W$41,0)),1) -> 1 | N26: =IF(JCIMS!N26>=0,JCIMS!N26/INDEX(CIMS!N$4:N$41,MATCH($C26&$E26,CIMS!$W$4:$W$41,0)),1) -> 1 | O26: =IF(JCIMS!O26>=0,JCIMS!O26/INDEX(CIMS!O$4:O$41,MATCH($C26&$E26,CIMS!$W$4:$W$41,0)),1) -> 1 | P26: =IF(JCIMS!P26>=0,JCIMS!P26/INDEX(CIMS!P$4:P$41,MATCH($C26&$E26,CIMS!$W$4:$W$41,0)),1) -> 1 | Q26: =IF(JCIMS!Q26>=0,JCIMS!Q26/INDEX(CIMS!Q$4:Q$41,MATCH($C26&$E26,CIMS!$W$4:$W$41,0)),1) -> 1 | ... T26: =IF(JCIMS!T26>=0,JCIMS!T26/INDEX(CIMS!T$4:T$41,MATCH($C26&$E26,CIMS!$W$4:$W$41,0)),1) -> 1 | V26: =C26&D26&E26 -> AlbertaBiodieselEthanol
C27: Alberta | D27: Biodiesel | E27: Jet Fuel | F27: 2005 | G27: CAD | H27: GJ | I27: JCIMS | J27: =IF(JCIMS!J27>=0,JCIMS!J27/INDEX(CIMS!J$4:J$41,MATCH("Generic Fuels"&$E27,CIMS!$W$4:$W$41,0)),1) -> 1 | K27: =IF(JCIMS!K27>=0,JCIMS!K27/INDEX(CIMS!K$4:K$41,MATCH("Generic Fuels"&$E27,CIMS!$W$4:$W$41,0)),1) -> 1 | L27: =IF(JCIMS!L27>=0,JCIMS!L27/INDEX(CIMS!L$4:L$41,MATCH("Generic Fuels"&$E27,CIMS!$W$4:$W$41,0)),1) -> 1 | M27: =IF(JCIMS!M27>=0,JCIMS!M27/INDEX(CIMS!M$4:M$41,MATCH("Generic Fuels"&$E27,CIMS!$W$4:$W$41,0)),1) -> 1 | N27: =IF(JCIMS!N27>=0,JCIMS!N27/INDEX(CIMS!N$4:N$41,MATCH("Generic Fuels"&$E27,CIMS!$W$4:$W$41,0)),1) -> 1 | O27: =IF(JCIMS!O27>=0,JCIMS!O27/INDEX(CIMS!O$4:O$41,MATCH("Generic Fuels"&$E27,CIMS!$W$4:$W$41,0)),1) -> 1 | P27: =IF(JCIMS!P27>=0,JCIMS!P27/INDEX(CIMS!P$4:P$41,MATCH("Generic Fuels"&$E27,CIMS!$W$4:$W$41,0)),1) -> 1 | Q27: =IF(JCIMS!Q27>=0,JCIMS!Q27/INDEX(CIMS!Q$4:Q$41,MATCH("Generic Fuels"&$E27,CIMS!$W$4:$W$41,0)),1) -> 1 | ... T27: =IF(JCIMS!T27>=0,JCIMS!T27/INDEX(CIMS!T$4:T$41,MATCH("Generic Fuels"&$E27,CIMS!$W$4:$W$41,0)),1) -> 1 | V27: =C27&D27&E27 -> AlbertaBiodieselJet Fuel
C28: Alberta | D28: Biodiesel | E28: Black Liquor | F28: 2005 | G28: CAD | H28: GJ | I28: JCIMS | J28: =IF(JCIMS!J28>=0,JCIMS!J28/INDEX(CIMS!J$4:J$41,MATCH("Generic Fuels"&$E28,CIMS!$W$4:$W$41,0)),1) -> 1 | K28: =IF(JCIMS!K28>=0,JCIMS!K28/INDEX(CIMS!K$4:K$41,MATCH("Generic Fuels"&$E28,CIMS!$W$4:$W$41,0)),1) -> 1 | L28: =IF(JCIMS!L28>=0,JCIMS!L28/INDEX(CIMS!L$4:L$41,MATCH("Generic Fuels"&$E28,CIMS!$W$4:$W$41,0)),1) -> 1 | M28: =IF(JCIMS!M28>=0,JCIMS!M28/INDEX(CIMS!M$4:M$41,MATCH("Generic Fuels"&$E28,CIMS!$W$4:$W$41,0)),1) -> 1 | N28: =IF(JCIMS!N28>=0,JCIMS!N28/INDEX(CIMS!N$4:N$41,MATCH("Generic Fuels"&$E28,CIMS!$W$4:$W$41,0)),1) -> 1 | O28: =IF(JCIMS!O28>=0,JCIMS!O28/INDEX(CIMS!O$4:O$41,MATCH("Generic Fuels"&$E28,CIMS!$W$4:$W$41,0)),1) -> 1 | P28: =IF(JCIMS!P28>=0,JCIMS!P28/INDEX(CIMS!P$4:P$41,MATCH("Generic Fuels"&$E28,CIMS!$W$4:$W$41,0)),1) -> 1 | Q28: =IF(JCIMS!Q28>=0,JCIMS!Q28/INDEX(CIMS!Q$4:Q$41,MATCH("Generic Fuels"&$E28,CIMS!$W$4:$W$41,0)),1) -> 1 | ... T28: =IF(JCIMS!T28>=0,JCIMS!T28/INDEX(CIMS!T$4:T$41,MATCH("Generic Fuels"&$E28,CIMS!$W$4:$W$41,0)),1) -> 1 | V28: =C28&D28&E28 -> AlbertaBiodieselBlack Liquor
C29: Alberta | D29: Biodiesel | E29: Coal | F29: 2005 | G29: CAD | H29: GJ | I29: JCIMS | J29: =IF(JCIMS!J29>=0,JCIMS!J29/INDEX(CIMS!J$4:J$41,MATCH("Generic Fuels"&$E29,CIMS!$W$4:$W$41,0)),1) -> 1.0250494 | K29: =IF(JCIMS!K29>=0,JCIMS!K29/INDEX(CIMS!K$4:K$41,MATCH("Generic Fuels"&$E29,CIMS!$W$4:$W$41,0)),1) -> 1.1191135 | L29: =IF(JCIMS!L29>=0,JCIMS!L29/INDEX(CIMS!L$4:L$41,MATCH("Generic Fuels"&$E29,CIMS!$W$4:$W$41,0)),1) -> 1.4388435 | M29: =IF(JCIMS!M29>=0,JCIMS!M29/INDEX(CIMS!M$4:M$41,MATCH("Generic Fuels"&$E29,CIMS!$W$4:$W$41,0)),1) -> 1.4388435 | N29: =IF(JCIMS!N29>=0,JCIMS!N29/INDEX(CIMS!N$4:N$41,MATCH("Generic Fuels"&$E29,CIMS!$W$4:$W$41,0)),1) -> 1.4388435 | O29: =IF(JCIMS!O29>=0,JCIMS!O29/INDEX(CIMS!O$4:O$41,MATCH("Generic Fuels"&$E29,CIMS!$W$4:$W$41,0)),1) -> 1.4388435 | P29: =IF(JCIMS!P29>=0,JCIMS!P29/INDEX(CIMS!P$4:P$41,MATCH("Generic Fuels"&$E29,CIMS!$W$4:$W$41,0)),1) -> 1.4388435 | Q29: =IF(JCIMS!Q29>=0,JCIMS!Q29/INDEX(CIMS!Q$4:Q$41,MATCH("Generic Fuels"&$E29,CIMS!$W$4:$W$41,0)),1) -> 1.4388435 | ... T29: =IF(JCIMS!T29>=0,JCIMS!T29/INDEX(CIMS!T$4:T$41,MATCH("Generic Fuels"&$E29,CIMS!$W$4:$W$41,0)),1) -> 1.4388435 | V29: =C29&D29&E29 -> AlbertaBiodieselCoal
C30: Alberta | D30: Biodiesel | E30: Coke | F30: 2005 | G30: CAD | H30: GJ | I30: JCIMS | J30: =IF(JCIMS!J30>=0,JCIMS!J30/INDEX(CIMS!J$4:J$41,MATCH("Generic Fuels"&$E30,CIMS!$W$4:$W$41,0)),1) -> 1 | K30: =IF(JCIMS!K30>=0,JCIMS!K30/INDEX(CIMS!K$4:K$41,MATCH("Generic Fuels"&$E30,CIMS!$W$4:$W$41,0)),1) -> 1 | L30: =IF(JCIMS!L30>=0,JCIMS!L30/INDEX(CIMS!L$4:L$41,MATCH("Generic Fuels"&$E30,CIMS!$W$4:$W$41,0)),1) -> 1 | M30: =IF(JCIMS!M30>=0,JCIMS!M30/INDEX(CIMS!M$4:M$41,MATCH("Generic Fuels"&$E30,CIMS!$W$4:$W$41,0)),1) -> 1 | N30: =IF(JCIMS!N30>=0,JCIMS!N30/INDEX(CIMS!N$4:N$41,MATCH("Generic Fuels"&$E30,CIMS!$W$4:$W$41,0)),1) -> 1 | O30: =IF(JCIMS!O30>=0,JCIMS!O30/INDEX(CIMS!O$4:O$41,MATCH("Generic Fuels"&$E30,CIMS!$W$4:$W$41,0)),1) -> 1 | P30: =IF(JCIMS!P30>=0,JCIMS!P30/INDEX(CIMS!P$4:P$41,MATCH("Generic Fuels"&$E30,CIMS!$W$4:$W$41,0)),1) -> 1 | Q30: =IF(JCIMS!Q30>=0,JCIMS!Q30/INDEX(CIMS!Q$4:Q$41,MATCH("Generic Fuels"&$E30,CIMS!$W$4:$W$41,0)),1) -> 1 | ... T30: =IF(JCIMS!T30>=0,JCIMS!T30/INDEX(CIMS!T$4:T$41,MATCH("Generic Fuels"&$E30,CIMS!$W$4:$W$41,0)),1) -> 1 | V30: =C30&D30&E30 -> AlbertaBiodieselCoke
C31: Alberta | D31: Biodiesel | E31: Diesel | F31: 2005 | G31: CAD | H31: GJ | I31: JCIMS | J31: =IF(JCIMS!J31>=0,JCIMS!J31/INDEX(CIMS!J$4:J$41,MATCH("Generic Fuels"&$E31,CIMS!$W$4:$W$41,0)),1) -> 0.54113867 | K31: =IF(JCIMS!K31>=0,JCIMS!K31/INDEX(CIMS!K$4:K$41,MATCH("Generic Fuels"&$E31,CIMS!$W$4:$W$41,0)),1) -> 0.6699771 | L31: =IF(JCIMS!L31>=0,JCIMS!L31/INDEX(CIMS!L$4:L$41,MATCH("Generic Fuels"&$E31,CIMS!$W$4:$W$41,0)),1) -> 0.99456382 | M31: =IF(JCIMS!M31>=0,JCIMS!M31/INDEX(CIMS!M$4:M$41,MATCH("Generic Fuels"&$E31,CIMS!$W$4:$W$41,0)),1) -> 1.0252742 | N31: =IF(JCIMS!N31>=0,JCIMS!N31/INDEX(CIMS!N$4:N$41,MATCH("Generic Fuels"&$E31,CIMS!$W$4:$W$41,0)),1) -> 1.2011335 | O31: =IF(JCIMS!O31>=0,JCIMS!O31/INDEX(CIMS!O$4:O$41,MATCH("Generic Fuels"&$E31,CIMS!$W$4:$W$41,0)),1) -> 1.332558 | P31: =IF(JCIMS!P31>=0,JCIMS!P31/INDEX(CIMS!P$4:P$41,MATCH("Generic Fuels"&$E31,CIMS!$W$4:$W$41,0)),1) -> 1.4468791 | Q31: =IF(JCIMS!Q31>=0,JCIMS!Q31/INDEX(CIMS!Q$4:Q$41,MATCH("Generic Fuels"&$E31,CIMS!$W$4:$W$41,0)),1) -> 1.5420727 | ... T31: =IF(JCIMS!T31>=0,JCIMS!T31/INDEX(CIMS!T$4:T$41,MATCH("Generic Fuels"&$E31,CIMS!$W$4:$W$41,0)),1) -> 1.6390718 | V31: =C31&D31&E31 -> AlbertaBiodieselDiesel
C32: Alberta | D32: Biodiesel | E32: Gasoline | F32: 2005 | G32: CAD | H32: GJ | I32: JCIMS | J32: =IF(JCIMS!J32>=0,JCIMS!J32/INDEX(CIMS!J$4:J$41,MATCH("Generic Fuels"&$E32,CIMS!$W$4:$W$41,0)),1) -> 1 | K32: =IF(JCIMS!K32>=0,JCIMS!K32/INDEX(CIMS!K$4:K$41,MATCH("Generic Fuels"&$E32,CIMS!$W$4:$W$41,0)),1) -> 1 | L32: =IF(JCIMS!L32>=0,JCIMS!L32/INDEX(CIMS!L$4:L$41,MATCH("Generic Fuels"&$E32,CIMS!$W$4:$W$41,0)),1) -> 1 | M32: =IF(JCIMS!M32>=0,JCIMS!M32/INDEX(CIMS!M$4:M$41,MATCH("Generic Fuels"&$E32,CIMS!$W$4:$W$41,0)),1) -> 1 | N32: =IF(JCIMS!N32>=0,JCIMS!N32/INDEX(CIMS!N$4:N$41,MATCH("Generic Fuels"&$E32,CIMS!$W$4:$W$41,0)),1) -> 1 | O32: =IF(JCIMS!O32>=0,JCIMS!O32/INDEX(CIMS!O$4:O$41,MATCH("Generic Fuels"&$E32,CIMS!$W$4:$W$41,0)),1) -> 1 | P32: =IF(JCIMS!P32>=0,JCIMS!P32/INDEX(CIMS!P$4:P$41,MATCH("Generic Fuels"&$E32,CIMS!$W$4:$W$41,0)),1) -> 1 | Q32: =IF(JCIMS!Q32>=0,JCIMS!Q32/INDEX(CIMS!Q$4:Q$41,MATCH("Generic Fuels"&$E32,CIMS!$W$4:$W$41,0)),1) -> 1 | ... T32: =IF(JCIMS!T32>=0,JCIMS!T32/INDEX(CIMS!T$4:T$41,MATCH("Generic Fuels"&$E32,CIMS!$W$4:$W$41,0)),1) -> 1 | V32: =C32&D32&E32 -> AlbertaBiodieselGasoline
C33: Alberta | D33: Biodiesel | E33: Fuel Oil | F33: 2005 | G33: CAD | H33: GJ | I33: JCIMS | J33: =IF(JCIMS!J33>=0,JCIMS!J33/INDEX(CIMS!J$4:J$41,MATCH("Generic Fuels"&$E33,CIMS!$W$4:$W$41,0)),1) -> 1 | K33: =IF(JCIMS!K33>=0,JCIMS!K33/INDEX(CIMS!K$4:K$41,MATCH("Generic Fuels"&$E33,CIMS!$W$4:$W$41,0)),1) -> 1 | L33: =IF(JCIMS!L33>=0,JCIMS!L33/INDEX(CIMS!L$4:L$41,MATCH("Generic Fuels"&$E33,CIMS!$W$4:$W$41,0)),1) -> 1 | M33: =IF(JCIMS!M33>=0,JCIMS!M33/INDEX(CIMS!M$4:M$41,MATCH("Generic Fuels"&$E33,CIMS!$W$4:$W$41,0)),1) -> 1 | N33: =IF(JCIMS!N33>=0,JCIMS!N33/INDEX(CIMS!N$4:N$41,MATCH("Generic Fuels"&$E33,CIMS!$W$4:$W$41,0)),1) -> 1 | O33: =IF(JCIMS!O33>=0,JCIMS!O33/INDEX(CIMS!O$4:O$41,MATCH("Generic Fuels"&$E33,CIMS!$W$4:$W$41,0)),1) -> 1 | P33: =IF(JCIMS!P33>=0,JCIMS!P33/INDEX(CIMS!P$4:P$41,MATCH("Generic Fuels"&$E33,CIMS!$W$4:$W$41,0)),1) -> 1 | Q33: =IF(JCIMS!Q33>=0,JCIMS!Q33/INDEX(CIMS!Q$4:Q$41,MATCH("Generic Fuels"&$E33,CIMS!$W$4:$W$41,0)),1) -> 1 | ... T33: =IF(JCIMS!T33>=0,JCIMS!T33/INDEX(CIMS!T$4:T$41,MATCH("Generic Fuels"&$E33,CIMS!$W$4:$W$41,0)),1) -> 1 | V33: =C33&D33&E33 -> AlbertaBiodieselFuel Oil
C34: Alberta | D34: Biodiesel | E34: Hydrogen | F34: 2005 | G34: CAD | H34: GJ | I34: JCIMS | J34: =IF(JCIMS!J34>=0,JCIMS!J34/INDEX(CIMS!J$4:J$41,MATCH("Generic Fuels"&$E34,CIMS!$W$4:$W$41,0)),1) -> 1 | K34: =IF(JCIMS!K34>=0,JCIMS!K34/INDEX(CIMS!K$4:K$41,MATCH("Generic Fuels"&$E34,CIMS!$W$4:$W$41,0)),1) -> 1 | L34: =IF(JCIMS!L34>=0,JCIMS!L34/INDEX(CIMS!L$4:L$41,MATCH("Generic Fuels"&$E34,CIMS!$W$4:$W$41,0)),1) -> 1 | M34: =IF(JCIMS!M34>=0,JCIMS!M34/INDEX(CIMS!M$4:M$41,MATCH("Generic Fuels"&$E34,CIMS!$W$4:$W$41,0)),1) -> 1 | N34: =IF(JCIMS!N34>=0,JCIMS!N34/INDEX(CIMS!N$4:N$41,MATCH("Generic Fuels"&$E34,CIMS!$W$4:$W$41,0)),1) -> 1 | O34: =IF(JCIMS!O34>=0,JCIMS!O34/INDEX(CIMS!O$4:O$41,MATCH("Generic Fuels"&$E34,CIMS!$W$4:$W$41,0)),1) -> 1 | P34: =IF(JCIMS!P34>=0,JCIMS!P34/INDEX(CIMS!P$4:P$41,MATCH("Generic Fuels"&$E34,CIMS!$W$4:$W$41,0)),1) -> 1 | Q34: =IF(JCIMS!Q34>=0,JCIMS!Q34/INDEX(CIMS!Q$4:Q$41,MATCH("Generic Fuels"&$E34,CIMS!$W$4:$W$41,0)),1) -> 1 | ... T34: =IF(JCIMS!T34>=0,JCIMS!T34/INDEX(CIMS!T$4:T$41,MATCH("Generic Fuels"&$E34,CIMS!$W$4:$W$41,0)),1) -> 1 | V34: =C34&D34&E34 -> AlbertaBiodieselHydrogen
C35: Alberta | D35: Biodiesel | E35: Biogas | F35: 2005 | G35: CAD | H35: GJ | I35: JCIMS | J35: =IF(JCIMS!J35>=0,JCIMS!J35/INDEX(CIMS!J$4:J$41,MATCH("Generic Fuels"&$E35,CIMS!$W$4:$W$41,0)),1) -> 1 | K35: =IF(JCIMS!K35>=0,JCIMS!K35/INDEX(CIMS!K$4:K$41,MATCH("Generic Fuels"&$E35,CIMS!$W$4:$W$41,0)),1) -> 1 | L35: =IF(JCIMS!L35>=0,JCIMS!L35/INDEX(CIMS!L$4:L$41,MATCH("Generic Fuels"&$E35,CIMS!$W$4:$W$41,0)),1) -> 1 | M35: =IF(JCIMS!M35>=0,JCIMS!M35/INDEX(CIMS!M$4:M$41,MATCH("Generic Fuels"&$E35,CIMS!$W$4:$W$41,0)),1) -> 1 | N35: =IF(JCIMS!N35>=0,JCIMS!N35/INDEX(CIMS!N$4:N$41,MATCH("Generic Fuels"&$E35,CIMS!$W$4:$W$41,0)),1) -> 1 | O35: =IF(JCIMS!O35>=0,JCIMS!O35/INDEX(CIMS!O$4:O$41,MATCH("Generic Fuels"&$E35,CIMS!$W$4:$W$41,0)),1) -> 1 | P35: =IF(JCIMS!P35>=0,JCIMS!P35/INDEX(CIMS!P$4:P$41,MATCH("Generic Fuels"&$E35,CIMS!$W$4:$W$41,0)),1) -> 1 | Q35: =IF(JCIMS!Q35>=0,JCIMS!Q35/INDEX(CIMS!Q$4:Q$41,MATCH("Generic Fuels"&$E35,CIMS!$W$4:$W$41,0)),1) -> 1 | ... T35: =IF(JCIMS!T35>=0,JCIMS!T35/INDEX(CIMS!T$4:T$41,MATCH("Generic Fuels"&$E35,CIMS!$W$4:$W$41,0)),1) -> 1 | V35: =C35&D35&E35 -> AlbertaBiodieselBiogas
C36: Alberta | D36: Biodiesel | E36: LPG | F36: 2005 | G36: CAD | H36: GJ | I36: JCIMS | J36: =IF(JCIMS!J36>=0,JCIMS!J36/INDEX(CIMS!J$4:J$41,MATCH("Generic Fuels"&$E36,CIMS!$W$4:$W$41,0)),1) -> 1 | K36: =IF(JCIMS!K36>=0,JCIMS!K36/INDEX(CIMS!K$4:K$41,MATCH("Generic Fuels"&$E36,CIMS!$W$4:$W$41,0)),1) -> 1 | L36: =IF(JCIMS!L36>=0,JCIMS!L36/INDEX(CIMS!L$4:L$41,MATCH("Generic Fuels"&$E36,CIMS!$W$4:$W$41,0)),1) -> 1 | M36: =IF(JCIMS!M36>=0,JCIMS!M36/INDEX(CIMS!M$4:M$41,MATCH("Generic Fuels"&$E36,CIMS!$W$4:$W$41,0)),1) -> 1 | N36: =IF(JCIMS!N36>=0,JCIMS!N36/INDEX(CIMS!N$4:N$41,MATCH("Generic Fuels"&$E36,CIMS!$W$4:$W$41,0)),1) -> 1 | O36: =IF(JCIMS!O36>=0,JCIMS!O36/INDEX(CIMS!O$4:O$41,MATCH("Generic Fuels"&$E36,CIMS!$W$4:$W$41,0)),1) -> 1 | P36: =IF(JCIMS!P36>=0,JCIMS!P36/INDEX(CIMS!P$4:P$41,MATCH("Generic Fuels"&$E36,CIMS!$W$4:$W$41,0)),1) -> 1 | Q36: =IF(JCIMS!Q36>=0,JCIMS!Q36/INDEX(CIMS!Q$4:Q$41,MATCH("Generic Fuels"&$E36,CIMS!$W$4:$W$41,0)),1) -> 1 | ... T36: =IF(JCIMS!T36>=0,JCIMS!T36/INDEX(CIMS!T$4:T$41,MATCH("Generic Fuels"&$E36,CIMS!$W$4:$W$41,0)),1) -> 1 | V36: =C36&D36&E36 -> AlbertaBiodieselLPG
C37: Alberta | D37: Biodiesel | E37: Natural Gas | F37: 2005 | G37: CAD | H37: GJ | I37: JCIMS | J37: =IF(JCIMS!J37>=0,JCIMS!J37/INDEX(CIMS!J$4:J$41,MATCH("Generic Fuels"&$E37,CIMS!$W$4:$W$41,0)),1) -> 1.5753572 | K37: =IF(JCIMS!K37>=0,JCIMS!K37/INDEX(CIMS!K$4:K$41,MATCH("Generic Fuels"&$E37,CIMS!$W$4:$W$41,0)),1) -> 1.1602932 | L37: =IF(JCIMS!L37>=0,JCIMS!L37/INDEX(CIMS!L$4:L$41,MATCH("Generic Fuels"&$E37,CIMS!$W$4:$W$41,0)),1) -> 0.81132676 | M37: =IF(JCIMS!M37>=0,JCIMS!M37/INDEX(CIMS!M$4:M$41,MATCH("Generic Fuels"&$E37,CIMS!$W$4:$W$41,0)),1) -> 0.44280498 | N37: =IF(JCIMS!N37>=0,JCIMS!N37/INDEX(CIMS!N$4:N$41,MATCH("Generic Fuels"&$E37,CIMS!$W$4:$W$41,0)),1) -> 1.9148443 | O37: =IF(JCIMS!O37>=0,JCIMS!O37/INDEX(CIMS!O$4:O$41,MATCH("Generic Fuels"&$E37,CIMS!$W$4:$W$41,0)),1) -> 1.9837531 | P37: =IF(JCIMS!P37>=0,JCIMS!P37/INDEX(CIMS!P$4:P$41,MATCH("Generic Fuels"&$E37,CIMS!$W$4:$W$41,0)),1) -> 2.1434783 | Q37: =IF(JCIMS!Q37>=0,JCIMS!Q37/INDEX(CIMS!Q$4:Q$41,MATCH("Generic Fuels"&$E37,CIMS!$W$4:$W$41,0)),1) -> 2.0033718 | ... T37: =IF(JCIMS!T37>=0,JCIMS!T37/INDEX(CIMS!T$4:T$41,MATCH("Generic Fuels"&$E37,CIMS!$W$4:$W$41,0)),1) -> 1.3318893 | V37: =C37&D37&E37 -> AlbertaBiodieselNatural Gas
C38: Alberta | D38: Biodiesel | E38: Petroleum Coke | F38: 2005 | G38: CAD | H38: GJ | I38: JCIMS | J38: =IF(JCIMS!J38>=0,JCIMS!J38/INDEX(CIMS!J$4:J$41,MATCH("Generic Fuels"&$E38,CIMS!$W$4:$W$41,0)),1) -> 1 | K38: =IF(JCIMS!K38>=0,JCIMS!K38/INDEX(CIMS!K$4:K$41,MATCH("Generic Fuels"&$E38,CIMS!$W$4:$W$41,0)),1) -> 1 | L38: =IF(JCIMS!L38>=0,JCIMS!L38/INDEX(CIMS!L$4:L$41,MATCH("Generic Fuels"&$E38,CIMS!$W$4:$W$41,0)),1) -> 1 | M38: =IF(JCIMS!M38>=0,JCIMS!M38/INDEX(CIMS!M$4:M$41,MATCH("Generic Fuels"&$E38,CIMS!$W$4:$W$41,0)),1) -> 1 | N38: =IF(JCIMS!N38>=0,JCIMS!N38/INDEX(CIMS!N$4:N$41,MATCH("Generic Fuels"&$E38,CIMS!$W$4:$W$41,0)),1) -> 1 | O38: =IF(JCIMS!O38>=0,JCIMS!O38/INDEX(CIMS!O$4:O$41,MATCH("Generic Fuels"&$E38,CIMS!$W$4:$W$41,0)),1) -> 1 | P38: =IF(JCIMS!P38>=0,JCIMS!P38/INDEX(CIMS!P$4:P$41,MATCH("Generic Fuels"&$E38,CIMS!$W$4:$W$41,0)),1) -> 1 | Q38: =IF(JCIMS!Q38>=0,JCIMS!Q38/INDEX(CIMS!Q$4:Q$41,MATCH("Generic Fuels"&$E38,CIMS!$W$4:$W$41,0)),1) -> 1 | ... T38: =IF(JCIMS!T38>=0,JCIMS!T38/INDEX(CIMS!T$4:T$41,MATCH("Generic Fuels"&$E38,CIMS!$W$4:$W$41,0)),1) -> 1 | V38: =C38&D38&E38 -> AlbertaBiodieselPetroleum Coke
... C43: Alberta | D43: Biodiesel | E43: Solid Biomass | F43: 2005 | G43: CAD | H43: GJ | I43: JCIMS | J43: =IF(JCIMS!J43>=0,JCIMS!J43/INDEX(CIMS!J$4:J$41,MATCH("Generic Fuels"&$E43,CIMS!$W$4:$W$41,0)),1) -> 1 | K43: =IF(JCIMS!K43>=0,JCIMS!K43/INDEX(CIMS!K$4:K$41,MATCH("Generic Fuels"&$E43,CIMS!$W$4:$W$41,0)),1) -> 1 | L43: =IF(JCIMS!L43>=0,JCIMS!L43/INDEX(CIMS!L$4:L$41,MATCH("Generic Fuels"&$E43,CIMS!$W$4:$W$41,0)),1) -> 1 | M43: =IF(JCIMS!M43>=0,JCIMS!M43/INDEX(CIMS!M$4:M$41,MATCH("Generic Fuels"&$E43,CIMS!$W$4:$W$41,0)),1) -> 1 | N43: =IF(JCIMS!N43>=0,JCIMS!N43/INDEX(CIMS!N$4:N$41,MATCH("Generic Fuels"&$E43,CIMS!$W$4:$W$41,0)),1) -> 1 | O43: =IF(JCIMS!O43>=0,JCIMS!O43/INDEX(CIMS!O$4:O$41,MATCH("Generic Fuels"&$E43,CIMS!$W$4:$W$41,0)),1) -> 1 | P43: =IF(JCIMS!P43>=0,JCIMS!P43/INDEX(CIMS!P$4:P$41,MATCH("Generic Fuels"&$E43,CIMS!$W$4:$W$41,0)),1) -> 1 | Q43: =IF(JCIMS!Q43>=0,JCIMS!Q43/INDEX(CIMS!Q$4:Q$41,MATCH("Generic Fuels"&$E43,CIMS!$W$4:$W$41,0)),1) -> 1 | ... T43: =IF(JCIMS!T43>=0,JCIMS!T43/INDEX(CIMS!T$4:T$41,MATCH("Generic Fuels"&$E43,CIMS!$W$4:$W$41,0)),1) -> 1 | V43: =C43&D43&E43 -> AlbertaBiodieselSolid Biomass
C44: Alberta | D44: Chemical Products | E44: Biodiesel | F44: 2005 | G44: CAD | H44: GJ | I44: JCIMS | J44: =IF(JCIMS!J44>=0,JCIMS!J44/INDEX(CIMS!J$4:J$41,MATCH($C44&$E44,CIMS!$W$4:$W$41,0)),1) -> 1 | K44: =IF(JCIMS!K44>=0,JCIMS!K44/INDEX(CIMS!K$4:K$41,MATCH($C44&$E44,CIMS!$W$4:$W$41,0)),1) -> 1 | L44: =IF(JCIMS!L44>=0,JCIMS!L44/INDEX(CIMS!L$4:L$41,MATCH($C44&$E44,CIMS!$W$4:$W$41,0)),1) -> 1 | M44: =IF(JCIMS!M44>=0,JCIMS!M44/INDEX(CIMS!M$4:M$41,MATCH($C44&$E44,CIMS!$W$4:$W$41,0)),1) -> 1 | N44: =IF(JCIMS!N44>=0,JCIMS!N44/INDEX(CIMS!N$4:N$41,MATCH($C44&$E44,CIMS!$W$4:$W$41,0)),1) -> 1 | O44: =IF(JCIMS!O44>=0,JCIMS!O44/INDEX(CIMS!O$4:O$41,MATCH($C44&$E44,CIMS!$W$4:$W$41,0)),1) -> 1 | P44: =IF(JCIMS!P44>=0,JCIMS!P44/INDEX(CIMS!P$4:P$41,MATCH($C44&$E44,CIMS!$W$4:$W$41,0)),1) -> 1 | Q44: =IF(JCIMS!Q44>=0,JCIMS!Q44/INDEX(CIMS!Q$4:Q$41,MATCH($C44&$E44,CIMS!$W$4:$W$41,0)),1) -> 1 | ... T44: =IF(JCIMS!T44>=0,JCIMS!T44/INDEX(CIMS!T$4:T$41,MATCH($C44&$E44,CIMS!$W$4:$W$41,0)),1) -> 1 | V44: =C44&D44&E44 -> AlbertaChemical ProductsBiodiesel
C45: Alberta | D45: Chemical Products | E45: Electricity | F45: 2005 | G45: CAD | H45: GJ | I45: JCIMS | J45: =IF(JCIMS!J45>=0,JCIMS!J45/INDEX(CIMS!J$4:J$41,MATCH($C45&$E45,CIMS!$W$4:$W$41,0)),1) -> 0.63865561 | K45: =IF(JCIMS!K45>=0,JCIMS!K45/INDEX(CIMS!K$4:K$41,MATCH($C45&$E45,CIMS!$W$4:$W$41,0)),1) -> 1.0117098 | L45: =IF(JCIMS!L45>=0,JCIMS!L45/INDEX(CIMS!L$4:L$41,MATCH($C45&$E45,CIMS!$W$4:$W$41,0)),1) -> 1.0587142 | M45: =IF(JCIMS!M45>=0,JCIMS!M45/INDEX(CIMS!M$4:M$41,MATCH($C45&$E45,CIMS!$W$4:$W$41,0)),1) -> 1.6976859 | N45: =IF(JCIMS!N45>=0,JCIMS!N45/INDEX(CIMS!N$4:N$41,MATCH($C45&$E45,CIMS!$W$4:$W$41,0)),1) -> 1.5115374 | O45: =IF(JCIMS!O45>=0,JCIMS!O45/INDEX(CIMS!O$4:O$41,MATCH($C45&$E45,CIMS!$W$4:$W$41,0)),1) -> 1.5905143 | P45: =IF(JCIMS!P45>=0,JCIMS!P45/INDEX(CIMS!P$4:P$41,MATCH($C45&$E45,CIMS!$W$4:$W$41,0)),1) -> 1.7373186 | Q45: =IF(JCIMS!Q45>=0,JCIMS!Q45/INDEX(CIMS!Q$4:Q$41,MATCH($C45&$E45,CIMS!$W$4:$W$41,0)),1) -> 1.5983 | ... T45: =IF(JCIMS!T45>=0,JCIMS!T45/INDEX(CIMS!T$4:T$41,MATCH($C45&$E45,CIMS!$W$4:$W$41,0)),1) -> 1.2628374 | V45: =C45&D45&E45 -> AlbertaChemical ProductsElectricity
C46: Alberta | D46: Chemical Products | E46: Ethanol | F46: 2005 | G46: CAD | H46: GJ | I46: JCIMS | J46: =IF(JCIMS!J46>=0,JCIMS!J46/INDEX(CIMS!J$4:J$41,MATCH($C46&$E46,CIMS!$W$4:$W$41,0)),1) -> 1 | K46: =IF(JCIMS!K46>=0,JCIMS!K46/INDEX(CIMS!K$4:K$41,MATCH($C46&$E46,CIMS!$W$4:$W$41,0)),1) -> 1 | L46: =IF(JCIMS!L46>=0,JCIMS!L46/INDEX(CIMS!L$4:L$41,MATCH($C46&$E46,CIMS!$W$4:$W$41,0)),1) -> 1 | M46: =IF(JCIMS!M46>=0,JCIMS!M46/INDEX(CIMS!M$4:M$41,MATCH($C46&$E46,CIMS!$W$4:$W$41,0)),1) -> 1 | N46: =IF(JCIMS!N46>=0,JCIMS!N46/INDEX(CIMS!N$4:N$41,MATCH($C46&$E46,CIMS!$W$4:$W$41,0)),1) -> 1 | O46: =IF(JCIMS!O46>=0,JCIMS!O46/INDEX(CIMS!O$4:O$41,MATCH($C46&$E46,CIMS!$W$4:$W$41,0)),1) -> 1 | P46: =IF(JCIMS!P46>=0,JCIMS!P46/INDEX(CIMS!P$4:P$41,MATCH($C46&$E46,CIMS!$W$4:$W$41,0)),1) -> 1 | Q46: =IF(JCIMS!Q46>=0,JCIMS!Q46/INDEX(CIMS!Q$4:Q$41,MATCH($C46&$E46,CIMS!$W$4:$W$41,0)),1) -> 1 | ... T46: =IF(JCIMS!T46>=0,JCIMS!T46/INDEX(CIMS!T$4:T$41,MATCH($C46&$E46,CIMS!$W$4:$W$41,0)),1) -> 1 | V46: =C46&D46&E46 -> AlbertaChemical ProductsEthanol
C47: Alberta | D47: Chemical Products | E47: Jet Fuel | F47: 2005 | G47: CAD | H47: GJ | I47: JCIMS | J47: =IF(JCIMS!J47>=0,JCIMS!J47/INDEX(CIMS!J$4:J$41,MATCH("Generic Fuels"&$E47,CIMS!$W$4:$W$41,0)),1) -> 1 | K47: =IF(JCIMS!K47>=0,JCIMS!K47/INDEX(CIMS!K$4:K$41,MATCH("Generic Fuels"&$E47,CIMS!$W$4:$W$41,0)),1) -> 1 | L47: =IF(JCIMS!L47>=0,JCIMS!L47/INDEX(CIMS!L$4:L$41,MATCH("Generic Fuels"&$E47,CIMS!$W$4:$W$41,0)),1) -> 1 | M47: =IF(JCIMS!M47>=0,JCIMS!M47/INDEX(CIMS!M$4:M$41,MATCH("Generic Fuels"&$E47,CIMS!$W$4:$W$41,0)),1) -> 1 | N47: =IF(JCIMS!N47>=0,JCIMS!N47/INDEX(CIMS!N$4:N$41,MATCH("Generic Fuels"&$E47,CIMS!$W$4:$W$41,0)),1) -> 1 | O47: =IF(JCIMS!O47>=0,JCIMS!O47/INDEX(CIMS!O$4:O$41,MATCH("Generic Fuels"&$E47,CIMS!$W$4:$W$41,0)),1) -> 1 | P47: =IF(JCIMS!P47>=0,JCIMS!P47/INDEX(CIMS!P$4:P$41,MATCH("Generic Fuels"&$E47,CIMS!$W$4:$W$41,0)),1) -> 1 | Q47: =IF(JCIMS!Q47>=0,JCIMS!Q47/INDEX(CIMS!Q$4:Q$41,MATCH("Generic Fuels"&$E47,CIMS!$W$4:$W$41,0)),1) -> 1 | ... T47: =IF(JCIMS!T47>=0,JCIMS!T47/INDEX(CIMS!T$4:T$41,MATCH("Generic Fuels"&$E47,CIMS!$W$4:$W$41,0)),1) -> 1 | V47: =C47&D47&E47 -> AlbertaChemical ProductsJet Fuel
C48: Alberta | D48: Chemical Products | E48: Black Liquor | F48: 2005 | G48: CAD | H48: GJ | I48: JCIMS | J48: =IF(JCIMS!J48>=0,JCIMS!J48/INDEX(CIMS!J$4:J$41,MATCH("Generic Fuels"&$E48,CIMS!$W$4:$W$41,0)),1) -> 1 | K48: =IF(JCIMS!K48>=0,JCIMS!K48/INDEX(CIMS!K$4:K$41,MATCH("Generic Fuels"&$E48,CIMS!$W$4:$W$41,0)),1) -> 1 | L48: =IF(JCIMS!L48>=0,JCIMS!L48/INDEX(CIMS!L$4:L$41,MATCH("Generic Fuels"&$E48,CIMS!$W$4:$W$41,0)),1) -> 1 | M48: =IF(JCIMS!M48>=0,JCIMS!M48/INDEX(CIMS!M$4:M$41,MATCH("Generic Fuels"&$E48,CIMS!$W$4:$W$41,0)),1) -> 1 | N48: =IF(JCIMS!N48>=0,JCIMS!N48/INDEX(CIMS!N$4:N$41,MATCH("Generic Fuels"&$E48,CIMS!$W$4:$W$41,0)),1) -> 1 | O48: =IF(JCIMS!O48>=0,JCIMS!O48/INDEX(CIMS!O$4:O$41,MATCH("Generic Fuels"&$E48,CIMS!$W$4:$W$41,0)),1) -> 1 | P48: =IF(JCIMS!P48>=0,JCIMS!P48/INDEX(CIMS!P$4:P$41,MATCH("Generic Fuels"&$E48,CIMS!$W$4:$W$41,0)),1) -> 1 | Q48: =IF(JCIMS!Q48>=0,JCIMS!Q48/INDEX(CIMS!Q$4:Q$41,MATCH("Generic Fuels"&$E48,CIMS!$W$4:$W$41,0)),1) -> 1 | ... T48: =IF(JCIMS!T48>=0,JCIMS!T48/INDEX(CIMS!T$4:T$41,MATCH("Generic Fuels"&$E48,CIMS!$W$4:$W$41,0)),1) -> 1 | V48: =C48&D48&E48 -> AlbertaChemical ProductsBlack Liquor
...

Sheet JCIMS
B1: Category | C1: Region | D1: Sector | E1: Fuel | F1: Unit | I1: Source | J1: 2000 | K1: 2005 | L1: 2010 | M1: 2015 | N1: 2020 | O1: 2025 | P1: 2030 | Q1: 2035 | R1: 2040 | S1: 2045 | T1: 2050 | AE1: 2000 | AF1: 2005 | AG1: 2010 | AH1: 2015 | AI1: 2020 | AJ1: 2025 | AK1: 2030 | AL1: 2035 | AM1: 2040 | AN1: 2045 | AO1: 2050
F2: Year | G2: Currency | H2: Commodity | J2: JCIMS final user price | AD2: Data collected from JCIMS
B3: JCIMS final user price
C4: AB | D4: Agriculture | E4: Biodiesel | F4: 2005 | G4: CAD | H4: GJ | J4: {=IFERROR(_xlfn._xlws.FILTER(AE$4:AE$6723,(AE$4:AE$6723>=0)*($AB$4:$AB$6723=$C4)*($AC$4:$AC$6723=$D4)*(ISNUMBER(_xlfn.XMATCH($AD$4:$AD$6723,$V4:$Z4,0)))),-1)} -> 25.894454 | K4: {=IFERROR(_xlfn._xlws.FILTER(AF$4:AF$6723,(AF$4:AF$6723>=0)*($AB$4:$AB$6723=$C4)*($AC$4:$AC$6723=$D4)*(ISNUMBER(_xlfn.XMATCH($AD$4:$AD$6723,$V4:$Z4,0)))),-1)} -> 31.806651 | L4: {=IFERROR(_xlfn._xlws.FILTER(AG$4:AG$6723,(AG$4:AG$6723>=0)*($AB$4:$AB$6723=$C4)*($AC$4:$AC$6723=$D4)*(ISNUMBER(_xlfn.XMATCH($AD$4:$AD$6723,$V4:$Z4,0)))),-1)} -> 42.233208 | M4: {=IFERROR(_xlfn._xlws.FILTER(AH$4:AH$6723,(AH$4:AH$6723>=0)*($AB$4:$AB$6723=$C4)*($AC$4:$AC$6723=$D4)*(ISNUMBER(_xlfn.XMATCH($AD$4:$AD$6723,$V4:$Z4,0)))),-1)} -> 45.888225 | N4: {=IFERROR(_xlfn._xlws.FILTER(AI$4:AI$6723,(AI$4:AI$6723>=0)*($AB$4:$AB$6723=$C4)*($AC$4:$AC$6723=$D4)*(ISNUMBER(_xlfn.XMATCH($AD$4:$AD$6723,$V4:$Z4,0)))),-1)} -> 49.439287 | O4: {=IFERROR(_xlfn._xlws.FILTER(AJ$4:AJ$6723,(AJ$4:AJ$6723>=0)*($AB$4:$AB$6723=$C4)*($AC$4:$AC$6723=$D4)*(ISNUMBER(_xlfn.XMATCH($AD$4:$AD$6723,$V4:$Z4,0)))),-1)} -> 65.487499 | P4: {=IFERROR(_xlfn._xlws.FILTER(AK$4:AK$6723,(AK$4:AK$6723>=0)*($AB$4:$AB$6723=$C4)*($AC$4:$AC$6723=$D4)*(ISNUMBER(_xlfn.XMATCH($AD$4:$AD$6723,$V4:$Z4,0)))),-1)} -> 63.017398 | Q4: {=IFERROR(_xlfn._xlws.FILTER(AL$4:AL$6723,(AL$4:AL$6723>=0)*($AB$4:$AB$6723=$C4)*($AC$4:$AC$6723=$D4)*(ISNUMBER(_xlfn.XMATCH($AD$4:$AD$6723,$V4:$Z4,0)))),-1)} -> 60.668356 | ... T4: {=IFERROR(_xlfn._xlws.FILTER(AO$4:AO$6723,(AO$4:AO$6723>=0)*($AB$4:$AB$6723=$C4)*($AC$4:$AC$6723=$D4)*(ISNUMBER(_xlfn.XMATCH($AD$4:$AD$6723,$V4:$Z4,0)))),-1)} -> 58.43444 | V4: Biodiesel | AB4: AB | AC4: Agriculture | AD4: Aviation Turbo Fuel | AE4: -1 | AF4: -1 | AG4: -1 | AH4: -1 | AI4: -1 | AJ4: -1 | AK4: -1 | AL4: -1 | AM4: -1 | AN4: -1 | AO4: -1
C5: AB | D5: Agriculture | E5: Electricity | F5: 2005 | G5: CAD | H5: GJ | J5: {=IFERROR(_xlfn._xlws.FILTER(AE$4:AE$6723,(AE$4:AE$6723>=0)*($AB$4:$AB$6723=$C5)*($AC$4:$AC$6723=$D5)*(ISNUMBER(_xlfn.XMATCH($AD$4:$AD$6723,$V5:$Z5,0)))),-1)} -> 23.459667 | K5: {=IFERROR(_xlfn._xlws.FILTER(AF$4:AF$6723,(AF$4:AF$6723>=0)*($AB$4:$AB$6723=$C5)*($AC$4:$AC$6723=$D5)*(ISNUMBER(_xlfn.XMATCH($AD$4:$AD$6723,$V5:$Z5,0)))),-1)} -> 26.178836 | L5: {=IFERROR(_xlfn._xlws.FILTER(AG$4:AG$6723,(AG$4:AG$6723>=0)*($AB$4:$AB$6723=$C5)*($AC$4:$AC$6723=$D5)*(ISNUMBER(_xlfn.XMATCH($AD$4:$AD$6723,$V5:$Z5,0)))),-1)} -> 18.528762 | M5: {=IFERROR(_xlfn._xlws.FILTER(AH$4:AH$6723,(AH$4:AH$6723>=0)*($AB$4:$AB$6723=$C5)*($AC$4:$AC$6723=$D5)*(ISNUMBER(_xlfn.XMATCH($AD$4:$AD$6723,$V5:$Z5,0)))),-1)} -> 26.432553 | N5: {=IFERROR(_xlfn._xlws.FILTER(AI$4:AI$6723,(AI$4:AI$6723>=0)*($AB$4:$AB$6723=$C5)*($AC$4:$AC$6723=$D5)*(ISNUMBER(_xlfn.XMATCH($AD$4:$AD$6723,$V5:$Z5,0)))),-1)} -> 26.34597 | O5: {=IFERROR(_xlfn._xlws.FILTER(AJ$4:AJ$6723,(AJ$4:AJ$6723>=0)*($AB$4:$AB$6723=$C5)*($AC$4:$AC$6723=$D5)*(ISNUMBER(_xlfn.XMATCH($AD$4:$AD$6723,$V5:$Z5,0)))),-1)} -> 30.16269 | P5: {=IFERROR(_xlfn._xlws.FILTER(AK$4:AK$6723,(AK$4:AK$6723>=0)*($AB$4:$AB$6723=$C5)*($AC$4:$AC$6723=$D5)*(ISNUMBER(_xlfn.XMATCH($AD$4:$AD$6723,$V5:$Z5,0)))),-1)} -> 35.681031 | Q5: {=IFERROR(_xlfn._xlws.FILTER(AL$4:AL$6723,(AL$4:AL$6723>=0)*($AB$4:$AB$6723=$C5)*($AC$4:$AC$6723=$D5)*(ISNUMBER(_xlfn.XMATCH($AD$4:$AD$6723,$V5:$Z5,0)))),-1)} -> 35.695167 | ... T5: {=IFERROR(_xlfn._xlws.FILTER(AO$4:AO$6723,(AO$4:AO$6723>=0)*($AB$4:$AB$6723=$C5)*($AC$4:$AC$6723=$D5)*(ISNUMBER(_xlfn.XMATCH($AD$4:$AD$6723,$V5:$Z5,0)))),-1)} -> 35.695167 | V5: Electricity | AB5: AB | AC5: Agriculture | AD5: Biodiesel | AE5: 25.894454 | AF5: 31.806651 | AG5: 42.233208 | AH5: 45.888225 | AI5: 49.439287 | AJ5: 65.487499 | AK5: 63.017398 | AL5: 60.668356 | AM5: 58.43444 | AN5: 58.43444 | AO5: 58.43444
C6: AB | D6: Agriculture | E6: Ethanol | F6: 2005 | G6: CAD | H6: GJ | J6: {=IFERROR(_xlfn._xlws.FILTER(AE$4:AE$6723,(AE$4:AE$6723>=0)*($AB$4:$AB$6723=$C6)*($AC$4:$AC$6723=$D6)*(ISNUMBER(_xlfn.XMATCH($AD$4:$AD$6723,$V6:$Z6,0)))),-1)} -> -1 | K6: {=IFERROR(_xlfn._xlws.FILTER(AF$4:AF$6723,(AF$4:AF$6723>=0)*($AB$4:$AB$6723=$C6)*($AC$4:$AC$6723=$D6)*(ISNUMBER(_xlfn.XMATCH($AD$4:$AD$6723,$V6:$Z6,0)))),-1)} -> -1 | L6: {=IFERROR(_xlfn._xlws.FILTER(AG$4:AG$6723,(AG$4:AG$6723>=0)*($AB$4:$AB$6723=$C6)*($AC$4:$AC$6723=$D6)*(ISNUMBER(_xlfn.XMATCH($AD$4:$AD$6723,$V6:$Z6,0)))),-1)} -> -1 | M6: {=IFERROR(_xlfn._xlws.FILTER(AH$4:AH$6723,(AH$4:AH$6723>=0)*($AB$4:$AB$6723=$C6)*($AC$4:$AC$6723=$D6)*(ISNUMBER(_xlfn.XMATCH($AD$4:$AD$6723,$V6:$Z6,0)))),-1)} -> -1 | N6: {=IFERROR(_xlfn._xlws.FILTER(AI$4:AI$6723,(AI$4:AI$6723>=0)*($AB$4:$AB$6723=$C6)*($AC$4:$AC$6723=$D6)*(ISNUMBER(_xlfn.XMATCH($AD$4:$AD$6723,$V6:$Z6,0)))),-1)} -> -1 | O6: {=IFERROR(_xlfn._xlws.FILTER(AJ$4:AJ$6723,(AJ$4:AJ$6723>=0)*($AB$4:$AB$6723=$C6)*($AC$4:$AC$6723=$D6)*(ISNUMBER(_xlfn.XMATCH($AD$4:$AD$6723,$V6:$Z6,0)))),-1)} -> -1 | P6: {=IFERROR(_xlfn._xlws.FILTER(AK$4:AK$6723,(AK$4:AK$6723>=0)*($AB$4:$AB$6723=$C6)*($AC$4:$AC$6723=$D6)*(ISNUMBER(_xlfn.XMATCH($AD$4:$AD$6723,$V6:$Z6,0)))),-1)} -> -1 | Q6: {=IFERROR(_xlfn._xlws.FILTER(AL$4:AL$6723,(AL$4:AL$6723>=0)*($AB$4:$AB$6723=$C6)*($AC$4:$AC$6723=$D6)*(ISNUMBER(_xlfn.XMATCH($AD$4:$AD$6723,$V6:$Z6,0)))),-1)} -> -1 | ... T6: {=IFERROR(_xlfn._xlws.FILTER(AO$4:AO$6723,(AO$4:AO$6723>=0)*($AB$4:$AB$6723=$C6)*($AC$4:$AC$6723=$D6)*(ISNUMBER(_xlfn.XMATCH($AD$4:$AD$6723,$V6:$Z6,0)))),-1)} -> -1 | V6: Ethanol | AB6: AB | AC6: Agriculture | AD6: Biomethane | AE6: -1 | AF6: -1 | AG6: -1 | AH6: -1 | AI6: -1 | AJ6: -1 | AK6: -1 | AL6: -1 | AM6: -1 | AN6: -1 | AO6: -1
C7: AB | D7: Agriculture | E7: Aviation Turbo Fuel | F7: 2005 | G7: CAD | H7: GJ | J7: {=IFERROR(_xlfn._xlws.FILTER(AE$4:AE$6723,(AE$4:AE$6723>=0)*($AB$4:$AB$6723=$C7)*($AC$4:$AC$6723=$D7)*(ISNUMBER(_xlfn.XMATCH($AD$4:$AD$6723,$V7:$Z7,0)))),-1)} -> -1 | K7: {=IFERROR(_xlfn._xlws.FILTER(AF$4:AF$6723,(AF$4:AF$6723>=0)*($AB$4:$AB$6723=$C7)*($AC$4:$AC$6723=$D7)*(ISNUMBER(_xlfn.XMATCH($AD$4:$AD$6723,$V7:$Z7,0)))),-1)} -> -1 | L7: {=IFERROR(_xlfn._xlws.FILTER(AG$4:AG$6723,(AG$4:AG$6723>=0)*($AB$4:$AB$6723=$C7)*($AC$4:$AC$6723=$D7)*(ISNUMBER(_xlfn.XMATCH($AD$4:$AD$6723,$V7:$Z7,0)))),-1)} -> -1 | M7: {=IFERROR(_xlfn._xlws.FILTER(AH$4:AH$6723,(AH$4:AH$6723>=0)*($AB$4:$AB$6723=$C7)*($AC$4:$AC$6723=$D7)*(ISNUMBER(_xlfn.XMATCH($AD$4:$AD$6723,$V7:$Z7,0)))),-1)} -> -1 | N7: {=IFERROR(_xlfn._xlws.FILTER(AI$4:AI$6723,(AI$4:AI$6723>=0)*($AB$4:$AB$6723=$C7)*($AC$4:$AC$6723=$D7)*(ISNUMBER(_xlfn.XMATCH($AD$4:$AD$6723,$V7:$Z7,0)))),-1)} -> -1 | O7: {=IFERROR(_xlfn._xlws.FILTER(AJ$4:AJ$6723,(AJ$4:AJ$6723>=0)*($AB$4:$AB$6723=$C7)*($AC$4:$AC$6723=$D7)*(ISNUMBER(_xlfn.XMATCH($AD$4:$AD$6723,$V7:$Z7,0)))),-1)} -> -1 | P7: {=IFERROR(_xlfn._xlws.FILTER(AK$4:AK$6723,(AK$4:AK$6723>=0)*($AB$4:$AB$6723=$C7)*($AC$4:$AC$6723=$D7)*(ISNUMBER(_xlfn.XMATCH($AD$4:$AD$6723,$V7:$Z7,0)))),-1)} -> -1 | Q7: {=IFERROR(_xlfn._xlws.FILTER(AL$4:AL$6723,(AL$4:AL$6723>=0)*($AB$4:$AB$6723=$C7)*($AC$4:$AC$6723=$D7)*(ISNUMBER(_xlfn.XMATCH($AD$4:$AD$6723,$V7:$Z7,0)))),-1)} -> -1 | ... T7: {=IFERROR(_xlfn._xlws.FILTER(AO$4:AO$6723,(AO$4:AO$6723>=0)*($AB$4:$AB$6723=$C7)*($AC$4:$AC$6723=$D7)*(ISNUMBER(_xlfn.XMATCH($AD$4:$AD$6723,$V7:$Z7,0)))),-1)} -> -1 | V7: Aviation Turbo Fuel | AB7: AB | AC7: Agriculture | AD7: Bitumen | AE7: -1 | AF7: -1 | AG7: -1 | AH7: -1 | AI7: -1 | AJ7: -1 | AK7: -1 | AL7: -1 | AM7: -1 | AN7: -1 | AO7: -1
C8: AB | D8: Agriculture | E8: Black Liquor | F8: 2005 | G8: CAD | H8: GJ | J8: {=IFERROR(_xlfn._xlws.FILTER(AE$4:AE$6723,(AE$4:AE$6723>=0)*($AB$4:$AB$6723=$C8)*($AC$4:$AC$6723=$D8)*(ISNUMBER(_xlfn.XMATCH($AD$4:$AD$6723,$V8:$Z8,0)))),-1)} -> -1 | K8: {=IFERROR(_xlfn._xlws.FILTER(AF$4:AF$6723,(AF$4:AF$6723>=0)*($AB$4:$AB$6723=$C8)*($AC$4:$AC$6723=$D8)*(ISNUMBER(_xlfn.XMATCH($AD$4:$AD$6723,$V8:$Z8,0)))),-1)} -> -1 | L8: {=IFERROR(_xlfn._xlws.FILTER(AG$4:AG$6723,(AG$4:AG$6723>=0)*($AB$4:$AB$6723=$C8)*($AC$4:$AC$6723=$D8)*(ISNUMBER(_xlfn.XMATCH($AD$4:$AD$6723,$V8:$Z8,0)))),-1)} -> -1 | M8: {=IFERROR(_xlfn._xlws.FILTER(AH$4:AH$6723,(AH$4:AH$6723>=0)*($AB$4:$AB$6723=$C8)*($AC$4:$AC$6723=$D8)*(ISNUMBER(_xlfn.XMATCH($AD$4:$AD$6723,$V8:$Z8,0)))),-1)} -> -1 | N8: {=IFERROR(_xlfn._xlws.FILTER(AI$4:AI$6723,(AI$4:AI$6723>=0)*($AB$4:$AB$6723=$C8)*($AC$4:$AC$6723=$D8)*(ISNUMBER(_xlfn.XMATCH($AD$4:$AD$6723,$V8:$Z8,0)))),-1)} -> -1 | O8: {=IFERROR(_xlfn._xlws.FILTER(AJ$4:AJ$6723,(AJ$4:AJ$6723>=0)*($AB$4:$AB$6723=$C8)*($AC$4:$AC$6723=$D8)*(ISNUMBER(_xlfn.XMATCH($AD$4:$AD$6723,$V8:$Z8,0)))),-1)} -> -1 | P8: {=IFERROR(_xlfn._xlws.FILTER(AK$4:AK$6723,(AK$4:AK$6723>=0)*($AB$4:$AB$6723=$C8)*($AC$4:$AC$6723=$D8)*(ISNUMBER(_xlfn.XMATCH($AD$4:$AD$6723,$V8:$Z8,0)))),-1)} -> -1 | Q8: {=IFERROR(_xlfn._xlws.FILTER(AL$4:AL$6723,(AL$4:AL$6723>=0)*($AB$4:$AB$6723=$C8)*($AC$4:$AC$6723=$D8)*(ISNUMBER(_xlfn.XMATCH($AD$4:$AD$6723,$V8:$Z8,0)))),-1)} -> -1 | ... T8: {=IFERROR(_xlfn._xlws.FILTER(AO$4:AO$6723,(AO$4:AO$6723>=0)*($AB$4:$AB$6723=$C8)*($AC$4:$AC$6723=$D8)*(ISNUMBER(_xlfn.XMATCH($AD$4:$AD$6723,$V8:$Z8,0)))),-1)} -> -1 | V8: Black Liquor | AB8: AB | AC8: Agriculture | AD8: Black Liquor | AE8: -1 | AF8: -1 | AG8: -1 | AH8: -1 | AI8: -1 | AJ8: -1 | AK8: -1 | AL8: -1 | AM8: -1 | AN8: -1 | AO8: -1
C9: AB | D9: Agriculture | E9: Coal | F9: 2005 | G9: CAD | H9: GJ | J9: {=IFERROR(_xlfn._xlws.FILTER(AE$4:AE$6723,(AE$4:AE$6723>=0)*($AB$4:$AB$6723=$C9)*($AC$4:$AC$6723=$D9)*(ISNUMBER(_xlfn.XMATCH($AD$4:$AD$6723,$V9:$Z9,0)))),-1)} -> -1 | K9: {=IFERROR(_xlfn._xlws.FILTER(AF$4:AF$6723,(AF$4:AF$6723>=0)*($AB$4:$AB$6723=$C9)*($AC$4:$AC$6723=$D9)*(ISNUMBER(_xlfn.XMATCH($AD$4:$AD$6723,$V9:$Z9,0)))),-1)} -> -1 | L9: {=IFERROR(_xlfn._xlws.FILTER(AG$4:AG$6723,(AG$4:AG$6723>=0)*($AB$4:$AB$6723=$C9)*($AC$4:$AC$6723=$D9)*(ISNUMBER(_xlfn.XMATCH($AD$4:$AD$6723,$V9:$Z9,0)))),-1)} -> -1 | M9: {=IFERROR(_xlfn._xlws.FILTER(AH$4:AH$6723,(AH$4:AH$6723>=0)*($AB$4:$AB$6723=$C9)*($AC$4:$AC$6723=$D9)*(ISNUMBER(_xlfn.XMATCH($AD$4:$AD$6723,$V9:$Z9,0)))),-1)} -> -1 | N9: {=IFERROR(_xlfn._xlws.FILTER(AI$4:AI$6723,(AI$4:AI$6723>=0)*($AB$4:$AB$6723=$C9)*($AC$4:$AC$6723=$D9)*(ISNUMBER(_xlfn.XMATCH($AD$4:$AD$6723,$V9:$Z9,0)))),-1)} -> -1 | O9: {=IFERROR(_xlfn._xlws.FILTER(AJ$4:AJ$6723,(AJ$4:AJ$6723>=0)*($AB$4:$AB$6723=$C9)*($AC$4:$AC$6723=$D9)*(ISNUMBER(_xlfn.XMATCH($AD$4:$AD$6723,$V9:$Z9,0)))),-1)} -> -1 | P9: {=IFERROR(_xlfn._xlws.FILTER(AK$4:AK$6723,(AK$4:AK$6723>=0)*($AB$4:$AB$6723=$C9)*($AC$4:$AC$6723=$D9)*(ISNUMBER(_xlfn.XMATCH($AD$4:$AD$6723,$V9:$Z9,0)))),-1)} -> -1 | Q9: {=IFERROR(_xlfn._xlws.FILTER(AL$4:AL$6723,(AL$4:AL$6723>=0)*($AB$4:$AB$6723=$C9)*($AC$4:$AC$6723=$D9)*(ISNUMBER(_xlfn.XMATCH($AD$4:$AD$6723,$V9:$Z9,0)))),-1)} -> -1 | ... T9: {=IFERROR(_xlfn._xlws.FILTER(AO$4:AO$6723,(AO$4:AO$6723>=0)*($AB$4:$AB$6723=$C9)*($AC$4:$AC$6723=$D9)*(ISNUMBER(_xlfn.XMATCH($AD$4:$AD$6723,$V9:$Z9,0)))),-1)} -> -1 | V9: Coal Bituminous Appalachian | W9: Coal Bituminous Eastern | X9: Coal Lignite Western | Y9: Coal Sub Bituminous Western | Z9: Metallurgical Coal | AB9: AB | AC9: Agriculture | AD9: Byproduct gas | AE9: -1 | AF9: -1 | AG9: -1 | AH9: -1 | AI9: -1 | AJ9: -1 | AK9: -1 | AL9: -1 | AM9: -1 | AN9: -1 | AO9: -1
C10: AB | D10: Agriculture | E10: Coke | F10: 2005 | G10: CAD | H10: GJ | J10: {=IFERROR(_xlfn._xlws.FILTER(AE$4:AE$6723,(AE$4:AE$6723>=0)*($AB$4:$AB$6723=$C10)*($AC$4:$AC$6723=$D10)*(ISNUMBER(_xlfn.XMATCH($AD$4:$AD$6723,$V10:$Z10,0)))),-1)} -> -1 | K10: {=IFERROR(_xlfn._xlws.FILTER(AF$4:AF$6723,(AF$4:AF$6723>=0)*($AB$4:$AB$6723=$C10)*($AC$4:$AC$6723=$D10)*(ISNUMBER(_xlfn.XMATCH($AD$4:$AD$6723,$V10:$Z10,0)))),-1)} -> -1 | L10: {=IFERROR(_xlfn._xlws.FILTER(AG$4:AG$6723,(AG$4:AG$6723>=0)*($AB$4:$AB$6723=$C10)*($AC$4:$AC$6723=$D10)*(ISNUMBER(_xlfn.XMATCH($AD$4:$AD$6723,$V10:$Z10,0)))),-1)} -> -1 | M10: {=IFERROR(_xlfn._xlws.FILTER(AH$4:AH$6723,(AH$4:AH$6723>=0)*($AB$4:$AB$6723=$C10)*($AC$4:$AC$6723=$D10)*(ISNUMBER(_xlfn.XMATCH($AD$4:$AD$6723,$V10:$Z10,0)))),-1)} -> -1 | N10: {=IFERROR(_xlfn._xlws.FILTER(AI$4:AI$6723,(AI$4:AI$6723>=0)*($AB$4:$AB$6723=$C10)*($AC$4:$AC$6723=$D10)*(ISNUMBER(_xlfn.XMATCH($AD$4:$AD$6723,$V10:$Z10,0)))),-1)} -> -1 | O10: {=IFERROR(_xlfn._xlws.FILTER(AJ$4:AJ$6723,(AJ$4:AJ$6723>=0)*($AB$4:$AB$6723=$C10)*($AC$4:$AC$6723=$D10)*(ISNUMBER(_xlfn.XMATCH($AD$4:$AD$6723,$V10:$Z10,0)))),-1)} -> -1 | P10: {=IFERROR(_xlfn._xlws.FILTER(AK$4:AK$6723,(AK$4:AK$6723>=0)*($AB$4:$AB$6723=$C10)*($AC$4:$AC$6723=$D10)*(ISNUMBER(_xlfn.XMATCH($AD$4:$AD$6723,$V10:$Z10,0)))),-1)} -> -1 | Q10: {=IFERROR(_xlfn._xlws.FILTER(AL$4:AL$6723,(AL$4:AL$6723>=0)*($AB$4:$AB$6723=$C10)*($AC$4:$AC$6723=$D10)*(ISNUMBER(_xlfn.XMATCH($AD$4:$AD$6723,$V10:$Z10,0)))),-1)} -> -1 | ... T10: {=IFERROR(_xlfn._xlws.FILTER(AO$4:AO$6723,(AO$4:AO$6723>=0)*($AB$4:$AB$6723=$C10)*($AC$4:$AC$6723=$D10)*(ISNUMBER(_xlfn.XMATCH($AD$4:$AD$6723,$V10:$Z10,0)))),-1)} -> -1 | V10: Metallurgical Coal | AB10: AB | AC10: Agriculture | AD10: Coal Bituminous Appalachian | AE10: -1 | AF10: -1 | AG10: -1 | AH10: -1 | AI10: -1 | AJ10: -1 | AK10: -1 | AL10: -1 | AM10: -1 | AN10: -1 | AO10: -1
C11: AB | D11: Agriculture | E11: Diesel | F11: 2005 | G11: CAD | H11: GJ | J11: {=IFERROR(_xlfn._xlws.FILTER(AE$4:AE$6723,(AE$4:AE$6723>=0)*($AB$4:$AB$6723=$C11)*($AC$4:$AC$6723=$D11)*(ISNUMBER(_xlfn.XMATCH($AD$4:$AD$6723,$V11:$Z11,0)))),-1)} -> 17.87105 | K11: {=IFERROR(_xlfn._xlws.FILTER(AF$4:AF$6723,(AF$4:AF$6723>=0)*($AB$4:$AB$6723=$C11)*($AC$4:$AC$6723=$D11)*(ISNUMBER(_xlfn.XMATCH($AD$4:$AD$6723,$V11:$Z11,0)))),-1)} -> 22.125927 | L11: {=IFERROR(_xlfn._xlws.FILTER(AG$4:AG$6723,(AG$4:AG$6723>=0)*($AB$4:$AB$6723=$C11)*($AC$4:$AC$6723=$D11)*(ISNUMBER(_xlfn.XMATCH($AD$4:$AD$6723,$V11:$Z11,0)))),-1)} -> 32.128058 | M11: {=IFERROR(_xlfn._xlws.FILTER(AH$4:AH$6723,(AH$4:AH$6723>=0)*($AB$4:$AB$6723=$C11)*($AC$4:$AC$6723=$D11)*(ISNUMBER(_xlfn.XMATCH($AD$4:$AD$6723,$V11:$Z11,0)))),-1)} -> 33.509307 | N11: {=IFERROR(_xlfn._xlws.FILTER(AI$4:AI$6723,(AI$4:AI$6723>=0)*($AB$4:$AB$6723=$C11)*($AC$4:$AC$6723=$D11)*(ISNUMBER(_xlfn.XMATCH($AD$4:$AD$6723,$V11:$Z11,0)))),-1)} -> 39.872491 | O11: {=IFERROR(_xlfn._xlws.FILTER(AJ$4:AJ$6723,(AJ$4:AJ$6723>=0)*($AB$4:$AB$6723=$C11)*($AC$4:$AC$6723=$D11)*(ISNUMBER(_xlfn.XMATCH($AD$4:$AD$6723,$V11:$Z11,0)))),-1)} -> 42.553319 | P11: {=IFERROR(_xlfn._xlws.FILTER(AK$4:AK$6723,(AK$4:AK$6723>=0)*($AB$4:$AB$6723=$C11)*($AC$4:$AC$6723=$D11)*(ISNUMBER(_xlfn.XMATCH($AD$4:$AD$6723,$V11:$Z11,0)))),-1)} -> 44.364077 | Q11: {=IFERROR(_xlfn._xlws.FILTER(AL$4:AL$6723,(AL$4:AL$6723>=0)*($AB$4:$AB$6723=$C11)*($AC$4:$AC$6723=$D11)*(ISNUMBER(_xlfn.XMATCH($AD$4:$AD$6723,$V11:$Z11,0)))),-1)} -> 45.307288 | ... T11: {=IFERROR(_xlfn._xlws.FILTER(AO$4:AO$6723,(AO$4:AO$6723>=0)*($AB$4:$AB$6723=$C11)*($AC$4:$AC$6723=$D11)*(ISNUMBER(_xlfn.XMATCH($AD$4:$AD$6723,$V11:$Z11,0)))),-1)} -> 46.570622 | V11: Diesel Road | W11: Diesel Marine | X11: Diesel Rail | Y11: Diesel Offroad | AB11: AB | AC11: Agriculture | AD11: Coal Bituminous Eastern | AE11: -1 | AF11: -1 | AG11: -1 | AH11: -1 | AI11: -1 | AJ11: -1 | AK11: -1 | AL11: -1 | AM11: -1 | AN11: -1 | AO11: -1
