Workbook
Name long_month: 31
Name short_month: 30

Sheet Source
A1: Forecasted values are no longer available in this publication.
A2: For the latest projections of crude oil and natural gas production in Canada please visit the Canada’s Energy Future main page.
A4: Data Sources / Sources de données
A6: BC | B6: https://www2.gov.bc.ca/gov/content/industry/natural-gas-oil/statistics
A7: AB | B7: https://www.aer.ca/providing-information/data-and-reports/statistical-reports/st3
A8: SK | B8: https://dashboard.saskatchewan.ca/business-economy/business-industry-trade/oil-production#by-type-tab
A9: MB | B9: https://www.manitoba.ca/iem/petroleum/reports/index.html
A10: NWT | B10: https://www.statsnwt.ca/economy/oil-gas/
A11: ON | B11: https://www150.statcan.gc.ca/t1/tbl1/en/tv.action?pid=2510006301
A12: NS | B12: https://www.cnsopb.ns.ca/offshore-activity//legacy-production-projects/cohasset-panuke
A13: NB | B13: https://www2.gnb.ca/content/dam/gnb/Departments/en/pdf/Minerals-Minerales/Monthly_Statistics.pdf
A14: NL | B14: https://www.cnlopb.ca/information/statistics/
A16: Calculations
A18: BC | B18: Light Crude Oil: B.C. Oil Production Report file
B19: Condensate: Pentanes Plus from B.C. By-Products Production file + Wellhead Condensate from B.C. Oil Production Report file
A20: AB | B20: Light Crude Oil: Crude Oil Light + Crude Oil Medium from Oil Supply and Disposition file
B21: Heavy Crude Oil: Crude Oil Heavy + Crude Oil Ultra-Heavy from Oil Supply and Disposition file
B22: AB Upgraded Bitumen: Upgraded Production from Oil Supply and Disposition file
B23: AB Non-Upgraded Bitumen: Nonupgraded Total from Oil Supply and Disposition file
B24: Condensate: Condensate Production + Pentanes Plus - Plant/Gathering Process + Pentanes Plus - Fractionation Yield from Oil Supply and Disposition file
A25: SK | B25: Light Crude Oil: Light from Saskatchewan Oil Production by Type table
B26: Heavy Crude Oil: Medium + Heavy from Saskatchewan Oil Production by Type table
A27: MB | B27: Light Crude Oil: Oil Fluid Type from MS Excel file
A28: NWT | B28: Light Crude Oil: Total Oil Production from Crude Oil table
A29: ON | B29: Light Crude Oil: Ontario Crude Oil Production from Statistics Canada. Table 25-10-0063-01 Supply and disposition of crude oil and equivalent
A30: NS | B30: Currently no production from province
A31: NB | B31: Light Crude Oil: Crude Oil from table
A32: NL | B32: Light Crude Oil: Monthly Production Summary from the Hibernia, North Amethyst, Terra Nova and, White Rose fields in Resource Management tab
B33: Heavy Crude Oil: Monthly Production Summary from the Hebron field in Resource Management tab
A35: Les valeurs prévues ne sont plus disponibles dans cette publication.
A36: Pour connaître les dernières projections relatives à la production de pétrole brut et de gaz naturel au Canada, consultez la page principale d’Avenir énergétique du Canada.
A38: Calculs
A40: BC | B40: Pétrole brut léger : Fichier du rapport sur la production en Colombie-Britannique
B41: Condensats : Pentanes plus tirés du dossier sur la production de sous-produits en Colombie‑Britannique + condensats à la tête de puits tirés du dossier du rapport sur la production de pétrole en Colombie-Britannique
A42: AB | B42: Pétrole brut léger : pétrole brut léger + pétrole brut moyen tirés du fichier sur l’approvisionnement et l’utilisation du pétrole
B43: Pétrole brut lourd : Pétrole brut lourd + pétrole brut ultra lourd tirés du fichier sur l’approvisionnement et l’utilisation du pétrole
B44: Bitume valorisé en Alberta : Production valorisée tirée du fichier sur l’approvisionnement et l’utilisation du pétrole
B45: Bitume non valorisé en Alberta : Total non valorisé tiré du fichier sur l’approvisionnement et l’utilisation du pétrole
B46: Condensats : Production de condensats + Pentanes plus - Procédé d’usine/de collecte + Pentanes plus - Rendement du fractionnement tirés du fichier sur l’approvisionnement et l’utilisation du pétrole
A47: SK | B47: Pétrole brut léger : Tableau de la production de pétrole léger en Saskatchewan selon le type
...

Sheet 24TABLE - cubic meters per day
A2: 45730 | H2: 2024 ESTIMATED PRODUCTION OF CANADIAN CRUDE OIL AND EQUIVALENT (m3/d)
H3: PRODUCTION ESTIMATIVE DE PÉTROLE BRUT ET D'ÉQUIVALENTS AU CANADA EN 2024 (M³/J)
N4: 2024
B5: Jan/janv. | C5: Feb/fév. | D5: Mar/mars | E5: Apr/avr. | F5: May/mai | G5: June/juin | H5: July/juil. | I5: Aug/août | J5: Sep/sept. | K5: Oct/oct. | L5: Nov/nov. | M5: Dec/déc. | N5: Avg/moyenne
A6: CONV. LIGHT CRUDE OIL/
A7: PÉTROLE BRUT LÉGER CLASS.
A8: AB | B8: 57177.612 | C8: 60127.575 | D8: 61958.221 | E8: 62286.785 | F8: 60682.107 | G8: 58429.705 | H8: 58316.344 | I8: 59574.305 | J8: 58857.528 | K8: 61811.837 | L8: 64273.273 | M8: 64646.05 | N8: 60678.358
A9: BC | B9: 1506 | C9: 1592.1034 | D9: 1491.6452 | E9: 1868.3 | F9: 1571.1935 | G9: 1626.8 | H9: 1470 | I9: 1989.2581 | J9: 2052.0667 | K9: 1905.5484 | L9: 1950.5333 | M9: 1876.5806 | N9: 1741.0355
A10: SK | B10: 23359.977 | C10: 24458.245 | D10: 24994.319 | E10: 24979.143 | F10: 23943.271 | G10: 23043.383 | H10: 22819.258 | I10: 23667.826 | J10: 23938.233 | K10: 24448.426 | L10: 24528.633 | M10: 24198.484 | N10: 24028.277
A11: MB | B11: 5943.1355 | C11: 6061.4655 | D11: 6235.3871 | E11: 6104.1567 | F11: 5856.3645 | G11: 5799.4733 | H11: 5867.0742 | I11: 5861.7097 | J11: 5776.43 | K11: 5680.4806 | L11: 5530.85 | N11: 5883.2194
A12: NWT/NT | B12: 608.79677 | C12: 575.08621 | D12: 645.47419 | E12: 634.75333 | F12: 655.27419 | G12: 624.92333 | H12: 556.35161 | I12: 621.99677 | J12: 621.32 | K12: 602.93548 | L12: 596.03667 | M12: 586.17419 | N12: 610.8623
A13: NF/NL | B13: 10959.484 | C13: 15775.966 | D13: 12430.645 | E13: 18389.233 | F13: 15175.968 | G13: 12979.1 | H13: 16268.903 | I13: 17754.129 | J13: 14776.633 | K13: 12177.387 | L13: 13877 | M13: 19247.419 | N13: 14979.765
A14: NB | B14: 4.4741935 | C14: 4.0103448 | D14: 3.5387097 | E14: 4.5933333 | F14: 3.2322581 | G14: 2.1833333 | H14: 3.2354839 | I14: 2.1451613 | N14: 3.4221311
A15: ON | B15: 76.290323 | C15: 80.37931 | D15: 82.774194 | E15: 81.9 | F15: 80.483871 | G15: 79.333333 | H15: 78.580645 | I15: 79.419355 | J15: 78.666667 | K15: 80.290323 | N15: 79.806557
A16: SUB TOTAL/SOUS-TOTAL | B16: =SUM(B8:B15) | C16: =SUM(C8:C15) | D16: =SUM(D8:D15) | E16: =SUM(E8:E15) | F16: =SUM(F8:F15) | G16: =SUM(G8:G15) | H16: =SUM(H8:H15) | I16: =SUM(I8:I15) | ... M16: =SUM(M8:M15) | N16: 106859.63
A17: AB UPGRADED BITUMEN/ BITUME VALORISÉ-AB1
A18: SUB TOTAL/SOUS-TOTAL | B18: 202817.1 | C18: 205905.09 | D18: 205836.87 | E18: 195371.45 | F18: 162612.32 | G18: 188903.42 | H18: 210898.03 | I18: 218775.35 | J18: 191671.4 | K18: 198899.56 | L18: 217903.52 | M18: 225978.81 | N18: 202150.55
A19: C5+ / CONDENSATE/C5+/CONDENSATS
A20: AB | B20: 59736.096 | C20: 60404.315 | D20: 60234.456 | E20: 61274.908 | F20: 57953.003 | G20: 60541.387 | H20: 60809.608 | I20: 65093.038 | J20: 60077.398 | K20: 66868.183 | L20: 68928.4 | M20: 67432.699 | N20: 62454.447
A21: BC | B21: 19509.535 | C21: 19556.71 | D21: 19843.152 | E21: 20041.203 | F21: 19337.142 | G21: 19943.903 | H21: 18854.603 | I21: 20545.074 | J21: 20639.817 | K21: 20045.671 | L21: 21518.55 | M21: 23949.623 | N21: 20317.152
A22: SK
A23: SUB TOTAL/SOUS-TOTAL | B23: =SUM(B20:B22) | C23: =SUM(C20:C22) | D23: =SUM(D20:D22) | E23: =SUM(E20:E22) | F23: =SUM(F20:F22) | G23: =SUM(G20:G22) | H23: =SUM(H20:H22) | I23: =SUM(I20:I22) | ... M23: =SUM(M20:M22) | N23: 82771.599
A24: TOTAL LIGHT/LÉGER | B24: =SUM(B23,B16,B18) | C24: =SUM(C23,C16,C18) | D24: =SUM(D23,D16,D18) | E24: =SUM(E23,E16,E18) | F24: =SUM(F23,F16,F18) | G24: =SUM(G23,G16,G18) | H24: =SUM(H23,H16,H18) | I24: =SUM(I23,I16,I18) | ... M24: =SUM(M23,M16,M18) | N24: 392414.15
A25: HEAVY CRUDE OIL/ PÉTROLE BRUT LOURD
A26: AB CONV./CLASS.-AB | B26: 23488.826 | C26: 24839.416 | D26: 25007.158 | E26: 24215.353 | F26: 24897.238 | G26: 25589.113 | H26: 25049.774 | I26: 25275.086 | J26: 24818.776 | K26: 24797.644 | L26: 24294.529 | M26: 24035.793 | N26: 24691.184
A27: AB NON-UPGRADED BITUMEN / BITUME NON VALORISÉ-AB2 | B27: 310846.26 | C27: 325799.14 | D27: 337501.03 | E27: 330465.97 | F27: 325103.68 | G27: 332487.87 | H27: 329266.65 | I27: 324172.74 | J27: 316994.9 | K27: 357247.26 | L27: 344809.57 | M27: 347134.35 | N27: 331858.89
A28: AB SUB TOTAL/SOUS-TOTAL -AB | B28: =SUM(B26:B27) | C28: =SUM(C26:C27) | D28: =SUM(D26:D27) | E28: =SUM(E26:E27) | F28: =SUM(F26:F27) | G28: =SUM(G26:G27) | H28: =SUM(H26:H27) | I28: =SUM(I26:I27) | ... M28: =SUM(M26:M27) | N28: 356550.08
A29: SK CONV./CLASS.-SK | B29: 47401.194 | C29: 48200.848 | D29: 48117.781 | E29: 48371.07 | F29: 48227.816 | G29: 47015.133 | H29: 46681.668 | I29: 47274.723 | J29: 45197.773 | K29: 46982.313 | L29: 46869.483 | M29: 47057.352 | N29: 47282.668
A30: NL CONV | B30: 19261.903 | C30: 17954.448 | D30: 17831.839 | E30: 16570.733 | F30: 17052.581 | G30: 17007.933 | H30: 17877.548 | I30: 18517.71 | J30: 19963.267 | K30: 19072.258 | L30: 18423.067 | M30: 19200.194 | N30: 18231.869
A31: TOTAL HEAVY/LOURD3 | B31: =SUM(B28:B30) | C31: =SUM(C28:C30) | D31: =SUM(D28:D30) | E31: =SUM(E28:E30) | F31: =SUM(F28:F30) | G31: =SUM(G28:G30) | H31: =SUM(H28:H30) | I31: =SUM(I28:I30) | ... M31: =SUM(M28:M30) | N31: 422064.61
A32: TOTAL PRODUCTION | B32: =SUM(B31,B24) | C32: =SUM(C31,C24) | D32: =SUM(D31,D24) | E32: =SUM(E31,E24) | F32: =SUM(F31,F24) | G32: =SUM(G31,G24) | H32: =SUM(H31,H24) | I32: =SUM(I31,I24) | ... M32: =SUM(M31,M24) | N32: 814478.76
H35: ESTIMATED PRODUCTION BY REGION
A36: WESTERN CANADA/OUEST CANADIEN
A37: CONV. LIGHT/LÉGER CLASS. | B37: 88595.522 | C37: 92814.475 | D37: 95325.047 | E37: 95873.139 | F37: 92708.21 | G37: 89524.285 | H37: 89029.028 | I37: 91715.096 | J37: 91245.578 | K37: 94449.227 | L37: 96879.326 | M37: 91307.289 | N37: 92443.447
A38: AB UPGRADED BITUMEN/ BITUME VALORISÉ-AB 1 | B38: 202817.1 | C38: 205905.09 | D38: 205836.87 | E38: 195371.45 | F38: 162612.32 | G38: 188903.42 | H38: 210898.03 | I38: 218775.35 | J38: 191671.4 | K38: 198899.56 | L38: 217903.52 | M38: 225978.81 | N38: 202150.55
A39: PENTANES PLUS | B39: 79245.631 | C39: 79961.025 | D39: 80077.607 | E39: 81316.112 | F39: 77290.145 | G39: 80485.291 | H39: 79664.211 | I39: 85638.113 | J39: 80717.215 | K39: 86913.854 | L39: 90446.95 | M39: 91382.321 | N39: 82771.599
A40: TOTAL LIGHT/LÉGER | B40: =SUM(B37:B39) | C40: =SUM(C37:C39) | D40: =SUM(D37:D39) | E40: =SUM(E37:E39) | F40: =SUM(F37:F39) | G40: =SUM(G37:G39) | H40: =SUM(H37:H39) | I40: =SUM(I37:I39) | ... M40: =SUM(M37:M39) | N40: 377365.59
A41: CONV. HEAVY/LOURD CLASS. | B41: 70890.019 | C41: 73040.265 | D41: 73124.939 | E41: 72586.423 | F41: 73125.054 | G41: 72604.246 | H41: 71731.442 | I41: 72549.809 | J41: 70016.549 | K41: 71779.957 | L41: 71164.012 | M41: 71093.144 | N41: 71973.852
A42: AB NON-UPGRADED BITUMEN / BITUME NON VALORISÉ-AB2 | B42: =B27 | C42: =C27 | D42: =D27 | E42: =E27 | F42: =F27 | G42: =G27 | H42: =H27 | I42: =I27 | ... M42: =M27 | N42: 331858.89
A43: TOTAL HEAVY/LOURD | B43: =SUM(B41:B42) | C43: =SUM(C41:C42) | D43: =SUM(D41:D42) | E43: =SUM(E41:E42) | F43: =SUM(F41:F42) | G43: =SUM(G41:G42) | H43: =SUM(H41:H42) | I43: =SUM(I41:I42) | ... M43: =SUM(M41:M42) | N43: 403832.75
...

Sheet 24TABLE - barrels per day
A2: ='24TABLE - cubic meters per day'!A2 | H2: 2024 ESTIMATED PRODUCTION OF CANADIAN CRUDE OIL AND EQUIVALENT (b/d)
H3: PRODUCTION ESTIMATIVE DE PÉTROLE BRUT ET D'ÉQUIVALENTS AU CANADA EN 2024 (b/j)
N4: ='24TABLE - cubic meters per day'!N4
B5: Jan/janv. | C5: Feb/fév. | D5: Mar/mars | E5: Apr/avr. | F5: May/mai | G5: June/juin | H5: July/juil. | I5: Aug/août | J5: Sep/sept. | K5: Oct/oct. | L5: Nov/nov. | M5: Dec/déc. | N5: Avg/moyenne
A6: CONV. LIGHT CRUDE OIL/
A7: PÉTROLE BRUT LÉGER CLASS.
A8: AB | B8: ='24TABLE - cubic meters per day'!B8*6.2898 | C8: ='24TABLE - cubic meters per day'!C8*6.2898 | D8: ='24TABLE - cubic meters per day'!D8*6.2898 | E8: ='24TABLE - cubic meters per day'!E8*6.2898 | F8: ='24TABLE - cubic meters per day'!F8*6.2898 | G8: ='24TABLE - cubic meters per day'!G8*6.2898 | H8: ='24TABLE - cubic meters per day'!H8*6.2898 | I8: ='24TABLE - cubic meters per day'!I8*6.2898 | ... N8: ='24TABLE - cubic meters per day'!N8*6.2898
A9: BC | B9: ='24TABLE - cubic meters per day'!B9*6.2898 | C9: ='24TABLE - cubic meters per day'!C9*6.2898 | D9: ='24TABLE - cubic meters per day'!D9*6.2898 | E9: ='24TABLE - cubic meters per day'!E9*6.2898 | F9: ='24TABLE - cubic meters per day'!F9*6.2898 | G9: ='24TABLE - cubic meters per day'!G9*6.2898 | H9: ='24TABLE - cubic meters per day'!H9*6.2898 | I9: ='24TABLE - cubic meters per day'!I9*6.2898 | ... N9: ='24TABLE - cubic meters per day'!N9*6.2898
A10: SK | B10: ='24TABLE - cubic meters per day'!B10*6.2898 | C10: ='24TABLE - cubic meters per day'!C10*6.2898 | D10: ='24TABLE - cubic meters per day'!D10*6.2898 | E10: ='24TABLE - cubic meters per day'!E10*6.2898 | F10: ='24TABLE - cubic meters per day'!F10*6.2898 | G10: ='24TABLE - cubic meters per day'!G10*6.2898 | H10: ='24TABLE - cubic meters per day'!H10*6.2898 | I10: ='24TABLE - cubic meters per day'!I10*6.2898 | ... N10: ='24TABLE - cubic meters per day'!N10*6.2898
A11: MB | B11: ='24TABLE - cubic meters per day'!B11*6.2898 | C11: ='24TABLE - cubic meters per day'!C11*6.2898 | D11: ='24TABLE - cubic meters per day'!D11*6.2898 | E11: ='24TABLE - cubic meters per day'!E11*6.2898 | F11: ='24TABLE - cubic meters per day'!F11*6.2898 | G11: ='24TABLE - cubic meters per day'!G11*6.2898 | H11: ='24TABLE - cubic meters per day'!H11*6.2898 | I11: ='24TABLE - cubic meters per day'!I11*6.2898 | ... N11: ='24TABLE - cubic meters per day'!N11*6.2898
A12: NWT/NT | B12: ='24TABLE - cubic meters per day'!B12*6.2898 | C12: ='24TABLE - cubic meters per day'!C12*6.2898 | D12: ='24TABLE - cubic meters per day'!D12*6.2898 | E12: ='24TABLE - cubic meters per day'!E12*6.2898 | F12: ='24TABLE - cubic meters per day'!F12*6.2898 | G12: ='24TABLE - cubic meters per day'!G12*6.2898 | H12: ='24TABLE - cubic meters per day'!H12*6.2898 | I12: ='24TABLE - cubic meters per day'!I12*6.2898 | ... N12: ='24TABLE - cubic meters per day'!N12*6.2898
A13: NF/NL | B13: ='24TABLE - cubic meters per day'!B13*6.2898 | C13: ='24TABLE - cubic meters per day'!C13*6.2898 | D13: ='24TABLE - cubic meters per day'!D13*6.2898 | E13: ='24TABLE - cubic meters per day'!E13*6.2898 | F13: ='24TABLE - cubic meters per day'!F13*6.2898 | G13: ='24TABLE - cubic meters per day'!G13*6.2898 | H13: ='24TABLE - cubic meters per day'!H13*6.2898 | I13: ='24TABLE - cubic meters per day'!I13*6.2898 | ... N13: ='24TABLE - cubic meters per day'!N13*6.2898
A14: NB | B14: ='24TABLE - cubic meters per day'!B14*6.2898 | C14: ='24TABLE - cubic meters per day'!C14*6.2898 | D14: ='24TABLE - cubic meters per day'!D14*6.2898 | E14: ='24TABLE - cubic meters per day'!E14*6.2898 | F14: ='24TABLE - cubic meters per day'!F14*6.2898 | G14: ='24TABLE - cubic meters per day'!G14*6.2898 | H14: ='24TABLE - cubic meters per day'!H14*6.2898 | I14: ='24TABLE - cubic meters per day'!I14*6.2898 | ... M14: ='24TABLE - cubic meters per day'!M14*6.2898
A15: ON | B15: ='24TABLE - cubic meters per day'!B15*6.2898 | C15: ='24TABLE - cubic meters per day'!C15*6.2898 | D15: ='24TABLE - cubic meters per day'!D15*6.2898 | E15: ='24TABLE - cubic meters per day'!E15*6.2898 | F15: ='24TABLE - cubic meters per day'!F15*6.2898 | G15: ='24TABLE - cubic meters per day'!G15*6.2898 | H15: ='24TABLE - cubic meters per day'!H15*6.2898 | I15: ='24TABLE - cubic meters per day'!I15*6.2898 | ... M15: ='24TABLE - cubic meters per day'!M15*6.2898
A16: SUB TOTAL/SOUS-TOTAL | B16: ='24TABLE - cubic meters per day'!B16*6.2898 | C16: ='24TABLE - cubic meters per day'!C16*6.2898 | D16: ='24TABLE - cubic meters per day'!D16*6.2898 | E16: ='24TABLE - cubic meters per day'!E16*6.2898 | F16: ='24TABLE - cubic meters per day'!F16*6.2898 | G16: ='24TABLE - cubic meters per day'!G16*6.2898 | H16: ='24TABLE - cubic meters per day'!H16*6.2898 | I16: ='24TABLE - cubic meters per day'!I16*6.2898 | ... N16: ='24TABLE - cubic meters per day'!N16*6.2898
A17: AB UPGRADED BITUMEN/ BITUME VALORISÉ-AB1
A18: SUB TOTAL/SOUS-TOTAL | B18: ='24TABLE - cubic meters per day'!B18*6.2898 | C18: ='24TABLE - cubic meters per day'!C18*6.2898 | D18: ='24TABLE - cubic meters per day'!D18*6.2898 | E18: ='24TABLE - cubic meters per day'!E18*6.2898 | F18: ='24TABLE - cubic meters per day'!F18*6.2898 | G18: ='24TABLE - cubic meters per day'!G18*6.2898 | H18: ='24TABLE - cubic meters per day'!H18*6.2898 | I18: ='24TABLE - cubic meters per day'!I18*6.2898 | ... N18: ='24TABLE - cubic meters per day'!N18*6.2898
A19: C5+ / CONDENSATE/C5+/CONDENSATS
A20: AB | B20: ='24TABLE - cubic meters per day'!B20*6.2898 | C20: ='24TABLE - cubic meters per day'!C20*6.2898 | D20: ='24TABLE - cubic meters per day'!D20*6.2898 | E20: ='24TABLE - cubic meters per day'!E20*6.2898 | F20: ='24TABLE - cubic meters per day'!F20*6.2898 | G20: ='24TABLE - cubic meters per day'!G20*6.2898 | H20: ='24TABLE - cubic meters per day'!H20*6.2898 | I20: ='24TABLE - cubic meters per day'!I20*6.2898 | ... N20: ='24TABLE - cubic meters per day'!N20*6.2898
A21: BC | B21: ='24TABLE - cubic meters per day'!B21*6.2898 | C21: ='24TABLE - cubic meters per day'!C21*6.2898 | D21: ='24TABLE - cubic meters per day'!D21*6.2898 | E21: ='24TABLE - cubic meters per day'!E21*6.2898 | F21: ='24TABLE - cubic meters per day'!F21*6.2898 | G21: ='24TABLE - cubic meters per day'!G21*6.2898 | H21: ='24TABLE - cubic meters per day'!H21*6.2898 | I21: ='24TABLE - cubic meters per day'!I21*6.2898 | ... N21: ='24TABLE - cubic meters per day'!N21*6.2898
A22: SK2
A23: SUB TOTAL/SOUS-TOTAL | B23: ='24TABLE - cubic meters per day'!B23*6.2898 | C23: ='24TABLE - cubic meters per day'!C23*6.2898 | D23: ='24TABLE - cubic meters per day'!D23*6.2898 | E23: ='24TABLE - cubic meters per day'!E23*6.2898 | F23: ='24TABLE - cubic meters per day'!F23*6.2898 | G23: ='24TABLE - cubic meters per day'!G23*6.2898 | H23: ='24TABLE - cubic meters per day'!H23*6.2898 | I23: ='24TABLE - cubic meters per day'!I23*6.2898 | ... N23: ='24TABLE - cubic meters per day'!N23*6.2898
A24: TOTAL LIGHT/LÉGER | B24: ='24TABLE - cubic meters per day'!B24*6.2898 | C24: ='24TABLE - cubic meters per day'!C24*6.2898 | D24: ='24TABLE - cubic meters per day'!D24*6.2898 | E24: ='24TABLE - cubic meters per day'!E24*6.2898 | F24: ='24TABLE - cubic meters per day'!F24*6.2898 | G24: ='24TABLE - cubic meters per day'!G24*6.2898 | H24: ='24TABLE - cubic meters per day'!H24*6.2898 | I24: ='24TABLE - cubic meters per day'!I24*6.2898 | ... N24: ='24TABLE - cubic meters per day'!N24*6.2898
A25: HEAVY CRUDE OIL/ PÉTROLE BRUT LOURD
A26: AB CONV./CLASS.-AB | B26: ='24TABLE - cubic meters per day'!B26*6.2898 | C26: ='24TABLE - cubic meters per day'!C26*6.2898 | D26: ='24TABLE - cubic meters per day'!D26*6.2898 | E26: ='24TABLE - cubic meters per day'!E26*6.2898 | F26: ='24TABLE - cubic meters per day'!F26*6.2898 | G26: ='24TABLE - cubic meters per day'!G26*6.2898 | H26: ='24TABLE - cubic meters per day'!H26*6.2898 | I26: ='24TABLE - cubic meters per day'!I26*6.2898 | ... N26: ='24TABLE - cubic meters per day'!N26*6.2898
A27: AB NON-UPGRADED BITUMEN / BITUME NON VALORISÉ-AB2 | B27: ='24TABLE - cubic meters per day'!B27*6.2898 | C27: ='24TABLE - cubic meters per day'!C27*6.2898 | D27: ='24TABLE - cubic meters per day'!D27*6.2898 | E27: ='24TABLE - cubic meters per day'!E27*6.2898 | F27: ='24TABLE - cubic meters per day'!F27*6.2898 | G27: ='24TABLE - cubic meters per day'!G27*6.2898 | H27: ='24TABLE - cubic meters per day'!H27*6.2898 | I27: ='24TABLE - cubic meters per day'!I27*6.2898 | ... N27: ='24TABLE - cubic meters per day'!N27*6.2898
A28: AB SUB TOTAL/SOUS-TOTAL -AB | B28: ='24TABLE - cubic meters per day'!B28*6.2898 | C28: ='24TABLE - cubic meters per day'!C28*6.2898 | D28: ='24TABLE - cubic meters per day'!D28*6.2898 | E28: ='24TABLE - cubic meters per day'!E28*6.2898 | F28: ='24TABLE - cubic meters per day'!F28*6.2898 | G28: ='24TABLE - cubic meters per day'!G28*6.2898 | H28: ='24TABLE - cubic meters per day'!H28*6.2898 | I28: ='24TABLE - cubic meters per day'!I28*6.2898 | ... N28: ='24TABLE - cubic meters per day'!N28*6.2898
A29: SK CONV./CLASS.-SK | B29: ='24TABLE - cubic meters per day'!B29*6.2898 | C29: ='24TABLE - cubic meters per day'!C29*6.2898 | D29: ='24TABLE - cubic meters per day'!D29*6.2898 | E29: ='24TABLE - cubic meters per day'!E29*6.2898 | F29: ='24TABLE - cubic meters per day'!F29*6.2898 | G29: ='24TABLE - cubic meters per day'!G29*6.2898 | H29: ='24TABLE - cubic meters per day'!H29*6.2898 | I29: ='24TABLE - cubic meters per day'!I29*6.2898 | ... N29: ='24TABLE - cubic meters per day'!N29*6.2898
A30: NL CONV | B30: ='24TABLE - cubic meters per day'!B30*6.2898 | C30: ='24TABLE - cubic meters per day'!C30*6.2898 | D30: ='24TABLE - cubic meters per day'!D30*6.2898 | E30: ='24TABLE - cubic meters per day'!E30*6.2898 | F30: ='24TABLE - cubic meters per day'!F30*6.2898 | G30: ='24TABLE - cubic meters per day'!G30*6.2898 | H30: ='24TABLE - cubic meters per day'!H30*6.2898 | I30: ='24TABLE - cubic meters per day'!I30*6.2898 | ... N30: ='24TABLE - cubic meters per day'!N30*6.2898
A31: TOTAL HEAVY/LOURD3 | B31: ='24TABLE - cubic meters per day'!B31*6.2898 | C31: ='24TABLE - cubic meters per day'!C31*6.2898 | D31: ='24TABLE - cubic meters per day'!D31*6.2898 | E31: ='24TABLE - cubic meters per day'!E31*6.2898 | F31: ='24TABLE - cubic meters per day'!F31*6.2898 | G31: ='24TABLE - cubic meters per day'!G31*6.2898 | H31: ='24TABLE - cubic meters per day'!H31*6.2898 | I31: ='24TABLE - cubic meters per day'!I31*6.2898 | ... N31: ='24TABLE - cubic meters per day'!N31*6.2898
A32: TOTAL PRODUCTION | B32: ='24TABLE - cubic meters per day'!B32*6.2898 | C32: ='24TABLE - cubic meters per day'!C32*6.2898 | D32: ='24TABLE - cubic meters per day'!D32*6.2898 | E32: ='24TABLE - cubic meters per day'!E32*6.2898 | F32: ='24TABLE - cubic meters per day'!F32*6.2898 | G32: ='24TABLE - cubic meters per day'!G32*6.2898 | H32: ='24TABLE - cubic meters per day'!H32*6.2898 | I32: ='24TABLE - cubic meters per day'!I32*6.2898 | ... N32: ='24TABLE - cubic meters per day'!N32*6.2898
H35: ESTIMATED PRODUCTION BY REGION
A36: WESTERN CANADA/OUEST CANADIEN
A37: CONV. LIGHT/LÉGER CLASS. | B37: ='24TABLE - cubic meters per day'!B37*6.2898 | C37: ='24TABLE - cubic meters per day'!C37*6.2898 | D37: ='24TABLE - cubic meters per day'!D37*6.2898 | E37: ='24TABLE - cubic meters per day'!E37*6.2898 | F37: ='24TABLE - cubic meters per day'!F37*6.2898 | G37: ='24TABLE - cubic meters per day'!G37*6.2898 | H37: ='24TABLE - cubic meters per day'!H37*6.2898 | I37: ='24TABLE - cubic meters per day'!I37*6.2898 | ... N37: ='24TABLE - cubic meters per day'!N37*6.2898
A38: AB UPGRADED BITUMEN/ BITUME VALORISÉ-AB 1 | B38: ='24TABLE - cubic meters per day'!B38*6.2898 | C38: ='24TABLE - cubic meters per day'!C38*6.2898 | D38: ='24TABLE - cubic meters per day'!D38*6.2898 | E38: ='24TABLE - cubic meters per day'!E38*6.2898 | F38: ='24TABLE - cubic meters per day'!F38*6.2898 | G38: ='24TABLE - cubic meters per day'!G38*6.2898 | H38: ='24TABLE - cubic meters per day'!H38*6.2898 | I38: ='24TABLE - cubic meters per day'!I38*6.2898 | ... N38: ='24TABLE - cubic meters per day'!N38*6.2898
A39: PENTANES PLUS | B39: ='24TABLE - cubic meters per day'!B39*6.2898 | C39: ='24TABLE - cubic meters per day'!C39*6.2898 | D39: ='24TABLE - cubic meters per day'!D39*6.2898 | E39: ='24TABLE - cubic meters per day'!E39*6.2898 | F39: ='24TABLE - cubic meters per day'!F39*6.2898 | G39: ='24TABLE - cubic meters per day'!G39*6.2898 | H39: ='24TABLE - cubic meters per day'!H39*6.2898 | I39: ='24TABLE - cubic meters per day'!I39*6.2898 | ... N39: ='24TABLE - cubic meters per day'!N39*6.2898
A40: TOTAL LIGHT/LÉGER | B40: ='24TABLE - cubic meters per day'!B40*6.2898 | C40: ='24TABLE - cubic meters per day'!C40*6.2898 | D40: ='24TABLE - cubic meters per day'!D40*6.2898 | E40: ='24TABLE - cubic meters per day'!E40*6.2898 | F40: ='24TABLE - cubic meters per day'!F40*6.2898 | G40: ='24TABLE - cubic meters per day'!G40*6.2898 | H40: ='24TABLE - cubic meters per day'!H40*6.2898 | I40: ='24TABLE - cubic meters per day'!I40*6.2898 | ... N40: ='24TABLE - cubic meters per day'!N40*6.2898
A41: CONV. HEAVY/LOURD CLASS. | B41: ='24TABLE - cubic meters per day'!B41*6.2898 | C41: ='24TABLE - cubic meters per day'!C41*6.2898 | D41: ='24TABLE - cubic meters per day'!D41*6.2898 | E41: ='24TABLE - cubic meters per day'!E41*6.2898 | F41: ='24TABLE - cubic meters per day'!F41*6.2898 | G41: ='24TABLE - cubic meters per day'!G41*6.2898 | H41: ='24TABLE - cubic meters per day'!H41*6.2898 | I41: ='24TABLE - cubic meters per day'!I41*6.2898 | ... N41: ='24TABLE - cubic meters per day'!N41*6.2898
A42: AB NON-UPGRADED BITUMEN / BITUME NON VALORISÉ-AB2 | B42: ='24TABLE - cubic meters per day'!B42*6.2898 | C42: ='24TABLE - cubic meters per day'!C42*6.2898 | D42: ='24TABLE - cubic meters per day'!D42*6.2898 | E42: ='24TABLE - cubic meters per day'!E42*6.2898 | F42: ='24TABLE - cubic meters per day'!F42*6.2898 | G42: ='24TABLE - cubic meters per day'!G42*6.2898 | H42: ='24TABLE - cubic meters per day'!H42*6.2898 | I42: ='24TABLE - cubic meters per day'!I42*6.2898 | ... N42: ='24TABLE - cubic meters per day'!N42*6.2898
A43: TOTAL HEAVY/LOURD | B43: ='24TABLE - cubic meters per day'!B43*6.2898 | C43: ='24TABLE - cubic meters per day'!C43*6.2898 | D43: ='24TABLE - cubic meters per day'!D43*6.2898 | E43: ='24TABLE - cubic meters per day'!E43*6.2898 | F43: ='24TABLE - cubic meters per day'!F43*6.2898 | G43: ='24TABLE - cubic meters per day'!G43*6.2898 | H43: ='24TABLE - cubic meters per day'!H43*6.2898 | I43: ='24TABLE - cubic meters per day'!I43*6.2898 | ... N43: ='24TABLE - cubic meters per day'!N43*6.2898
...

Sheet 23TABLE - cubic meters per day
A2: 45469 | H2: 2023 ESTIMATED PRODUCTION OF CANADIAN CRUDE OIL AND EQUIVALENT (m3/d)
H3: PRODUCTION ESTIMATIVE DE PÉTROLE BRUT ET D'ÉQUIVALENTS AU CANADA EN 2023 (M³/J)
N4: 2023
B5: Jan/janv. | C5: Feb/fév. | D5: Mar/mars | E5: Apr/avr. | F5: May/mai | G5: June/juin | H5: July/juil. | I5: Aug/août | J5: Sep/sept. | K5: Oct/oct. | L5: Nov/nov. | M5: Dec/déc. | N5: Avg/moyenne
A6: CONV. LIGHT CRUDE OIL/
A7: PÉTROLE BRUT LÉGER CLASS.
A8: AB | B8: 58982.092 | C8: 59389.438 | D8: 60554.264 | E8: 61083.033 | F8: 53046.256 | G8: 55139.798 | H8: 59202.708 | I8: 60868.755 | J8: 60069.149 | K8: 60560.887 | L8: 61650.681 | M8: 62681.757 | N8: 59435.568
A9: BC | B9: 1732.5161 | C9: 1743.9286 | D9: 1720.6452 | E9: 1869.1333 | F9: 1263.6774 | G9: 1406.0333 | H9: 1311.6452 | I9: 1303.4194 | J9: 1085.8 | K9: 1294.0968 | L9: 1358.3667 | M9: 1544.5484 | N9: 1467.663
A10: SK | B10: 24759.548 | C10: 25713.014 | D10: 26031.381 | E10: 25149.823 | F10: 24161.306 | G10: 23561.21 | H10: 24331.487 | I10: 24789.59 | J10: 25464.063 | K10: 25482.719 | L10: 25103.34 | M10: 24963.103 | N10: 24954.55
A11: MB | B11: 6456.9452 | C11: 6219.1857 | D11: 6113.5452 | E11: 5965.5133 | F11: 6415.5065 | G11: 6130.4367 | H11: 6019.7903 | I11: 5834.6194 | J11: 5727.09 | K11: 6122.1968 | L11: 6256.34 | M11: 6225.5613 | N11: 6124.2512
A12: NWT/NT | B12: 674.14194 | C12: 645.41786 | D12: 620.09355 | E12: 669.38333 | F12: 619.93548 | G12: 637.41667 | H12: 658.9 | I12: 644.09677 | J12: 655.49 | K12: 629.68387 | L12: 625.86333 | M12: 614.6129 | N12: 641.15534
A13: NF/NL | B13: 15104.29 | C13: 14169.929 | D13: 11608.355 | E13: 12688.033 | F13: 13449.71 | G13: 12204.5 | H13: 13895.355 | I13: 13565.161 | J13: 13185.433 | K13: 12343.935 | L13: 11779.333 | M13: 13607.871 | N13: 13132.307
A14: NB | B14: 4.0870968 | C14: 3.8678571 | D14: 3.6258065 | E14: 2.3766667 | N14: 3.4891667
A15: ON | B15: 79.225806 | C15: 79.892857 | D15: 80.612903 | E15: 80.5 | F15: 77.16129 | G15: 77.833333 | H15: 78.870968 | I15: 76.645161 | J15: 78 | K15: 79 | L15: 79.7 | M15: 80 | N15: 78.945205
A16: SUB TOTAL/SOUS-TOTAL | B16: =SUM(B8:B15) | C16: =SUM(C8:C15) | D16: =SUM(D8:D15) | E16: =SUM(E8:E15) | F16: =SUM(F8:F15) | G16: =SUM(G8:G15) | H16: =SUM(H8:H15) | I16: =SUM(I8:I15) | ... M16: =SUM(M8:M15) | N16: 105835.59
A17: AB UPGRADED BITUMEN/ BITUME VALORISÉ-AB1
A18: SUB TOTAL/SOUS-TOTAL | B18: 183513.34 | C18: 205299.27 | D18: 205035.39 | E18: 178425.25 | F18: 171156.39 | G18: 182274.85 | H18: 217002.52 | I18: 209244.21 | J18: 171545.67 | K18: 168503.92 | L18: 216377.67 | M18: 223178.6 | N18: 194284.24
A19: C5+ / CONDENSATE/C5+/CONDENSATS
A20: AB | B20: 57699.305 | C20: 57209.846 | D20: 57831.827 | E20: 57261.867 | F20: 49120.447 | G20: 54994.89 | H20: 58509.042 | I20: 60349.606 | J20: 57285.406 | K20: 63343.574 | L20: 64009.809 | M20: 66272.046 | N20: 58672.154
A21: BC | B21: 15354.468 | C21: 14596.793 | D21: 16142.784 | E21: 16644.187 | F21: 14636.094 | G21: 15207.3 | H21: 15426.171 | I21: 17235.303 | J21: 16568.587 | K21: 17964.865 | L21: 19128.483 | M21: 19493.897 | N21: 16545.282
A22: SK | B22: 572.76194 | C22: 572.76179 | D22: 572.76194 | E22: 572.762 | F22: 572.76194 | G22: 572.762 | H22: 572.76194 | I22: 572.76194 | J22: 572.762 | K22: 572.76194 | L22: 572.762 | M22: 572.76194 | N22: 572.76195
A23: SUB TOTAL/SOUS-TOTAL | B23: =SUM(B20:B22) | C23: =SUM(C20:C22) | D23: =SUM(D20:D22) | E23: =SUM(E20:E22) | F23: =SUM(F20:F22) | G23: =SUM(G20:G22) | H23: =SUM(H20:H22) | I23: =SUM(I20:I22) | ... M23: =SUM(M20:M22) | N23: 75790.198
A24: TOTAL LIGHT/LÉGER | B24: =SUM(B23,B16,B18) | C24: =SUM(C23,C16,C18) | D24: =SUM(D23,D16,D18) | E24: =SUM(E23,E16,E18) | F24: =SUM(F23,F16,F18) | G24: =SUM(G23,G16,G18) | H24: =SUM(H23,H16,H18) | I24: =SUM(I23,I16,I18) | ... M24: =SUM(M23,M16,M18) | N24: 375910.02
A25: HEAVY CRUDE OIL/ PÉTROLE BRUT LOURD
A26: AB CONV./CLASS.-AB | B26: 23059.497 | C26: 23695.307 | D26: 23554.688 | E26: 23435.36 | F26: 22853.623 | G26: 22157.177 | H26: 22739.065 | I26: 22607.632 | J26: 22863.11 | K26: 23330.888 | L26: 23480.273 | M26: 23539.106 | N26: 23106.207
A27: AB NON-UPGRADED BITUMEN / BITUME NON VALORISÉ-AB2 | B27: 317371.52 | C27: 311396.54 | D27: 312652.1 | E27: 286798.2 | F27: 286834.32 | G27: 304669.87 | H27: 309469.94 | I27: 312633.42 | J27: 350245.07 | K27: 343120.81 | L27: 347793 | M27: 344686.32 | N27: 318997.56
A28: AB SUB TOTAL/SOUS-TOTAL -AB | B28: =SUM(B26:B27) | C28: =SUM(C26:C27) | D28: =SUM(D26:D27) | E28: =SUM(E26:E27) | F28: =SUM(F26:F27) | G28: =SUM(G26:G27) | H28: =SUM(H26:H27) | I28: =SUM(I26:I27) | ... M28: =SUM(M26:M27) | N28: 342103.76
A29: SK CONV./CLASS.-SK | B29: 46869.497 | C29: 47160.914 | D29: 47108.932 | E29: 47492.067 | F29: 47552.284 | G29: 46999.24 | H29: 47220.016 | I29: 46801.742 | J29: 45634.38 | K29: 46584.7 | L29: 47677.223 | M29: 48599.142 | N29: 47143.613
A30: NL CONV | B30: 22190.645 | C30: 18841.786 | D30: 18777.613 | E30: 21921.8 | F30: 20915.419 | G30: 20297.7 | H30: 19921.806 | I30: 19334.194 | J30: 4875.2 | K30: 18031.871 | L30: 20108.5 | M30: 18968.581 | N30: 18701.397
A31: TOTAL HEAVY/LOURD3 | B31: =SUM(B28:B30) | C31: =SUM(C28:C30) | D31: =SUM(D28:D30) | E31: =SUM(E28:E30) | F31: =SUM(F28:F30) | G31: =SUM(G28:G30) | H31: =SUM(H28:H30) | I31: =SUM(I28:I30) | ... M31: =SUM(M28:M30) | N31: 407948.77
A32: TOTAL PRODUCTION | B32: =SUM(B31,B24) | C32: =SUM(C31,C24) | D32: =SUM(D31,D24) | E32: =SUM(E31,E24) | F32: =SUM(F31,F24) | G32: =SUM(G31,G24) | H32: =SUM(H31,H24) | I32: =SUM(I31,I24) | ... M32: =SUM(M31,M24) | N32: 783858.8
H35: ESTIMATED PRODUCTION BY REGION
A36: WESTERN CANADA/OUEST CANADIEN
A37: CONV. LIGHT/LÉGER CLASS. | B37: =SUM(B8:B12,) | C37: =SUM(C8:C12,) | D37: =SUM(D8:D12,) | E37: =SUM(E8:E12,) | F37: =SUM(F8:F12,) | G37: =SUM(G8:G12,) | H37: =SUM(H8:H12,) | I37: =SUM(I8:I12,) | ... M37: =SUM(M8:M12,) | N37: 92623.265
A38: AB UPGRADED BITUMEN/ BITUME VALORISÉ-AB 1 | B38: =B18 | C38: =C18 | D38: =D18 | E38: =E18 | F38: =F18 | G38: =G18 | H38: =H18 | I38: =I18 | ... M38: =M18 | N38: 194284.24
A39: PENTANES PLUS | B39: =SUM(B20:B22) | C39: =SUM(C20:C22) | D39: =SUM(D20:D22) | E39: =SUM(E20:E22) | F39: =SUM(F20:F22) | G39: =SUM(G20:G22) | H39: =SUM(H20:H22) | I39: =SUM(I20:I22) | ... M39: =SUM(M20:M22) | N39: 75790.198
A40: TOTAL LIGHT/LÉGER | B40: =SUM(B37:B39) | C40: =SUM(C37:C39) | D40: =SUM(D37:D39) | E40: =SUM(E37:E39) | F40: =SUM(F37:F39) | G40: =SUM(G37:G39) | H40: =SUM(H37:H39) | I40: =SUM(I37:I39) | ... M40: =SUM(M37:M39) | N40: 362697.7
A41: CONV. HEAVY/LOURD CLASS. | B41: =SUM(B26,B29) | C41: =SUM(C26,C29) | D41: =SUM(D26,D29) | E41: =SUM(E26,E29) | F41: =SUM(F26,F29) | G41: =SUM(G26,G29) | H41: =SUM(H26,H29) | I41: =SUM(I26,I29) | ... M41: =SUM(M26,M29) | N41: 70249.85
A42: AB NON-UPGRADED BITUMEN / BITUME NON VALORISÉ-AB2 | B42: =B27 | C42: =C27 | D42: =D27 | E42: =E27 | F42: =F27 | G42: =G27 | H42: =H27 | I42: =I27 | ... M42: =M27 | N42: 318997.56
A43: TOTAL HEAVY/LOURD | B43: =SUM(B41:B42) | C43: =SUM(C41:C42) | D43: =SUM(D41:D42) | E43: =SUM(E41:E42) | F43: =SUM(F41:F42) | G43: =SUM(G41:G42) | H43: =SUM(H41:H42) | I43: =SUM(I41:I42) | ... M43: =SUM(M41:M42) | N43: 389247.41
...

Sheet 23TABLE - barrels per day
A2: ='23TABLE - cubic meters per day'!A2 | H2: 2023 ESTIMATED PRODUCTION OF CANADIAN CRUDE OIL AND EQUIVALENT (b/d)
H3: PRODUCTION ESTIMATIVE DE PÉTROLE BRUT ET D'ÉQUIVALENTS AU CANADA EN 2023 (b/j)
N4: ='23TABLE - cubic meters per day'!N4
B5: Jan/janv. | C5: Feb/fév. | D5: Mar/mars | E5: Apr/avr. | F5: May/mai | G5: June/juin | H5: July/juil. | I5: Aug/août | J5: Sep/sept. | K5: Oct/oct. | L5: Nov/nov. | M5: Dec/déc. | N5: Avg/moyenne
A6: CONV. LIGHT CRUDE OIL/
A7: PÉTROLE BRUT LÉGER CLASS.
A8: AB | B8: ='23TABLE - cubic meters per day'!B8*6.2898 | C8: ='23TABLE - cubic meters per day'!C8*6.2898 | D8: ='23TABLE - cubic meters per day'!D8*6.2898 | E8: ='23TABLE - cubic meters per day'!E8*6.2898 | F8: ='23TABLE - cubic meters per day'!F8*6.2898 | G8: ='23TABLE - cubic meters per day'!G8*6.2898 | H8: ='23TABLE - cubic meters per day'!H8*6.2898 | I8: ='23TABLE - cubic meters per day'!I8*6.2898 | ... N8: ='23TABLE - cubic meters per day'!N8*6.2898
A9: BC | B9: ='23TABLE - cubic meters per day'!B9*6.2898 | C9: ='23TABLE - cubic meters per day'!C9*6.2898 | D9: ='23TABLE - cubic meters per day'!D9*6.2898 | E9: ='23TABLE - cubic meters per day'!E9*6.2898 | F9: ='23TABLE - cubic meters per day'!F9*6.2898 | G9: ='23TABLE - cubic meters per day'!G9*6.2898 | H9: ='23TABLE - cubic meters per day'!H9*6.2898 | I9: ='23TABLE - cubic meters per day'!I9*6.2898 | ... N9: ='23TABLE - cubic meters per day'!N9*6.2898
A10: SK | B10: ='23TABLE - cubic meters per day'!B10*6.2898 | C10: ='23TABLE - cubic meters per day'!C10*6.2898 | D10: ='23TABLE - cubic meters per day'!D10*6.2898 | E10: ='23TABLE - cubic meters per day'!E10*6.2898 | F10: ='23TABLE - cubic meters per day'!F10*6.2898 | G10: ='23TABLE - cubic meters per day'!G10*6.2898 | H10: ='23TABLE - cubic meters per day'!H10*6.2898 | I10: ='23TABLE - cubic meters per day'!I10*6.2898 | ... N10: ='23TABLE - cubic meters per day'!N10*6.2898
A11: MB | B11: ='23TABLE - cubic meters per day'!B11*6.2898 | C11: ='23TABLE - cubic meters per day'!C11*6.2898 | D11: ='23TABLE - cubic meters per day'!D11*6.2898 | E11: ='23TABLE - cubic meters per day'!E11*6.2898 | F11: ='23TABLE - cubic meters per day'!F11*6.2898 | G11: ='23TABLE - cubic meters per day'!G11*6.2898 | H11: ='23TABLE - cubic meters per day'!H11*6.2898 | I11: ='23TABLE - cubic meters per day'!I11*6.2898 | ... N11: ='23TABLE - cubic meters per day'!N11*6.2898
A12: NWT/NT | B12: ='23TABLE - cubic meters per day'!B12*6.2898 | C12: ='23TABLE - cubic meters per day'!C12*6.2898 | D12: ='23TABLE - cubic meters per day'!D12*6.2898 | E12: ='23TABLE - cubic meters per day'!E12*6.2898 | F12: ='23TABLE - cubic meters per day'!F12*6.2898 | G12: ='23TABLE - cubic meters per day'!G12*6.2898 | H12: ='23TABLE - cubic meters per day'!H12*6.2898 | I12: ='23TABLE - cubic meters per day'!I12*6.2898 | ... N12: ='23TABLE - cubic meters per day'!N12*6.2898
A13: NF/NL | B13: ='23TABLE - cubic meters per day'!B13*6.2898 | C13: ='23TABLE - cubic meters per day'!C13*6.2898 | D13: ='23TABLE - cubic meters per day'!D13*6.2898 | E13: ='23TABLE - cubic meters per day'!E13*6.2898 | F13: ='23TABLE - cubic meters per day'!F13*6.2898 | G13: ='23TABLE - cubic meters per day'!G13*6.2898 | H13: ='23TABLE - cubic meters per day'!H13*6.2898 | I13: ='23TABLE - cubic meters per day'!I13*6.2898 | ... N13: ='23TABLE - cubic meters per day'!N13*6.2898
A14: NB | B14: ='23TABLE - cubic meters per day'!B14*6.2898 | C14: ='23TABLE - cubic meters per day'!C14*6.2898 | D14: ='23TABLE - cubic meters per day'!D14*6.2898 | E14: ='23TABLE - cubic meters per day'!E14*6.2898
A15: ON | B15: ='23TABLE - cubic meters per day'!B15*6.2898 | C15: ='23TABLE - cubic meters per day'!C15*6.2898 | D15: ='23TABLE - cubic meters per day'!D15*6.2898 | E15: ='23TABLE - cubic meters per day'!E15*6.2898 | F15: ='23TABLE - cubic meters per day'!F15*6.2898 | G15: ='23TABLE - cubic meters per day'!G15*6.2898 | H15: ='23TABLE - cubic meters per day'!H15*6.2898 | I15: ='23TABLE - cubic meters per day'!I15*6.2898 | ... N15: ='23TABLE - cubic meters per day'!N15*6.2898
A16: SUB TOTAL/SOUS-TOTAL | B16: =SUM(B8:B15) | C16: =SUM(C8:C15) | D16: =SUM(D8:D15) | E16: =SUM(E8:E15) | F16: =SUM(F8:F15) | G16: =SUM(G8:G15) | H16: =SUM(H8:H15) | I16: =SUM(I8:I15) | ... M16: =SUM(M8:M15) | N16: ='23TABLE - cubic meters per day'!N16*6.2898
A17: AB UPGRADED BITUMEN/ BITUME VALORISÉ-AB1
A18: SUB TOTAL/SOUS-TOTAL | B18: ='23TABLE - cubic meters per day'!B18*6.2898 | C18: ='23TABLE - cubic meters per day'!C18*6.2898 | D18: ='23TABLE - cubic meters per day'!D18*6.2898 | E18: ='23TABLE - cubic meters per day'!E18*6.2898 | F18: ='23TABLE - cubic meters per day'!F18*6.2898 | G18: ='23TABLE - cubic meters per day'!G18*6.2898 | H18: ='23TABLE - cubic meters per day'!H18*6.2898 | I18: ='23TABLE - cubic meters per day'!I18*6.2898 | ... N18: ='23TABLE - cubic meters per day'!N18*6.2898
A19: C5+ / CONDENSATE/C5+/CONDENSATS
A20: AB | B20: ='23TABLE - cubic meters per day'!B20*6.2898 | C20: ='23TABLE - cubic meters per day'!C20*6.2898 | D20: ='23TABLE - cubic meters per day'!D20*6.2898 | E20: ='23TABLE - cubic meters per day'!E20*6.2898 | F20: ='23TABLE - cubic meters per day'!F20*6.2898 | G20: ='23TABLE - cubic meters per day'!G20*6.2898 | H20: ='23TABLE - cubic meters per day'!H20*6.2898 | I20: ='23TABLE - cubic meters per day'!I20*6.2898 | ... N20: ='23TABLE - cubic meters per day'!N20*6.2898
A21: BC | B21: ='23TABLE - cubic meters per day'!B21*6.2898 | C21: ='23TABLE - cubic meters per day'!C21*6.2898 | D21: ='23TABLE - cubic meters per day'!D21*6.2898 | E21: ='23TABLE - cubic meters per day'!E21*6.2898 | F21: ='23TABLE - cubic meters per day'!F21*6.2898 | G21: ='23TABLE - cubic meters per day'!G21*6.2898 | H21: ='23TABLE - cubic meters per day'!H21*6.2898 | I21: ='23TABLE - cubic meters per day'!I21*6.2898 | ... N21: ='23TABLE - cubic meters per day'!N21*6.2898
A22: SK2 | B22: ='23TABLE - cubic meters per day'!B22*6.2898 | C22: ='23TABLE - cubic meters per day'!C22*6.2898 | D22: ='23TABLE - cubic meters per day'!D22*6.2898 | E22: ='23TABLE - cubic meters per day'!E22*6.2898 | F22: ='23TABLE - cubic meters per day'!F22*6.2898 | G22: ='23TABLE - cubic meters per day'!G22*6.2898 | H22: ='23TABLE - cubic meters per day'!H22*6.2898 | I22: ='23TABLE - cubic meters per day'!I22*6.2898 | ... M22: ='23TABLE - cubic meters per day'!M22*6.2898
A23: SUB TOTAL/SOUS-TOTAL | B23: ='23TABLE - cubic meters per day'!B23*6.2898 | C23: ='23TABLE - cubic meters per day'!C23*6.2898 | D23: ='23TABLE - cubic meters per day'!D23*6.2898 | E23: ='23TABLE - cubic meters per day'!E23*6.2898 | F23: ='23TABLE - cubic meters per day'!F23*6.2898 | G23: ='23TABLE - cubic meters per day'!G23*6.2898 | H23: ='23TABLE - cubic meters per day'!H23*6.2898 | I23: ='23TABLE - cubic meters per day'!I23*6.2898 | ... N23: ='23TABLE - cubic meters per day'!N23*6.2898
A24: TOTAL LIGHT/LÉGER | B24: =SUM(B23,B16,B18) | C24: =SUM(C23,C16,C18) | D24: =SUM(D23,D16,D18) | E24: =SUM(E23,E16,E18) | F24: =SUM(F23,F16,F18) | G24: =SUM(G23,G16,G18) | H24: =SUM(H23,H16,H18) | I24: =SUM(I23,I16,I18) | ... M24: =SUM(M23,M16,M18) | N24: ='23TABLE - cubic meters per day'!N24*6.2898
A25: HEAVY CRUDE OIL/ PÉTROLE BRUT LOURD
A26: AB CONV./CLASS.-AB | B26: ='23TABLE - cubic meters per day'!B26*6.2898 | C26: ='23TABLE - cubic meters per day'!C26*6.2898 | D26: ='23TABLE - cubic meters per day'!D26*6.2898 | E26: ='23TABLE - cubic meters per day'!E26*6.2898 | F26: ='23TABLE - cubic meters per day'!F26*6.2898 | G26: ='23TABLE - cubic meters per day'!G26*6.2898 | H26: ='23TABLE - cubic meters per day'!H26*6.2898 | I26: ='23TABLE - cubic meters per day'!I26*6.2898 | ... N26: ='23TABLE - cubic meters per day'!N26*6.2898
A27: AB NON-UPGRADED BITUMEN / BITUME NON VALORISÉ-AB2 | B27: ='23TABLE - cubic meters per day'!B27*6.2898 | C27: ='23TABLE - cubic meters per day'!C27*6.2898 | D27: ='23TABLE - cubic meters per day'!D27*6.2898 | E27: ='23TABLE - cubic meters per day'!E27*6.2898 | F27: ='23TABLE - cubic meters per day'!F27*6.2898 | G27: ='23TABLE - cubic meters per day'!G27*6.2898 | H27: ='23TABLE - cubic meters per day'!H27*6.2898 | I27: ='23TABLE - cubic meters per day'!I27*6.2898 | ... N27: ='23TABLE - cubic meters per day'!N27*6.2898
A28: AB SUB TOTAL/SOUS-TOTAL -AB | B28: ='23TABLE - cubic meters per day'!B28*6.2898 | C28: ='23TABLE - cubic meters per day'!C28*6.2898 | D28: ='23TABLE - cubic meters per day'!D28*6.2898 | E28: ='23TABLE - cubic meters per day'!E28*6.2898 | F28: ='23TABLE - cubic meters per day'!F28*6.2898 | G28: ='23TABLE - cubic meters per day'!G28*6.2898 | H28: ='23TABLE - cubic meters per day'!H28*6.2898 | I28: ='23TABLE - cubic meters per day'!I28*6.2898 | ... N28: ='23TABLE - cubic meters per day'!N28*6.2898
A29: SK CONV./CLASS.-SK | B29: ='23TABLE - cubic meters per day'!B29*6.2898 | C29: ='23TABLE - cubic meters per day'!C29*6.2898 | D29: ='23TABLE - cubic meters per day'!D29*6.2898 | E29: ='23TABLE - cubic meters per day'!E29*6.2898 | F29: ='23TABLE - cubic meters per day'!F29*6.2898 | G29: ='23TABLE - cubic meters per day'!G29*6.2898 | H29: ='23TABLE - cubic meters per day'!H29*6.2898 | I29: ='23TABLE - cubic meters per day'!I29*6.2898 | ... N29: ='23TABLE - cubic meters per day'!N29*6.2898
A30: NL CONV | B30: ='23TABLE - cubic meters per day'!B30*6.2898 | C30: ='23TABLE - cubic meters per day'!C30*6.2898 | D30: ='23TABLE - cubic meters per day'!D30*6.2898 | E30: ='23TABLE - cubic meters per day'!E30*6.2898 | F30: ='23TABLE - cubic meters per day'!F30*6.2898 | G30: ='23TABLE - cubic meters per day'!G30*6.2898 | H30: ='23TABLE - cubic meters per day'!H30*6.2898 | I30: ='23TABLE - cubic meters per day'!I30*6.2898 | ... N30: ='23TABLE - cubic meters per day'!N30*6.2898
A31: TOTAL HEAVY/LOURD3 | B31: =SUM(B28:B30) | C31: =SUM(C28:C30) | D31: =SUM(D28:D30) | E31: =SUM(E28:E30) | F31: =SUM(F28:F30) | G31: =SUM(G28:G30) | H31: =SUM(H28:H30) | I31: =SUM(I28:I30) | ... M31: =SUM(M28:M30) | N31: ='23TABLE - cubic meters per day'!N31*6.2898
A32: TOTAL PRODUCTION | B32: =SUM(B31,B24) | C32: =SUM(C31,C24) | D32: =SUM(D31,D24) | E32: =SUM(E31,E24) | F32: =SUM(F31,F24) | G32: =SUM(G31,G24) | H32: =SUM(H31,H24) | I32: =SUM(I31,I24) | ... M32: =SUM(M31,M24) | N32: ='23TABLE - cubic meters per day'!N32*6.2898
H35: ESTIMATED PRODUCTION BY REGION
A36: WESTERN CANADA/OUEST CANADIEN
A37: CONV. LIGHT/LÉGER CLASS. | B37: ='23TABLE - cubic meters per day'!B37*6.2898 | C37: ='23TABLE - cubic meters per day'!C37*6.2898 | D37: ='23TABLE - cubic meters per day'!D37*6.2898 | E37: ='23TABLE - cubic meters per day'!E37*6.2898 | F37: ='23TABLE - cubic meters per day'!F37*6.2898 | G37: ='23TABLE - cubic meters per day'!G37*6.2898 | H37: ='23TABLE - cubic meters per day'!H37*6.2898 | I37: ='23TABLE - cubic meters per day'!I37*6.2898 | ... N37: ='23TABLE - cubic meters per day'!N37*6.2898
A38: AB UPGRADED BITUMEN/ BITUME VALORISÉ-AB 1 | B38: ='23TABLE - cubic meters per day'!B38*6.2898 | C38: ='23TABLE - cubic meters per day'!C38*6.2898 | D38: ='23TABLE - cubic meters per day'!D38*6.2898 | E38: ='23TABLE - cubic meters per day'!E38*6.2898 | F38: ='23TABLE - cubic meters per day'!F38*6.2898 | G38: ='23TABLE - cubic meters per day'!G38*6.2898 | H38: ='23TABLE - cubic meters per day'!H38*6.2898 | I38: ='23TABLE - cubic meters per day'!I38*6.2898 | ... N38: ='23TABLE - cubic meters per day'!N38*6.2898
A39: PENTANES PLUS | B39: ='23TABLE - cubic meters per day'!B39*6.2898 | C39: ='23TABLE - cubic meters per day'!C39*6.2898 | D39: ='23TABLE - cubic meters per day'!D39*6.2898 | E39: ='23TABLE - cubic meters per day'!E39*6.2898 | F39: ='23TABLE - cubic meters per day'!F39*6.2898 | G39: ='23TABLE - cubic meters per day'!G39*6.2898 | H39: ='23TABLE - cubic meters per day'!H39*6.2898 | I39: ='23TABLE - cubic meters per day'!I39*6.2898 | ... N39: ='23TABLE - cubic meters per day'!N39*6.2898
A40: TOTAL LIGHT/LÉGER | B40: ='23TABLE - cubic meters per day'!B40*6.2898 | C40: ='23TABLE - cubic meters per day'!C40*6.2898 | D40: ='23TABLE - cubic meters per day'!D40*6.2898 | E40: ='23TABLE - cubic meters per day'!E40*6.2898 | F40: ='23TABLE - cubic meters per day'!F40*6.2898 | G40: ='23TABLE - cubic meters per day'!G40*6.2898 | H40: ='23TABLE - cubic meters per day'!H40*6.2898 | I40: ='23TABLE - cubic meters per day'!I40*6.2898 | ... N40: ='23TABLE - cubic meters per day'!N40*6.2898
A41: CONV. HEAVY/LOURD CLASS. | B41: ='23TABLE - cubic meters per day'!B41*6.2898 | C41: ='23TABLE - cubic meters per day'!C41*6.2898 | D41: ='23TABLE - cubic meters per day'!D41*6.2898 | E41: ='23TABLE - cubic meters per day'!E41*6.2898 | F41: ='23TABLE - cubic meters per day'!F41*6.2898 | G41: ='23TABLE - cubic meters per day'!G41*6.2898 | H41: ='23TABLE - cubic meters per day'!H41*6.2898 | I41: ='23TABLE - cubic meters per day'!I41*6.2898 | ... N41: ='23TABLE - cubic meters per day'!N41*6.2898
A42: AB NON-UPGRADED BITUMEN / BITUME NON VALORISÉ-AB2 | B42: ='23TABLE - cubic meters per day'!B42*6.2898 | C42: ='23TABLE - cubic meters per day'!C42*6.2898 | D42: ='23TABLE - cubic meters per day'!D42*6.2898 | E42: ='23TABLE - cubic meters per day'!E42*6.2898 | F42: ='23TABLE - cubic meters per day'!F42*6.2898 | G42: ='23TABLE - cubic meters per day'!G42*6.2898 | H42: ='23TABLE - cubic meters per day'!H42*6.2898 | I42: ='23TABLE - cubic meters per day'!I42*6.2898 | ... N42: ='23TABLE - cubic meters per day'!N42*6.2898
A43: TOTAL HEAVY/LOURD | B43: ='23TABLE - cubic meters per day'!B43*6.2898 | C43: ='23TABLE - cubic meters per day'!C43*6.2898 | D43: ='23TABLE - cubic meters per day'!D43*6.2898 | E43: ='23TABLE - cubic meters per day'!E43*6.2898 | F43: ='23TABLE - cubic meters per day'!F43*6.2898 | G43: ='23TABLE - cubic meters per day'!G43*6.2898 | H43: ='23TABLE - cubic meters per day'!H43*6.2898 | I43: ='23TABLE - cubic meters per day'!I43*6.2898 | ... N43: ='23TABLE - cubic meters per day'!N43*6.2898
...

Sheet 22TABLE - cubic meters per day
A2: 45033 | H2: 2022 ESTIMATED PRODUCTION OF CANADIAN CRUDE OIL AND EQUIVALENT (m3/d)
H3: PRODUCTION ESTIMATIVE DE PÉTROLE BRUT ET D'ÉQUIVALENTS AU CANADA EN 2022 (M³/J)
N4: 2022
B5: Jan/janv. | C5: Feb/fév. | D5: Mar/mars | E5: Apr/avr. | F5: May/mai | G5: June/juin | H5: July/juil. | I5: Aug/août | J5: Sep/sept. | K5: Oct/oct. | L5: Nov/nov. | M5: Dec/déc. | N5: Avg/moyenne
A6: CONV. LIGHT CRUDE OIL/
A7: PÉTROLE BRUT LÉGER CLASS.
A8: AB | B8: 52478.921 | C8: 54351.821 | D8: 56943.231 | E8: 59035.044 | F8: 57032.75 | G8: 56454.275 | H8: 56861.483 | I8: 57927.006 | J8: 57010.639 | K8: 59192.518 | L8: 59029.025 | M8: 58739.474 | N8: 57101.801
A9: BC | B9: 1718.6548 | C9: 1956.9821 | D9: 1817.0774 | E9: 1929.3233 | F9: 1877.6903 | G9: 1886.6967 | H9: 1825.8097 | I9: 1741.6452 | J9: 1686.6 | K9: 1774.0323 | L9: 1790.7667 | M9: 1724.0645 | N9: 1809.4392
A10: SK | B10: 23972.503 | C10: 24646.361 | D10: 26088.761 | E10: 24555.467 | F10: 24374.381 | G10: 23878.807 | H10: 23832.335 | I10: 24698.458 | J10: 25262.1 | K10: 25435.806 | L10: 25674.31 | M10: 24552.181 | N10: 24747.413
A11: MB | B11: 5907.9419 | C11: 5850.4393 | D11: 6290.8645 | E11: 6035.59 | F11: 5913.1065 | G11: 5801.43 | H11: 5729.6355 | I11: 5977.9194 | J11: 6091.3133 | K11: 6301.7645 | L11: 6261.37 | M11: 6357.971 | N11: 6044.8184
A12: NWT/NT | B12: 1012.8645 | C12: 1002.275 | D12: 1004.5065 | E12: 1028.28 | F12: 996.01935 | G12: 974.72 | H12: 874.85484 | I12: 839.01613 | J12: 727.72333 | K12: 723.37742 | L12: 694.56 | M12: 690.41935 | N12: 879.9863
A13: NF/NL | B13: 17261.903 | C13: 17365.393 | D13: 18327.097 | E13: 17244.833 | F13: 17254.484 | G13: 17209 | H13: 15934.032 | I13: 14270.774 | J13: 5672.1 | K13: 5821.9032 | L13: 16137.133 | M13: 15145.548 | N13: 14790.715
A14: NB | B14: 6.0290323 | C14: 5 | D14: 4.7290323 | E14: 3.3066667 | F14: 3.9322581 | G14: 3.63 | H14: 3.1612903 | I14: 3.7 | J14: 3.4833333 | K14: 3.3451613 | L14: 4.0933333 | M14: 3.9580645 | N14: 4.0271233
A15: ON | B15: 82.903226 | C15: 83.642857 | D15: 84.774194 | E15: 85.5 | F15: 84.516129 | G15: 81.866667 | H15: 83.387097 | I15: 79.935484 | J15: 81.433333 | K15: 83.354839 | L15: 82.833333 | M15: 78.16129 | N15: 82.682192
A16: SUB TOTAL/SOUS-TOTAL | B16: =SUM(B8:B15) | C16: =SUM(C8:C15) | D16: =SUM(D8:D15) | E16: =SUM(E8:E15) | F16: =SUM(F8:F15) | G16: =SUM(G8:G15) | H16: =SUM(H8:H15) | I16: =SUM(I8:I15) | ... M16: =SUM(M8:M15) | N16: 105460.88
A17: AB UPGRADED BITUMEN/ BITUME VALORISÉ-AB1
A18: SUB TOTAL/SOUS-TOTAL | B18: 185818.98 | C18: 198050.25 | D18: 193673.77 | E18: 179810.23 | F18: 164852.44 | G18: 181016.5 | H18: 186643.06 | I18: 180232.24 | J18: 176389.15 | K18: 174438.71 | L18: 211286.1 | M18: 195988.03 | N18: 185565.84
A19: C5+ / CONDENSATE/C5+/CONDENSATS
A20: AB | B20: 53989.906 | C20: 56013.478 | D20: 57126.377 | E20: 57970.901 | F20: 55786.008 | G20: 54321.105 | H20: 59822.986 | I20: 58830.31 | J20: 59457.691 | K20: 60797.147 | L20: 61257.151 | M20: 60958.447 | N20: 58041.724
A21: BC | B21: 16332.781 | C21: 16253.586 | D21: 16548.942 | E21: 16164.023 | F21: 15964.316 | G21: 15508.297 | H21: 15725.768 | I21: 15529.158 | J21: 13956.537 | K21: 16493.084 | L21: 17348.967 | M21: 10983.145 | N21: 15559.803
A22: SK | B22: 560.92871 | C22: 560.92893 | D22: 560.92871 | E22: 560.92867 | F22: 560.92871 | G22: 560.92867 | H22: 560.92871 | I22: 560.92871 | J22: 560.92867 | K22: 560.92871 | L22: 560.92867 | M22: 560.92871 | N22: 560.92871
A23: SUB TOTAL/SOUS-TOTAL | B23: 70873.074 | C23: 72876.421 | D23: 74225.706 | E23: 74703.66 | F23: 72300.71 | G23: 70355.107 | H23: 76099.142 | I23: 74909.858 | J23: 73982.96 | K23: 77840.616 | L23: 79174.85 | M23: 72491.977 | N23: 74162.456
A24: TOTAL LIGHT/LÉGER | B24: 359249.03 | C24: 376180.47 | D24: 378455.06 | E24: 364426.54 | F24: 344679.43 | G24: 357652.85 | H24: 367881 | I24: 360763.21 | J24: 347225.22 | K24: 351651.03 | L24: 400128.04 | M24: 375765.33 | N24: 365189.18
A25: HEAVY CRUDE OIL/ PÉTROLE BRUT LOURD
A26: AB CONV./CLASS.-AB | B26: 19125.694 | C26: 20076.251 | D26: 20707.406 | E26: 21275.69 | F26: 21604.365 | G26: 21547.626 | H26: 21457.713 | I26: 21756.048 | J26: 21677.267 | K26: 21615.31 | L26: 21086.786 | M26: 20190.632 | N26: 21013.502
A27: AB NON-UPGRADED BITUMEN / BITUME NON VALORISÉ-AB2 | B27: 297464.84 | C27: 310814.93 | D27: 310871.74 | E27: 305429.53 | F27: 295468.39 | G27: 297000.87 | H27: 323740.74 | I27: 334287.45 | J27: 347547.3 | K27: 341803.19 | L27: 323903.77 | M27: 317067.81 | N27: 317153.67
A28: AB SUB TOTAL/SOUS-TOTAL -AB | B28: 316590.54 | C28: 330891.2 | D28: 331579.28 | E28: 326819.93 | F28: 317081.45 | G28: 318535.83 | H28: 345210.95 | I28: 356060.39 | J28: 369217.09 | K28: 363358.86 | L28: 344990.56 | M28: 337258.45 | N28: 338167.18
A29: SK CONV./CLASS.-SK | B29: 45059.971 | C29: 45676.682 | D29: 46844.219 | E29: 48418.927 | F29: 47508.661 | G29: 47446.277 | H29: 47513.771 | I29: 47890.948 | J29: 48771.04 | K29: 47943.4 | L29: 47873.773 | M29: 47104.184 | N29: 47342.65
A30: NL CONV | B30: 20200.774 | C30: 21361.107 | D30: 21556.258 | E30: 21810.1 | F30: 21634.355 | G30: 21615.933 | H30: 22159.516 | I30: 22279.71 | J30: 22062.233 | K30: 23174.677 | L30: 22430.867 | M30: 22606.677 | N30: 21911.386
A31: TOTAL HEAVY/LOURD3 | B31: 381865.93 | C31: 397938.66 | D31: 399996.94 | E31: 397066.19 | F31: 386238.01 | G31: 387610.43 | H31: 414905.35 | I31: 426246.65 | J31: 440057.04 | K31: 434497.11 | L31: 415305.99 | M31: 406986.08 | N31: 407421.21
A32: TOTAL PRODUCTION | B32: =SUM(B31,B24) | C32: =SUM(C31,C24) | D32: =SUM(D31,D24) | E32: =SUM(E31,E24) | F32: =SUM(F31,F24) | G32: =SUM(G31,G24) | H32: =SUM(H31,H24) | I32: =SUM(I31,I24) | ... M32: =SUM(M31,M24) | N32: 772610.39
H35: ESTIMATED PRODUCTION BY REGION
A36: WESTERN CANADA/OUEST CANADIEN
A37: CONV. LIGHT/LÉGER CLASS. | B37: 85206.129 | C37: 87799.796 | D37: 92138.987 | E37: 92579.04 | F37: 90187.281 | G37: 88990.373 | H37: 89121.371 | I37: 91176.223 | J37: 90777.573 | K37: 93427.358 | L37: 93447.34 | M37: 92061.571 | N37: 90583.458
A38: AB UPGRADED BITUMEN/ BITUME VALORISÉ-AB 1 | B38: 185818.99 | C38: 198050.26 | D38: 193673.77 | E38: 179810.24 | F38: 164852.44 | G38: 181016.5 | H38: 186643.07 | I38: 180326.42 | J38: 176711.15 | K38: 174477.8 | L38: 211285.85 | M38: 195988.04 | N38: 185565.84
A39: PENTANES PLUS | B39: 70873.074 | C39: 72876.421 | D39: 74225.706 | E39: 74703.66 | F39: 72300.71 | G39: 70355.107 | H39: 76099.142 | I39: 74909.858 | J39: 73982.96 | K39: 77840.616 | L39: 79174.85 | M39: 72491.977 | N39: 74162.456
A40: TOTAL LIGHT/LÉGER | B40: 341898.19 | C40: 358726.47 | D40: 360038.46 | E40: 347092.94 | F40: 327340.43 | G40: 340361.98 | H40: 351863.58 | I40: 346412.5 | J40: 341471.69 | K40: 345745.77 | L40: 383908.04 | M40: 360541.58 | N40: 350311.75
A41: CONV. HEAVY/LOURD CLASS. | B41: 64200.31 | C41: 65762.607 | D41: 67568.81 | E41: 69711.843 | F41: 69126.565 | G41: 69006.293 | H41: 68992.6 | I41: 69662.59 | J41: 70454.98 | K41: 69578.881 | L41: 68971.35 | M41: 67311.577 | N41: 68356.153
A42: AB NON-UPGRADED BITUMEN / BITUME NON VALORISÉ-AB2 | B42: 297464.85 | C42: 310814.95 | D42: 310871.87 | E42: 305544.24 | F42: 295477.09 | G42: 296988.21 | H42: 323753.23 | I42: 334304.35 | J42: 347539.83 | K42: 341743.55 | L42: 323903.77 | M42: 317067.82 | N42: 317153.67
A43: TOTAL HEAVY/LOURD | B43: 361665.15 | C43: 376577.55 | D43: 378440.68 | E43: 375256.09 | F43: 364603.65 | G43: 365994.5 | H43: 392745.83 | I43: 403966.94 | J43: 417994.81 | K43: 411322.43 | L43: 392875.12 | M43: 384379.4 | N43: 385509.83
...

Sheet 22TABLE - barrels per day
A2: 45033 | H2: 2022 ESTIMATED PRODUCTION OF CANADIAN CRUDE OIL AND EQUIVALENT (b/d)
H3: PRODUCTION ESTIMATIVE DE PÉTROLE BRUT ET D'ÉQUIVALENTS AU CANADA EN 2022 (b/j)
N4: ='22TABLE - cubic meters per day'!N4
B5: Jan/janv. | C5: Feb/fév. | D5: Mar/mars | E5: Apr/avr. | F5: May/mai | G5: June/juin | H5: July/juil. | I5: Aug/août | J5: Sep/sept. | K5: Oct/oct. | L5: Nov/nov. | M5: Dec/déc. | N5: Avg/moyenne
A6: CONV. LIGHT CRUDE OIL/
A7: PÉTROLE BRUT LÉGER CLASS.
A8: AB | B8: ='22TABLE - cubic meters per day'!B8*6.2898 | C8: ='22TABLE - cubic meters per day'!C8*6.2898 | D8: ='22TABLE - cubic meters per day'!D8*6.2898 | E8: ='22TABLE - cubic meters per day'!E8*6.2898 | F8: ='22TABLE - cubic meters per day'!F8*6.2898 | G8: ='22TABLE - cubic meters per day'!G8*6.2898 | H8: ='22TABLE - cubic meters per day'!H8*6.2898 | I8: ='22TABLE - cubic meters per day'!I8*6.2898 | ... N8: ='22TABLE - cubic meters per day'!N8*6.2898
A9: BC | B9: ='22TABLE - cubic meters per day'!B9*6.2898 | C9: ='22TABLE - cubic meters per day'!C9*6.2898 | D9: ='22TABLE - cubic meters per day'!D9*6.2898 | E9: ='22TABLE - cubic meters per day'!E9*6.2898 | F9: ='22TABLE - cubic meters per day'!F9*6.2898 | G9: ='22TABLE - cubic meters per day'!G9*6.2898 | H9: ='22TABLE - cubic meters per day'!H9*6.2898 | I9: ='22TABLE - cubic meters per day'!I9*6.2898 | ... N9: ='22TABLE - cubic meters per day'!N9*6.2898
A10: SK | B10: ='22TABLE - cubic meters per day'!B10*6.2898 | C10: ='22TABLE - cubic meters per day'!C10*6.2898 | D10: ='22TABLE - cubic meters per day'!D10*6.2898 | E10: ='22TABLE - cubic meters per day'!E10*6.2898 | F10: ='22TABLE - cubic meters per day'!F10*6.2898 | G10: ='22TABLE - cubic meters per day'!G10*6.2898 | H10: ='22TABLE - cubic meters per day'!H10*6.2898 | I10: ='22TABLE - cubic meters per day'!I10*6.2898 | ... N10: ='22TABLE - cubic meters per day'!N10*6.2898
A11: MB | B11: ='22TABLE - cubic meters per day'!B11*6.2898 | C11: ='22TABLE - cubic meters per day'!C11*6.2898 | D11: ='22TABLE - cubic meters per day'!D11*6.2898 | E11: ='22TABLE - cubic meters per day'!E11*6.2898 | F11: ='22TABLE - cubic meters per day'!F11*6.2898 | G11: ='22TABLE - cubic meters per day'!G11*6.2898 | H11: ='22TABLE - cubic meters per day'!H11*6.2898 | I11: ='22TABLE - cubic meters per day'!I11*6.2898 | ... N11: ='22TABLE - cubic meters per day'!N11*6.2898
A12: NWT/NT | B12: ='22TABLE - cubic meters per day'!B12*6.2898 | C12: ='22TABLE - cubic meters per day'!C12*6.2898 | D12: ='22TABLE - cubic meters per day'!D12*6.2898 | E12: ='22TABLE - cubic meters per day'!E12*6.2898 | F12: ='22TABLE - cubic meters per day'!F12*6.2898 | G12: ='22TABLE - cubic meters per day'!G12*6.2898 | H12: ='22TABLE - cubic meters per day'!H12*6.2898 | I12: ='22TABLE - cubic meters per day'!I12*6.2898 | ... N12: ='22TABLE - cubic meters per day'!N12*6.2898
A13: NF/NL | B13: ='22TABLE - cubic meters per day'!B13*6.2898 | C13: ='22TABLE - cubic meters per day'!C13*6.2898 | D13: ='22TABLE - cubic meters per day'!D13*6.2898 | E13: ='22TABLE - cubic meters per day'!E13*6.2898 | F13: ='22TABLE - cubic meters per day'!F13*6.2898 | G13: ='22TABLE - cubic meters per day'!G13*6.2898 | H13: ='22TABLE - cubic meters per day'!H13*6.2898 | I13: ='22TABLE - cubic meters per day'!I13*6.2898 | ... N13: ='22TABLE - cubic meters per day'!N13*6.2898
A14: NB | B14: ='22TABLE - cubic meters per day'!B14*6.2898 | C14: ='22TABLE - cubic meters per day'!C14*6.2898 | D14: ='22TABLE - cubic meters per day'!D14*6.2898 | E14: ='22TABLE - cubic meters per day'!E14*6.2898 | F14: ='22TABLE - cubic meters per day'!F14*6.2898 | G14: ='22TABLE - cubic meters per day'!G14*6.2898 | H14: ='22TABLE - cubic meters per day'!H14*6.2898 | I14: ='22TABLE - cubic meters per day'!I14*6.2898 | ... N14: ='22TABLE - cubic meters per day'!N14*6.2898
A15: ON | B15: ='22TABLE - cubic meters per day'!B15*6.2898 | C15: ='22TABLE - cubic meters per day'!C15*6.2898 | D15: ='22TABLE - cubic meters per day'!D15*6.2898 | E15: ='22TABLE - cubic meters per day'!E15*6.2898 | F15: ='22TABLE - cubic meters per day'!F15*6.2898 | G15: ='22TABLE - cubic meters per day'!G15*6.2898 | H15: ='22TABLE - cubic meters per day'!H15*6.2898 | I15: ='22TABLE - cubic meters per day'!I15*6.2898 | ... N15: ='22TABLE - cubic meters per day'!N15*6.2898
A16: SUB TOTAL/SOUS-TOTAL | B16: ='22TABLE - cubic meters per day'!B16*6.2898 | C16: ='22TABLE - cubic meters per day'!C16*6.2898 | D16: ='22TABLE - cubic meters per day'!D16*6.2898 | E16: ='22TABLE - cubic meters per day'!E16*6.2898 | F16: ='22TABLE - cubic meters per day'!F16*6.2898 | G16: ='22TABLE - cubic meters per day'!G16*6.2898 | H16: ='22TABLE - cubic meters per day'!H16*6.2898 | I16: ='22TABLE - cubic meters per day'!I16*6.2898 | ... N16: ='22TABLE - cubic meters per day'!N16*6.2898
A17: AB UPGRADED BITUMEN/ BITUME VALORISÉ-AB1
A18: SUB TOTAL/SOUS-TOTAL | B18: ='22TABLE - cubic meters per day'!B18*6.2898 | C18: ='22TABLE - cubic meters per day'!C18*6.2898 | D18: ='22TABLE - cubic meters per day'!D18*6.2898 | E18: ='22TABLE - cubic meters per day'!E18*6.2898 | F18: ='22TABLE - cubic meters per day'!F18*6.2898 | G18: ='22TABLE - cubic meters per day'!G18*6.2898 | H18: ='22TABLE - cubic meters per day'!H18*6.2898 | I18: ='22TABLE - cubic meters per day'!I18*6.2898 | ... N18: ='22TABLE - cubic meters per day'!N18*6.2898
A19: C5+ / CONDENSATE/C5+/CONDENSATS
